Workbook

Sheet Urban population
A1: Model | B1: Scenario | C1: Region | D1: ISO-3code | E1: ISO-2code | F1: Variable | G1: IMAGE | H1: Unit | I1: 1950 | J1: 1955 | K1: 1960 | L1: 1965 | M1: 1970 | N1: 1975 | O1: 1980 | P1: 1985 | Q1: 1990 | R1: 1995 | S1: 2000 | T1: 2005 | U1: 2010 | V1: 2015 | W1: 2020 | X1: 2025 | Y1: 2030 | Z1: 2035 | AA1: 2040 | AB1: 2045 | AC1: 2050 | AD1: 2055 | AE1: 2060 | AF1: 2065 | AG1: 2070 | AH1: 2075 | AI1: 2080 | AJ1: 2085 | AK1: 2090 | AL1: 2095 | AM1: 2100
A2: IIASA-WiC POP 2023 | B2: SSP2 | C2: Aruba | D2: ABW | E2: =_xlfn.XLOOKUP(D2,[6]Feuil1!$C$2:$C$248,[6]Feuil1!$B$2:$B$248) -> AW | F2: Population | G2: Central America | H2: million | I2: =[1]data!F2*(_xlfn.XLOOKUP([1]data!$C2,[2]data!$B$2:$B$218,[2]data!E$2:E$218)/100) -> 0.019404607 | J2: =[1]data!G2*(_xlfn.XLOOKUP([1]data!$C2,[2]data!$B$2:$B$218,[2]data!F$2:F$218)/100) -> 0.023237886 | K2: =[1]data!H2*(_xlfn.XLOOKUP([1]data!$C2,[2]data!$B$2:$B$218,[2]data!G$2:G$218)/100) -> 0.02736088 | L2: =[1]data!I2*(_xlfn.XLOOKUP([1]data!$C2,[2]data!$B$2:$B$218,[2]data!H$2:H$218)/100) -> 0.029661528 | M2: =[1]data!J2*(_xlfn.XLOOKUP([1]data!$C2,[2]data!$B$2:$B$218,[2]data!I$2:I$218)/100) -> 0.02997544 | N2: =[1]data!K2*(_xlfn.XLOOKUP([1]data!$C2,[2]data!$B$2:$B$218,[2]data!J$2:J$218)/100) -> 0.030489375 | O2: =[1]data!L2*(_xlfn.XLOOKUP([1]data!$C2,[2]data!$B$2:$B$218,[2]data!K$2:K$218)/100) -> 0.03137969 | P2: =[1]data!M2*(_xlfn.XLOOKUP([1]data!$C2,[2]data!$B$2:$B$218,[2]data!L$2:L$218)/100) -> 0.032449032 | ... AM2: =[1]data!AJ2*(_xlfn.XLOOKUP([1]data!$C2,[2]data!$B$2:$B$218,[2]data!AI$2:AI$218)/100) -> 0.098279521
A3: IIASA-WiC POP 2023 | B3: SSP2 | C3: Angola | D3: AGO | E3: =_xlfn.XLOOKUP(D3,[6]Feuil1!$C$2:$C$248,[6]Feuil1!$B$2:$B$248) -> AO | F3: Population | G3: =_xlfn.XLOOKUP(C3,[3]Sheet1!$B$2:$B$172,[3]Sheet1!$D$2:$D$172) -> Rest of Southern Africa | H3: million | I3: =[1]data!F4*(_xlfn.XLOOKUP([1]data!$C4,[2]data!$B$2:$B$218,[2]data!E$2:E$218)/100) -> 0.33690131 | J3: =[1]data!G4*(_xlfn.XLOOKUP([1]data!$C4,[2]data!$B$2:$B$218,[2]data!F$2:F$218)/100) -> 0.4356874 | K3: =[1]data!H4*(_xlfn.XLOOKUP([1]data!$C4,[2]data!$B$2:$B$218,[2]data!G$2:G$218)/100) -> 0.5526066 | L3: =[1]data!I4*(_xlfn.XLOOKUP([1]data!$C4,[2]data!$B$2:$B$218,[2]data!H$2:H$218)/100) -> 0.713468 | M3: =[1]data!J4*(_xlfn.XLOOKUP([1]data!$C4,[2]data!$B$2:$B$218,[2]data!I$2:I$218)/100) -> 0.895005 | N3: =[1]data!K4*(_xlfn.XLOOKUP([1]data!$C4,[2]data!$B$2:$B$218,[2]data!J$2:J$218)/100) -> 1.3210698 | O3: =[1]data!L4*(_xlfn.XLOOKUP([1]data!$C4,[2]data!$B$2:$B$218,[2]data!K$2:K$218)/100) -> 1.9883023 | P3: =[1]data!M4*(_xlfn.XLOOKUP([1]data!$C4,[2]data!$B$2:$B$218,[2]data!L$2:L$218)/100) -> 2.9667218 | ... AM3: =[1]data!AJ4*(_xlfn.XLOOKUP([1]data!$C4,[2]data!$B$2:$B$218,[2]data!AI$2:AI$218)/100) -> 90.952647
A4: IIASA-WiC POP 2023 | B4: SSP2 | C4: Albania | D4: ALB | E4: =_xlfn.XLOOKUP(D4,[6]Feuil1!$C$2:$C$248,[6]Feuil1!$B$2:$B$248) -> AL | F4: Population | G4: =_xlfn.XLOOKUP(C4,[3]Sheet1!$B$2:$B$172,[3]Sheet1!$D$2:$D$172) -> Central Europe | H4: million | I4: =[1]data!F5*(_xlfn.XLOOKUP([1]data!$C5,[2]data!$B$2:$B$218,[2]data!E$2:E$218)/100) -> 0.25306717 | J4: =[1]data!G5*(_xlfn.XLOOKUP([1]data!$C5,[2]data!$B$2:$B$218,[2]data!F$2:F$218)/100) -> 0.38487794 | K4: =[1]data!H5*(_xlfn.XLOOKUP([1]data!$C5,[2]data!$B$2:$B$218,[2]data!G$2:G$218)/100) -> 0.5165757 | L4: =[1]data!I5*(_xlfn.XLOOKUP([1]data!$C5,[2]data!$B$2:$B$218,[2]data!H$2:H$218)/100) -> 0.6175884 | M4: =[1]data!J5*(_xlfn.XLOOKUP([1]data!$C5,[2]data!$B$2:$B$218,[2]data!I$2:I$218)/100) -> 0.72665942 | N4: =[1]data!K5*(_xlfn.XLOOKUP([1]data!$C5,[2]data!$B$2:$B$218,[2]data!J$2:J$218)/100) -> 0.85605657 | O4: =[1]data!L5*(_xlfn.XLOOKUP([1]data!$C5,[2]data!$B$2:$B$218,[2]data!K$2:K$218)/100) -> 0.98550761 | P4: =[1]data!M5*(_xlfn.XLOOKUP([1]data!$C5,[2]data!$B$2:$B$218,[2]data!L$2:L$218)/100) -> 1.1066363 | ... AM4: =[1]data!AJ5*(_xlfn.XLOOKUP([1]data!$C5,[2]data!$B$2:$B$218,[2]data!AI$2:AI$218)/100) -> 1.2267416
A5: IIASA-WiC POP 2023 | B5: SSP2 | C5: United Arab Emirates | D5: ARE | E5: =_xlfn.XLOOKUP(D5,[6]Feuil1!$C$2:$C$248,[6]Feuil1!$B$2:$B$248) -> AE | F5: Population | G5: =_xlfn.XLOOKUP(C5,[3]Sheet1!$B$2:$B$172,[3]Sheet1!$D$2:$D$172) -> Middle East | H5: million | I5: =[1]data!F6*(_xlfn.XLOOKUP([1]data!$C6,[2]data!$B$2:$B$218,[2]data!E$2:E$218)/100) -> 0.03926616 | J5: =[1]data!G6*(_xlfn.XLOOKUP([1]data!$C6,[2]data!$B$2:$B$218,[2]data!F$2:F$218)/100) -> 0.063919762 | K5: =[1]data!H6*(_xlfn.XLOOKUP([1]data!$C6,[2]data!$B$2:$B$218,[2]data!G$2:G$218)/100) -> 0.095359635 | L5: =[1]data!I6*(_xlfn.XLOOKUP([1]data!$C6,[2]data!$B$2:$B$218,[2]data!H$2:H$218)/100) -> 0.13169839 | M5: =[1]data!J6*(_xlfn.XLOOKUP([1]data!$C6,[2]data!$B$2:$B$218,[2]data!I$2:I$218)/100) -> 0.21964471 | N5: =[1]data!K6*(_xlfn.XLOOKUP([1]data!$C6,[2]data!$B$2:$B$218,[2]data!J$2:J$218)/100) -> 0.41292909 | O5: =[1]data!L6*(_xlfn.XLOOKUP([1]data!$C6,[2]data!$B$2:$B$218,[2]data!K$2:K$218)/100) -> 0.77564079 | P5: =[1]data!M6*(_xlfn.XLOOKUP([1]data!$C6,[2]data!$B$2:$B$218,[2]data!L$2:L$218)/100) -> 1.0723731 | ... AM5: =[1]data!AJ6*(_xlfn.XLOOKUP([1]data!$C6,[2]data!$B$2:$B$218,[2]data!AI$2:AI$218)/100) -> 9.2473715
A6: IIASA-WiC POP 2023 | B6: SSP2 | C6: Argentina | D6: ARG | E6: =_xlfn.XLOOKUP(D6,[6]Feuil1!$C$2:$C$248,[6]Feuil1!$B$2:$B$248) -> AR | F6: Population | G6: =_xlfn.XLOOKUP(C6,[3]Sheet1!$B$2:$B$172,[3]Sheet1!$D$2:$D$172) -> Rest of South America | H6: million | I6: =[1]data!F7*(_xlfn.XLOOKUP([1]data!$C7,[2]data!$B$2:$B$218,[2]data!E$2:E$218)/100) -> 11.002842 | J6: =[1]data!G7*(_xlfn.XLOOKUP([1]data!$C7,[2]data!$B$2:$B$218,[2]data!F$2:F$218)/100) -> 12.901961 | K6: =[1]data!H7*(_xlfn.XLOOKUP([1]data!$C7,[2]data!$B$2:$B$218,[2]data!G$2:G$218)/100) -> 14.858079 | L6: =[1]data!I7*(_xlfn.XLOOKUP([1]data!$C7,[2]data!$B$2:$B$218,[2]data!H$2:H$218)/100) -> 16.716499 | M6: =[1]data!J7*(_xlfn.XLOOKUP([1]data!$C7,[2]data!$B$2:$B$218,[2]data!I$2:I$218)/100) -> 18.662215 | N6: =[1]data!K7*(_xlfn.XLOOKUP([1]data!$C7,[2]data!$B$2:$B$218,[2]data!J$2:J$218)/100) -> 20.792515 | O6: =[1]data!L7*(_xlfn.XLOOKUP([1]data!$C7,[2]data!$B$2:$B$218,[2]data!K$2:K$218)/100) -> 23.049862 | P6: =[1]data!M7*(_xlfn.XLOOKUP([1]data!$C7,[2]data!$B$2:$B$218,[2]data!L$2:L$218)/100) -> 25.549523 | ... AM6: =[1]data!AJ7*(_xlfn.XLOOKUP([1]data!$C7,[2]data!$B$2:$B$218,[2]data!AI$2:AI$218)/100) -> 44.770689
A7: IIASA-WiC POP 2023 | B7: SSP2 | C7: Armenia | D7: ARM | E7: =_xlfn.XLOOKUP(D7,[6]Feuil1!$C$2:$C$248,[6]Feuil1!$B$2:$B$248) -> AM | F7: Population | G7: =_xlfn.XLOOKUP(C7,[3]Sheet1!$B$2:$B$172,[3]Sheet1!$D$2:$D$172) -> Russia region | H7: million | I7: =[1]data!F8*(_xlfn.XLOOKUP([1]data!$C8,[2]data!$B$2:$B$218,[2]data!E$2:E$218)/100) -> 0.55053064 | J7: =[1]data!G8*(_xlfn.XLOOKUP([1]data!$C8,[2]data!$B$2:$B$218,[2]data!F$2:F$218)/100) -> 0.72626916 | K7: =[1]data!H8*(_xlfn.XLOOKUP([1]data!$C8,[2]data!$B$2:$B$218,[2]data!G$2:G$218)/100) -> 0.95970809 | L7: =[1]data!I8*(_xlfn.XLOOKUP([1]data!$C8,[2]data!$B$2:$B$218,[2]data!H$2:H$218)/100) -> 1.2248274 | M7: =[1]data!J8*(_xlfn.XLOOKUP([1]data!$C8,[2]data!$B$2:$B$218,[2]data!I$2:I$218)/100) -> 1.5010778 | N7: =[1]data!K8*(_xlfn.XLOOKUP([1]data!$C8,[2]data!$B$2:$B$218,[2]data!J$2:J$218)/100) -> 1.7799236 | O7: =[1]data!L8*(_xlfn.XLOOKUP([1]data!$C8,[2]data!$B$2:$B$218,[2]data!K$2:K$218)/100) -> 2.0617046 | P7: =[1]data!M8*(_xlfn.XLOOKUP([1]data!$C8,[2]data!$B$2:$B$218,[2]data!L$2:L$218)/100) -> 2.2056233 | ... AM7: =[1]data!AJ8*(_xlfn.XLOOKUP([1]data!$C8,[2]data!$B$2:$B$218,[2]data!AI$2:AI$218)/100) -> 1.8269719
A8: IIASA-WiC POP 2023 | B8: SSP2 | C8: Antigua and Barbuda | D8: ATG | E8: =_xlfn.XLOOKUP(D8,[6]Feuil1!$C$2:$C$248,[6]Feuil1!$B$2:$B$248) -> AG | F8: Population | G8: =_xlfn.XLOOKUP(C8,[3]Sheet1!$B$2:$B$172,[3]Sheet1!$D$2:$D$172) -> #N/A | H8: million | I8: =[1]data!F9*(_xlfn.XLOOKUP([1]data!$C9,[2]data!$B$2:$B$218,[2]data!E$2:E$218)/100) -> 0.013529348 | J8: =[1]data!G9*(_xlfn.XLOOKUP([1]data!$C9,[2]data!$B$2:$B$218,[2]data!F$2:F$218)/100) -> 0.01736973 | K8: =[1]data!H9*(_xlfn.XLOOKUP([1]data!$C9,[2]data!$B$2:$B$218,[2]data!G$2:G$218)/100) -> 0.02176354 | L8: =[1]data!I9*(_xlfn.XLOOKUP([1]data!$C9,[2]data!$B$2:$B$218,[2]data!H$2:H$218)/100) -> 0.021653292 | M8: =[1]data!J9*(_xlfn.XLOOKUP([1]data!$C9,[2]data!$B$2:$B$218,[2]data!I$2:I$218)/100) -> 0.021732048 | N8: =[1]data!K9*(_xlfn.XLOOKUP([1]data!$C9,[2]data!$B$2:$B$218,[2]data!J$2:J$218)/100) -> 0.021922542 | O8: =[1]data!L9*(_xlfn.XLOOKUP([1]data!$C9,[2]data!$B$2:$B$218,[2]data!K$2:K$218)/100) -> 0.022414572 | P8: =[1]data!M9*(_xlfn.XLOOKUP([1]data!$C9,[2]data!$B$2:$B$218,[2]data!L$2:L$218)/100) -> 0.0228242 | ... AM8: =[1]data!AJ9*(_xlfn.XLOOKUP([1]data!$C9,[2]data!$B$2:$B$218,[2]data!AI$2:AI$218)/100) -> 0.058231723
A9: IIASA-WiC POP 2023 | B9: SSP2 | C9: Australia | D9: AUS | E9: =_xlfn.XLOOKUP(D9,[6]Feuil1!$C$2:$C$248,[6]Feuil1!$B$2:$B$248) -> AU | F9: Population | G9: =_xlfn.XLOOKUP(C9,[3]Sheet1!$B$2:$B$172,[3]Sheet1!$D$2:$D$172) -> Oceania | H9: million | I9: =[1]data!F10*(_xlfn.XLOOKUP([1]data!$C10,[2]data!$B$2:$B$218,[2]data!E$2:E$218)/100) -> 6.197653 | J9: =[1]data!G10*(_xlfn.XLOOKUP([1]data!$C10,[2]data!$B$2:$B$218,[2]data!F$2:F$218)/100) -> 7.2252182 | K9: =[1]data!H10*(_xlfn.XLOOKUP([1]data!$C10,[2]data!$B$2:$B$218,[2]data!G$2:G$218)/100) -> 8.2916103 | L9: =[1]data!I10*(_xlfn.XLOOKUP([1]data!$C10,[2]data!$B$2:$B$218,[2]data!H$2:H$218)/100) -> 9.34045 | M9: =[1]data!J10*(_xlfn.XLOOKUP([1]data!$C10,[2]data!$B$2:$B$218,[2]data!I$2:I$218)/100) -> 10.410889 | N9: =[1]data!K10*(_xlfn.XLOOKUP([1]data!$C10,[2]data!$B$2:$B$218,[2]data!J$2:J$218)/100) -> 11.710236 | O9: =[1]data!L10*(_xlfn.XLOOKUP([1]data!$C10,[2]data!$B$2:$B$218,[2]data!K$2:K$218)/100) -> 12.501436 | P9: =[1]data!M10*(_xlfn.XLOOKUP([1]data!$C10,[2]data!$B$2:$B$218,[2]data!L$2:L$218)/100) -> 13.420151 | ... AM9: =[1]data!AJ10*(_xlfn.XLOOKUP([1]data!$C10,[2]data!$B$2:$B$218,[2]data!AI$2:AI$218)/100) -> 33.602498
A10: IIASA-WiC POP 2023 | B10: SSP2 | C10: Austria | D10: AUT | E10: =_xlfn.XLOOKUP(D10,[6]Feuil1!$C$2:$C$248,[6]Feuil1!$B$2:$B$248) -> AT | F10: Population | G10: =_xlfn.XLOOKUP(C10,[3]Sheet1!$B$2:$B$172,[3]Sheet1!$D$2:$D$172) -> Western Europe | H10: million | I10: =[1]data!F11*(_xlfn.XLOOKUP([1]data!$C11,[2]data!$B$2:$B$218,[2]data!E$2:E$218)/100) -> 4.4124465 | J10: =[1]data!G11*(_xlfn.XLOOKUP([1]data!$C11,[2]data!$B$2:$B$218,[2]data!F$2:F$218)/100) -> 4.4580043 | K10: =[1]data!H11*(_xlfn.XLOOKUP([1]data!$C11,[2]data!$B$2:$B$218,[2]data!G$2:G$218)/100) -> 4.5479998 | L10: =[1]data!I11*(_xlfn.XLOOKUP([1]data!$C11,[2]data!$B$2:$B$218,[2]data!H$2:H$218)/100) -> 4.7104662 | M10: =[1]data!J11*(_xlfn.XLOOKUP([1]data!$C11,[2]data!$B$2:$B$218,[2]data!I$2:I$218)/100) -> 4.8670493 | N10: =[1]data!K11*(_xlfn.XLOOKUP([1]data!$C11,[2]data!$B$2:$B$218,[2]data!J$2:J$218)/100) -> 4.9564803 | O10: =[1]data!L11*(_xlfn.XLOOKUP([1]data!$C11,[2]data!$B$2:$B$218,[2]data!K$2:K$218)/100) -> 4.9335713 | P10: =[1]data!M11*(_xlfn.XLOOKUP([1]data!$C11,[2]data!$B$2:$B$218,[2]data!L$2:L$218)/100) -> 4.8612639 | ... AM10: =[1]data!AJ11*(_xlfn.XLOOKUP([1]data!$C11,[2]data!$B$2:$B$218,[2]data!AI$2:AI$218)/100) -> 6.9746205
A11: IIASA-WiC POP 2023 | B11: SSP2 | C11: Azerbaijan | D11: AZE | E11: =_xlfn.XLOOKUP(D11,[6]Feuil1!$C$2:$C$248,[6]Feuil1!$B$2:$B$248) -> AZ | F11: Population | G11: =_xlfn.XLOOKUP(C11,[3]Sheet1!$B$2:$B$172,[3]Sheet1!$D$2:$D$172) -> Russia region | H11: million | I11: =[1]data!F12*(_xlfn.XLOOKUP([1]data!$C12,[2]data!$B$2:$B$218,[2]data!E$2:E$218)/100) -> 1.4290308 | J11: =[1]data!G12*(_xlfn.XLOOKUP([1]data!$C12,[2]data!$B$2:$B$218,[2]data!F$2:F$218)/100) -> 1.751056 | K11: =[1]data!H12*(_xlfn.XLOOKUP([1]data!$C12,[2]data!$B$2:$B$218,[2]data!G$2:G$218)/100) -> 2.1415478 | L11: =[1]data!I12*(_xlfn.XLOOKUP([1]data!$C12,[2]data!$B$2:$B$218,[2]data!H$2:H$218)/100) -> 2.4424371 | M11: =[1]data!J12*(_xlfn.XLOOKUP([1]data!$C12,[2]data!$B$2:$B$218,[2]data!I$2:I$218)/100) -> 2.6863245 | N11: =[1]data!K12*(_xlfn.XLOOKUP([1]data!$C12,[2]data!$B$2:$B$218,[2]data!J$2:J$218)/100) -> 3.0496907 | O11: =[1]data!L12*(_xlfn.XLOOKUP([1]data!$C12,[2]data!$B$2:$B$218,[2]data!K$2:K$218)/100) -> 3.3473574 | P11: =[1]data!M12*(_xlfn.XLOOKUP([1]data!$C12,[2]data!$B$2:$B$218,[2]data!L$2:L$218)/100) -> 3.6555796 | ... AM11: =[1]data!AJ12*(_xlfn.XLOOKUP([1]data!$C12,[2]data!$B$2:$B$218,[2]data!AI$2:AI$218)/100) -> 7.7051155
A12: IIASA-WiC POP 2023 | B12: SSP2 | C12: Burundi | D12: BDI | E12: =_xlfn.XLOOKUP(D12,[6]Feuil1!$C$2:$C$248,[6]Feuil1!$B$2:$B$248) -> BI | F12: Population | G12: =_xlfn.XLOOKUP(C12,[3]Sheet1!$B$2:$B$172,[3]Sheet1!$D$2:$D$172) -> Eastern Africa | H12: million | I12: =[1]data!F13*(_xlfn.XLOOKUP([1]data!$C13,[2]data!$B$2:$B$218,[2]data!E$2:E$218)/100) -> 0.037898474 | J12: =[1]data!G13*(_xlfn.XLOOKUP([1]data!$C13,[2]data!$B$2:$B$218,[2]data!F$2:F$218)/100) -> 0.046945086 | K12: =[1]data!H13*(_xlfn.XLOOKUP([1]data!$C13,[2]data!$B$2:$B$218,[2]data!G$2:G$218)/100) -> 0.057114393 | L12: =[1]data!I13*(_xlfn.XLOOKUP([1]data!$C13,[2]data!$B$2:$B$218,[2]data!H$2:H$218)/100) -> 0.070990673 | M12: =[1]data!J13*(_xlfn.XLOOKUP([1]data!$C13,[2]data!$B$2:$B$218,[2]data!I$2:I$218)/100) -> 0.09676828 | N12: =[1]data!K13*(_xlfn.XLOOKUP([1]data!$C13,[2]data!$B$2:$B$218,[2]data!J$2:J$218)/100) -> 0.12988749 | O12: =[1]data!L13*(_xlfn.XLOOKUP([1]data!$C13,[2]data!$B$2:$B$218,[2]data!K$2:K$218)/100) -> 0.17959062 | P12: =[1]data!M13*(_xlfn.XLOOKUP([1]data!$C13,[2]data!$B$2:$B$218,[2]data!L$2:L$218)/100) -> 0.25499365 | ... AM12: =[1]data!AJ13*(_xlfn.XLOOKUP([1]data!$C13,[2]data!$B$2:$B$218,[2]data!AI$2:AI$218)/100) -> 16.372278
A13: IIASA-WiC POP 2023 | B13: SSP2 | C13: Belgium | D13: BEL | E13: =_xlfn.XLOOKUP(D13,[6]Feuil1!$C$2:$C$248,[6]Feuil1!$B$2:$B$248) -> BE | F13: Population | G13: =_xlfn.XLOOKUP(C13,[3]Sheet1!$B$2:$B$172,[3]Sheet1!$D$2:$D$172) -> Western Europe | H13: million | I13: =[1]data!F14*(_xlfn.XLOOKUP([1]data!$C14,[2]data!$B$2:$B$218,[2]data!E$2:E$218)/100) -> 7.8663868 | J13: =[1]data!G14*(_xlfn.XLOOKUP([1]data!$C14,[2]data!$B$2:$B$218,[2]data!F$2:F$218)/100) -> 8.1066131 | K13: =[1]data!H14*(_xlfn.XLOOKUP([1]data!$C14,[2]data!$B$2:$B$218,[2]data!G$2:G$218)/100) -> 8.4007482 | L13: =[1]data!I14*(_xlfn.XLOOKUP([1]data!$C14,[2]data!$B$2:$B$218,[2]data!H$2:H$218)/100) -> 8.7362889 | M13: =[1]data!J14*(_xlfn.XLOOKUP([1]data!$C14,[2]data!$B$2:$B$218,[2]data!I$2:I$218)/100) -> 9.0144867 | N13: =[1]data!K14*(_xlfn.XLOOKUP([1]data!$C14,[2]data!$B$2:$B$218,[2]data!J$2:J$218)/100) -> 9.221688 | O13: =[1]data!L14*(_xlfn.XLOOKUP([1]data!$C14,[2]data!$B$2:$B$218,[2]data!K$2:K$218)/100) -> 9.3701823 | P13: =[1]data!M14*(_xlfn.XLOOKUP([1]data!$C14,[2]data!$B$2:$B$218,[2]data!L$2:L$218)/100) -> 9.4726318 | ... AM13: =[1]data!AJ14*(_xlfn.XLOOKUP([1]data!$C14,[2]data!$B$2:$B$218,[2]data!AI$2:AI$218)/100) -> 12.425616
A14: IIASA-WiC POP 2023 | B14: SSP2 | C14: Benin | D14: BEN | E14: =_xlfn.XLOOKUP(D14,[6]Feuil1!$C$2:$C$248,[6]Feuil1!$B$2:$B$248) -> BJ | F14: Population | G14: =_xlfn.XLOOKUP(C14,[3]Sheet1!$B$2:$B$172,[3]Sheet1!$D$2:$D$172) -> Western Africa | H14: million | I14: =[1]data!F15*(_xlfn.XLOOKUP([1]data!$C15,[2]data!$B$2:$B$218,[2]data!E$2:E$218)/100) -> 0.11282185 | J14: =[1]data!G15*(_xlfn.XLOOKUP([1]data!$C15,[2]data!$B$2:$B$218,[2]data!F$2:F$218)/100) -> 0.15967427 | K14: =[1]data!H15*(_xlfn.XLOOKUP([1]data!$C15,[2]data!$B$2:$B$218,[2]data!G$2:G$218)/100) -> 0.23191736 | L14: =[1]data!I15*(_xlfn.XLOOKUP([1]data!$C15,[2]data!$B$2:$B$218,[2]data!H$2:H$218)/100) -> 0.33875963 | M14: =[1]data!J15*(_xlfn.XLOOKUP([1]data!$C15,[2]data!$B$2:$B$218,[2]data!I$2:I$218)/100) -> 0.4996139 | N14: =[1]data!K15*(_xlfn.XLOOKUP([1]data!$C15,[2]data!$B$2:$B$218,[2]data!J$2:J$218)/100) -> 0.73124866 | O14: =[1]data!L15*(_xlfn.XLOOKUP([1]data!$C15,[2]data!$B$2:$B$218,[2]data!K$2:K$218)/100) -> 1.0323645 | P14: =[1]data!M15*(_xlfn.XLOOKUP([1]data!$C15,[2]data!$B$2:$B$218,[2]data!L$2:L$218)/100) -> 1.3413526 | ... AM14: =[1]data!AJ15*(_xlfn.XLOOKUP([1]data!$C15,[2]data!$B$2:$B$218,[2]data!AI$2:AI$218)/100) -> 27.34143
... A19: IIASA-WiC POP 2023 | B19: SSP2 | C19: Bahamas | D19: BHS | E19: =_xlfn.XLOOKUP(D19,[6]Feuil1!$C$2:$C$248,[6]Feuil1!$B$2:$B$248) -> BS | F19: Population | G19: =_xlfn.XLOOKUP(C19,[3]Sheet1!$B$2:$B$172,[3]Sheet1!$D$2:$D$172) -> Central America | H19: million | I19: =[1]data!F20*(_xlfn.XLOOKUP([1]data!$C20,[2]data!$B$2:$B$218,[2]data!E$2:E$218)/100) -> 0.04226352 | J19: =[1]data!G20*(_xlfn.XLOOKUP([1]data!$C20,[2]data!$B$2:$B$218,[2]data!F$2:F$218)/100) -> 0.050747138 | K19: =[1]data!H20*(_xlfn.XLOOKUP([1]data!$C20,[2]data!$B$2:$B$218,[2]data!G$2:G$218)/100) -> 0.066718929 | L19: =[1]data!I20*(_xlfn.XLOOKUP([1]data!$C20,[2]data!$B$2:$B$218,[2]data!H$2:H$218)/100) -> 0.089703063 | M19: =[1]data!J20*(_xlfn.XLOOKUP([1]data!$C20,[2]data!$B$2:$B$218,[2]data!I$2:I$218)/100) -> 0.11777775 | N19: =[1]data!K20*(_xlfn.XLOOKUP([1]data!$C20,[2]data!$B$2:$B$218,[2]data!J$2:J$218)/100) -> 0.1398908 | O19: =[1]data!L20*(_xlfn.XLOOKUP([1]data!$C20,[2]data!$B$2:$B$218,[2]data!K$2:K$218)/100) -> 0.16199983 | P19: =[1]data!M20*(_xlfn.XLOOKUP([1]data!$C20,[2]data!$B$2:$B$218,[2]data!L$2:L$218)/100) -> 0.18675913 | ... AM19: =[1]data!AJ20*(_xlfn.XLOOKUP([1]data!$C20,[2]data!$B$2:$B$218,[2]data!AI$2:AI$218)/100) -> 0.38049123
A20: IIASA-WiC POP 2023 | B20: SSP2 | C20: Bosnia and Herzegovina | D20: BIH | E20: =_xlfn.XLOOKUP(D20,[6]Feuil1!$C$2:$C$248,[6]Feuil1!$B$2:$B$248) -> BA | F20: Population | G20: Central Europe | H20: million | I20: =[1]data!F21*(_xlfn.XLOOKUP([1]data!$C21,[2]data!$B$2:$B$218,[2]data!E$2:E$218)/100) -> 0.36590563 | J20: =[1]data!G21*(_xlfn.XLOOKUP([1]data!$C21,[2]data!$B$2:$B$218,[2]data!F$2:F$218)/100) -> 0.47443223 | K20: =[1]data!H21*(_xlfn.XLOOKUP([1]data!$C21,[2]data!$B$2:$B$218,[2]data!G$2:G$218)/100) -> 0.61390691 | L20: =[1]data!I21*(_xlfn.XLOOKUP([1]data!$C21,[2]data!$B$2:$B$218,[2]data!H$2:H$218)/100) -> 0.80648137 | M20: =[1]data!J21*(_xlfn.XLOOKUP([1]data!$C21,[2]data!$B$2:$B$218,[2]data!I$2:I$218)/100) -> 1.0318298 | N20: =[1]data!K21*(_xlfn.XLOOKUP([1]data!$C21,[2]data!$B$2:$B$218,[2]data!J$2:J$218)/100) -> 1.2528633 | O20: =[1]data!L21*(_xlfn.XLOOKUP([1]data!$C21,[2]data!$B$2:$B$218,[2]data!K$2:K$218)/100) -> 1.484736 | P20: =[1]data!M21*(_xlfn.XLOOKUP([1]data!$C21,[2]data!$B$2:$B$218,[2]data!L$2:L$218)/100) -> 1.642189 | ... AM20: =[1]data!AJ21*(_xlfn.XLOOKUP([1]data!$C21,[2]data!$B$2:$B$218,[2]data!AI$2:AI$218)/100) -> 1.3439226
A21: IIASA-WiC POP 2023 | B21: SSP2 | C21: Belarus | D21: BLR | E21: =_xlfn.XLOOKUP(D21,[6]Feuil1!$C$2:$C$248,[6]Feuil1!$B$2:$B$248) -> BY | F21: Population | G21: =_xlfn.XLOOKUP(C21,[3]Sheet1!$B$2:$B$172,[3]Sheet1!$D$2:$D$172) -> Ukraine region | H21: million | I21: =[1]data!F22*(_xlfn.XLOOKUP([1]data!$C22,[2]data!$B$2:$B$218,[2]data!E$2:E$218)/100) -> 2.0768161 | J21: =[1]data!G22*(_xlfn.XLOOKUP([1]data!$C22,[2]data!$B$2:$B$218,[2]data!F$2:F$218)/100) -> 2.2971746 | K21: =[1]data!H22*(_xlfn.XLOOKUP([1]data!$C22,[2]data!$B$2:$B$218,[2]data!G$2:G$218)/100) -> 2.7010299 | L21: =[1]data!I22*(_xlfn.XLOOKUP([1]data!$C22,[2]data!$B$2:$B$218,[2]data!H$2:H$218)/100) -> 3.3602653 | M21: =[1]data!J22*(_xlfn.XLOOKUP([1]data!$C22,[2]data!$B$2:$B$218,[2]data!I$2:I$218)/100) -> 4.0210342 | N21: =[1]data!K22*(_xlfn.XLOOKUP([1]data!$C22,[2]data!$B$2:$B$218,[2]data!J$2:J$218)/100) -> 4.7914359 | O21: =[1]data!L22*(_xlfn.XLOOKUP([1]data!$C22,[2]data!$B$2:$B$218,[2]data!K$2:K$218)/100) -> 5.5297098 | P21: =[1]data!M22*(_xlfn.XLOOKUP([1]data!$C22,[2]data!$B$2:$B$218,[2]data!L$2:L$218)/100) -> 6.2428117 | ... AM21: =[1]data!AJ22*(_xlfn.XLOOKUP([1]data!$C22,[2]data!$B$2:$B$218,[2]data!AI$2:AI$218)/100) -> 6.7726613
A22: IIASA-WiC POP 2023 | B22: SSP2 | C22: Belize | D22: BLZ | E22: =_xlfn.XLOOKUP(D22,[6]Feuil1!$C$2:$C$248,[6]Feuil1!$B$2:$B$248) -> BZ | F22: Population | G22: =_xlfn.XLOOKUP(C22,[3]Sheet1!$B$2:$B$172,[3]Sheet1!$D$2:$D$172) -> Central America | H22: million | I22: =[1]data!F23*(_xlfn.XLOOKUP([1]data!$C23,[2]data!$B$2:$B$218,[2]data!E$2:E$218)/100) -> 0.037689715 | J22: =[1]data!G23*(_xlfn.XLOOKUP([1]data!$C23,[2]data!$B$2:$B$218,[2]data!F$2:F$218)/100) -> 0.043152283 | K22: =[1]data!H23*(_xlfn.XLOOKUP([1]data!$C23,[2]data!$B$2:$B$218,[2]data!G$2:G$218)/100) -> 0.04872042 | L22: =[1]data!I23*(_xlfn.XLOOKUP([1]data!$C23,[2]data!$B$2:$B$218,[2]data!H$2:H$218)/100) -> 0.0542136 | M22: =[1]data!J23*(_xlfn.XLOOKUP([1]data!$C23,[2]data!$B$2:$B$218,[2]data!I$2:I$218)/100) -> 0.06107199 | N22: =[1]data!K23*(_xlfn.XLOOKUP([1]data!$C23,[2]data!$B$2:$B$218,[2]data!J$2:J$218)/100) -> 0.064997454 | O22: =[1]data!L23*(_xlfn.XLOOKUP([1]data!$C23,[2]data!$B$2:$B$218,[2]data!K$2:K$218)/100) -> 0.07080502 | P22: =[1]data!M23*(_xlfn.XLOOKUP([1]data!$C23,[2]data!$B$2:$B$218,[2]data!L$2:L$218)/100) -> 0.078196008 | ... AM22: =[1]data!AJ23*(_xlfn.XLOOKUP([1]data!$C23,[2]data!$B$2:$B$218,[2]data!AI$2:AI$218)/100) -> 0.44823678
A23: IIASA-WiC POP 2023 | B23: SSP2 | C23: Bolivia | D23: BOL | E23: =_xlfn.XLOOKUP(D23,[6]Feuil1!$C$2:$C$248,[6]Feuil1!$B$2:$B$248) -> BO | F23: Population | G23: =_xlfn.XLOOKUP(C23,[3]Sheet1!$B$2:$B$172,[3]Sheet1!$D$2:$D$172) -> Rest of South America | H23: million | I23: =[1]data!F24*(_xlfn.XLOOKUP([1]data!$C24,[2]data!$B$2:$B$218,[2]data!E$2:E$218)/100) -> 1.0366744 | J23: =[1]data!G24*(_xlfn.XLOOKUP([1]data!$C24,[2]data!$B$2:$B$218,[2]data!F$2:F$218)/100) -> 1.1743985 | K23: =[1]data!H24*(_xlfn.XLOOKUP([1]data!$C24,[2]data!$B$2:$B$218,[2]data!G$2:G$218)/100) -> 1.3503451 | L23: =[1]data!I24*(_xlfn.XLOOKUP([1]data!$C24,[2]data!$B$2:$B$218,[2]data!H$2:H$218)/100) -> 1.559535 | M23: =[1]data!J24*(_xlfn.XLOOKUP([1]data!$C24,[2]data!$B$2:$B$218,[2]data!I$2:I$218)/100) -> 1.8050223 | N23: =[1]data!K24*(_xlfn.XLOOKUP([1]data!$C24,[2]data!$B$2:$B$218,[2]data!J$2:J$218)/100) -> 2.0940174 | O23: =[1]data!L24*(_xlfn.XLOOKUP([1]data!$C24,[2]data!$B$2:$B$218,[2]data!K$2:K$218)/100) -> 2.581174 | P23: =[1]data!M24*(_xlfn.XLOOKUP([1]data!$C24,[2]data!$B$2:$B$218,[2]data!L$2:L$218)/100) -> 3.1906577 | ... AM23: =[1]data!AJ24*(_xlfn.XLOOKUP([1]data!$C24,[2]data!$B$2:$B$218,[2]data!AI$2:AI$218)/100) -> 14.431116
A24: IIASA-WiC POP 2023 | B24: SSP2 | C24: Brazil | D24: BRA | E24: =_xlfn.XLOOKUP(D24,[6]Feuil1!$C$2:$C$248,[6]Feuil1!$B$2:$B$248) -> BR | F24: Population | G24: =_xlfn.XLOOKUP(C24,[3]Sheet1!$B$2:$B$172,[3]Sheet1!$D$2:$D$172) -> Brazil | H24: million | I24: =[1]data!F25*(_xlfn.XLOOKUP([1]data!$C25,[2]data!$B$2:$B$218,[2]data!E$2:E$218)/100) -> 19.240988 | J24: =[1]data!G25*(_xlfn.XLOOKUP([1]data!$C25,[2]data!$B$2:$B$218,[2]data!F$2:F$218)/100) -> 25.378101 | K24: =[1]data!H25*(_xlfn.XLOOKUP([1]data!$C25,[2]data!$B$2:$B$218,[2]data!G$2:G$218)/100) -> 33.181238 | L24: =[1]data!I25*(_xlfn.XLOOKUP([1]data!$C25,[2]data!$B$2:$B$218,[2]data!H$2:H$218)/100) -> 42.555048 | M24: =[1]data!J25*(_xlfn.XLOOKUP([1]data!$C25,[2]data!$B$2:$B$218,[2]data!I$2:I$218)/100) -> 53.203666 | N24: =[1]data!K25*(_xlfn.XLOOKUP([1]data!$C25,[2]data!$B$2:$B$218,[2]data!J$2:J$218)/100) -> 65.311599 | O24: =[1]data!L25*(_xlfn.XLOOKUP([1]data!$C25,[2]data!$B$2:$B$218,[2]data!K$2:K$218)/100) -> 79.158874 | P24: =[1]data!M25*(_xlfn.XLOOKUP([1]data!$C25,[2]data!$B$2:$B$218,[2]data!L$2:L$218)/100) -> 94.602941 | ... AM24: =[1]data!AJ25*(_xlfn.XLOOKUP([1]data!$C25,[2]data!$B$2:$B$218,[2]data!AI$2:AI$218)/100) -> 174.61606
A25: IIASA-WiC POP 2023 | B25: SSP2 | C25: Barbados | D25: BRB | E25: =_xlfn.XLOOKUP(D25,[6]Feuil1!$C$2:$C$248,[6]Feuil1!$B$2:$B$248) -> BB | F25: Population | G25: Central America | H25: million | I25: =[1]data!F26*(_xlfn.XLOOKUP([1]data!$C26,[2]data!$B$2:$B$218,[2]data!E$2:E$218)/100) -> 0.075048651 | J25: =[1]data!G26*(_xlfn.XLOOKUP([1]data!$C26,[2]data!$B$2:$B$218,[2]data!F$2:F$218)/100) -> 0.08242416 | K25: =[1]data!H26*(_xlfn.XLOOKUP([1]data!$C26,[2]data!$B$2:$B$218,[2]data!G$2:G$218)/100) -> 0.085373056 | L25: =[1]data!I26*(_xlfn.XLOOKUP([1]data!$C26,[2]data!$B$2:$B$218,[2]data!H$2:H$218)/100) -> 0.088033848 | M25: =[1]data!J26*(_xlfn.XLOOKUP([1]data!$C26,[2]data!$B$2:$B$218,[2]data!I$2:I$218)/100) -> 0.090603216 | N25: =[1]data!K26*(_xlfn.XLOOKUP([1]data!$C26,[2]data!$B$2:$B$218,[2]data!J$2:J$218)/100) -> 0.095873718 | O25: =[1]data!L26*(_xlfn.XLOOKUP([1]data!$C26,[2]data!$B$2:$B$218,[2]data!K$2:K$218)/100) -> 0.10144338 | P25: =[1]data!M26*(_xlfn.XLOOKUP([1]data!$C26,[2]data!$B$2:$B$218,[2]data!L$2:L$218)/100) -> 0.099705906 | ... AM25: =[1]data!AJ26*(_xlfn.XLOOKUP([1]data!$C26,[2]data!$B$2:$B$218,[2]data!AI$2:AI$218)/100) -> 0.17681969
A26: IIASA-WiC POP 2023 | B26: SSP2 | C26: Brunei Darussalam | D26: BRN | E26: =_xlfn.XLOOKUP(D26,[6]Feuil1!$C$2:$C$248,[6]Feuil1!$B$2:$B$248) -> BN | F26: Population | G26: Southeastern Asia | H26: million | I26: =[1]data!F27*(_xlfn.XLOOKUP([1]data!$C27,[2]data!$B$2:$B$218,[2]data!E$2:E$218)/100) -> 0.012558212 | J26: =[1]data!G27*(_xlfn.XLOOKUP([1]data!$C27,[2]data!$B$2:$B$218,[2]data!F$2:F$218)/100) -> 0.021577944 | K26: =[1]data!H27*(_xlfn.XLOOKUP([1]data!$C27,[2]data!$B$2:$B$218,[2]data!G$2:G$218)/100) -> 0.036122254 | L26: =[1]data!I27*(_xlfn.XLOOKUP([1]data!$C27,[2]data!$B$2:$B$218,[2]data!H$2:H$218)/100) -> 0.055369916 | M26: =[1]data!J27*(_xlfn.XLOOKUP([1]data!$C27,[2]data!$B$2:$B$218,[2]data!I$2:I$218)/100) -> 0.080619688 | N26: =[1]data!K27*(_xlfn.XLOOKUP([1]data!$C27,[2]data!$B$2:$B$218,[2]data!J$2:J$218)/100) -> 0.10076832 | O26: =[1]data!L27*(_xlfn.XLOOKUP([1]data!$C27,[2]data!$B$2:$B$218,[2]data!K$2:K$218)/100) -> 0.11999231 | P26: =[1]data!M27*(_xlfn.XLOOKUP([1]data!$C27,[2]data!$B$2:$B$218,[2]data!L$2:L$218)/100) -> 0.14344478 | ... AM26: =[1]data!AJ27*(_xlfn.XLOOKUP([1]data!$C27,[2]data!$B$2:$B$218,[2]data!AI$2:AI$218)/100) -> 0.48775752
A27: IIASA-WiC POP 2023 | B27: SSP2 | C27: Bhutan | D27: BTN | E27: =_xlfn.XLOOKUP(D27,[6]Feuil1!$C$2:$C$248,[6]Feuil1!$B$2:$B$248) -> BT | F27: Population | G27: Rest of South Asia | H27: million | I27: =[1]data!F28*(_xlfn.XLOOKUP([1]data!$C28,[2]data!$B$2:$B$218,[2]data!E$2:E$218)/100) -> 0.003668931 | J27: =[1]data!G28*(_xlfn.XLOOKUP([1]data!$C28,[2]data!$B$2:$B$218,[2]data!F$2:F$218)/100) -> 0.005425308 | K27: =[1]data!H28*(_xlfn.XLOOKUP([1]data!$C28,[2]data!$B$2:$B$218,[2]data!G$2:G$218)/100) -> 0.007864236 | L27: =[1]data!I28*(_xlfn.XLOOKUP([1]data!$C28,[2]data!$B$2:$B$218,[2]data!H$2:H$218)/100) -> 0.011802922 | M27: =[1]data!J28*(_xlfn.XLOOKUP([1]data!$C28,[2]data!$B$2:$B$218,[2]data!I$2:I$218)/100) -> 0.017934549 | N27: =[1]data!K28*(_xlfn.XLOOKUP([1]data!$C28,[2]data!$B$2:$B$218,[2]data!J$2:J$218)/100) -> 0.02736955 | O27: =[1]data!L28*(_xlfn.XLOOKUP([1]data!$C28,[2]data!$B$2:$B$218,[2]data!K$2:K$218)/100) -> 0.041269307 | P27: =[1]data!M28*(_xlfn.XLOOKUP([1]data!$C28,[2]data!$B$2:$B$218,[2]data!L$2:L$218)/100) -> 0.061570668 | ... AM27: =[1]data!AJ28*(_xlfn.XLOOKUP([1]data!$C28,[2]data!$B$2:$B$218,[2]data!AI$2:AI$218)/100) -> 0.52196766
A28: IIASA-WiC POP 2023 | B28: SSP2 | C28: Botswana | D28: BWA | E28: =_xlfn.XLOOKUP(D28,[6]Feuil1!$C$2:$C$248,[6]Feuil1!$B$2:$B$248) -> BW | F28: Population | G28: =_xlfn.XLOOKUP(C28,[3]Sheet1!$B$2:$B$172,[3]Sheet1!$D$2:$D$172) -> Rest of Southern Africa | H28: million | I28: =[1]data!F29*(_xlfn.XLOOKUP([1]data!$C29,[2]data!$B$2:$B$218,[2]data!E$2:E$218)/100) -> 0.011038437 | J28: =[1]data!G29*(_xlfn.XLOOKUP([1]data!$C29,[2]data!$B$2:$B$218,[2]data!F$2:F$218)/100) -> 0.013255958 | K28: =[1]data!H29*(_xlfn.XLOOKUP([1]data!$C29,[2]data!$B$2:$B$218,[2]data!G$2:G$218)/100) -> 0.015723944 | L28: =[1]data!I29*(_xlfn.XLOOKUP([1]data!$C29,[2]data!$B$2:$B$218,[2]data!H$2:H$218)/100) -> 0.021622874 | M28: =[1]data!J29*(_xlfn.XLOOKUP([1]data!$C29,[2]data!$B$2:$B$218,[2]data!I$2:I$218)/100) -> 0.045928662 | N28: =[1]data!K29*(_xlfn.XLOOKUP([1]data!$C29,[2]data!$B$2:$B$218,[2]data!J$2:J$218)/100) -> 0.08439837 | O28: =[1]data!L29*(_xlfn.XLOOKUP([1]data!$C29,[2]data!$B$2:$B$218,[2]data!K$2:K$218)/100) -> 0.15112812 | P28: =[1]data!M29*(_xlfn.XLOOKUP([1]data!$C29,[2]data!$B$2:$B$218,[2]data!L$2:L$218)/100) -> 0.29868169 | ... AM28: =[1]data!AJ29*(_xlfn.XLOOKUP([1]data!$C29,[2]data!$B$2:$B$218,[2]data!AI$2:AI$218)/100) -> 3.002959
A29: IIASA-WiC POP 2023 | B29: SSP2 | C29: Central African Republic | D29: CAF | E29: =_xlfn.XLOOKUP(D29,[6]Feuil1!$C$2:$C$248,[6]Feuil1!$B$2:$B$248) -> CF | F29: Population | G29: =_xlfn.XLOOKUP(C29,[3]Sheet1!$B$2:$B$172,[3]Sheet1!$D$2:$D$172) -> Western Africa | H29: million | I29: =[1]data!F30*(_xlfn.XLOOKUP([1]data!$C30,[2]data!$B$2:$B$218,[2]data!E$2:E$218)/100) -> 0.20541816 | J29: =[1]data!G30*(_xlfn.XLOOKUP([1]data!$C30,[2]data!$B$2:$B$218,[2]data!F$2:F$218)/100) -> 0.26229057 | K29: =[1]data!H30*(_xlfn.XLOOKUP([1]data!$C30,[2]data!$B$2:$B$218,[2]data!G$2:G$218)/100) -> 0.33461797 | L29: =[1]data!I30*(_xlfn.XLOOKUP([1]data!$C30,[2]data!$B$2:$B$218,[2]data!H$2:H$218)/100) -> 0.43003261 | M29: =[1]data!J30*(_xlfn.XLOOKUP([1]data!$C30,[2]data!$B$2:$B$218,[2]data!I$2:I$218)/100) -> 0.56236318 | N29: =[1]data!K30*(_xlfn.XLOOKUP([1]data!$C30,[2]data!$B$2:$B$218,[2]data!J$2:J$218)/100) -> 0.7236272 | O29: =[1]data!L30*(_xlfn.XLOOKUP([1]data!$C30,[2]data!$B$2:$B$218,[2]data!K$2:K$218)/100) -> 0.81450242 | P29: =[1]data!M30*(_xlfn.XLOOKUP([1]data!$C30,[2]data!$B$2:$B$218,[2]data!L$2:L$218)/100) -> 0.90099745 | ... AM29: =[1]data!AJ30*(_xlfn.XLOOKUP([1]data!$C30,[2]data!$B$2:$B$218,[2]data!AI$2:AI$218)/100) -> 13.687156
A30: IIASA-WiC POP 2023 | B30: SSP2 | C30: Canada | D30: CAN | E30: =_xlfn.XLOOKUP(D30,[6]Feuil1!$C$2:$C$248,[6]Feuil1!$B$2:$B$248) -> CA | F30: Population | G30: =_xlfn.XLOOKUP(C30,[3]Sheet1!$B$2:$B$172,[3]Sheet1!$D$2:$D$172) -> Canada | H30: million | I30: =[1]data!F31*(_xlfn.XLOOKUP([1]data!$C31,[2]data!$B$2:$B$218,[2]data!E$2:E$218)/100) -> 8.2784969 | J30: =[1]data!G31*(_xlfn.XLOOKUP([1]data!$C31,[2]data!$B$2:$B$218,[2]data!F$2:F$218)/100) -> 10.207114 | K30: =[1]data!H31*(_xlfn.XLOOKUP([1]data!$C31,[2]data!$B$2:$B$218,[2]data!G$2:G$218)/100) -> 12.245174 | L30: =[1]data!I31*(_xlfn.XLOOKUP([1]data!$C31,[2]data!$B$2:$B$218,[2]data!H$2:H$218)/100) -> 14.219676 | M30: =[1]data!J31*(_xlfn.XLOOKUP([1]data!$C31,[2]data!$B$2:$B$218,[2]data!I$2:I$218)/100) -> 16.034425 | N30: =[1]data!K31*(_xlfn.XLOOKUP([1]data!$C31,[2]data!$B$2:$B$218,[2]data!J$2:J$218)/100) -> 17.369482 | O30: =[1]data!L31*(_xlfn.XLOOKUP([1]data!$C31,[2]data!$B$2:$B$218,[2]data!K$2:K$218)/100) -> 18.437686 | P30: =[1]data!M31*(_xlfn.XLOOKUP([1]data!$C31,[2]data!$B$2:$B$218,[2]data!L$2:L$218)/100) -> 19.650786 | ... AM30: =[1]data!AJ31*(_xlfn.XLOOKUP([1]data!$C31,[2]data!$B$2:$B$218,[2]data!AI$2:AI$218)/100) -> 41.823939
A31: IIASA-WiC POP 2023 | B31: SSP2 | C31: Switzerland | D31: CHE | E31: =_xlfn.XLOOKUP(D31,[6]Feuil1!$C$2:$C$248,[6]Feuil1!$B$2:$B$248) -> CH | F31: Population | G31: =_xlfn.XLOOKUP(C31,[3]Sheet1!$B$2:$B$172,[3]Sheet1!$D$2:$D$172) -> Western Europe | H31: million | I31: =[1]data!F32*(_xlfn.XLOOKUP([1]data!$C32,[2]data!$B$2:$B$218,[2]data!E$2:E$218)/100) -> 3.1462913 | J31: =[1]data!G32*(_xlfn.XLOOKUP([1]data!$C32,[2]data!$B$2:$B$218,[2]data!F$2:F$218)/100) -> 3.4347578 | K31: =[1]data!H32*(_xlfn.XLOOKUP([1]data!$C32,[2]data!$B$2:$B$218,[2]data!G$2:G$218)/100) -> 3.7549009 | L31: =[1]data!I32*(_xlfn.XLOOKUP([1]data!$C32,[2]data!$B$2:$B$218,[2]data!H$2:H$218)/100) -> 4.2207122 | M31: =[1]data!J32*(_xlfn.XLOOKUP([1]data!$C32,[2]data!$B$2:$B$218,[2]data!I$2:I$218)/100) -> 4.552781 | N31: =[1]data!K32*(_xlfn.XLOOKUP([1]data!$C32,[2]data!$B$2:$B$218,[2]data!J$2:J$218)/100) -> 4.7161335 | O31: =[1]data!L32*(_xlfn.XLOOKUP([1]data!$C32,[2]data!$B$2:$B$218,[2]data!K$2:K$218)/100) -> 4.6960352 | P31: =[1]data!M32*(_xlfn.XLOOKUP([1]data!$C32,[2]data!$B$2:$B$218,[2]data!L$2:L$218)/100) -> 4.7899083 | ... AM31: =[1]data!AJ32*(_xlfn.XLOOKUP([1]data!$C32,[2]data!$B$2:$B$218,[2]data!AI$2:AI$218)/100) -> 9.4617805
A32: IIASA-WiC POP 2023 | B32: SSP2 | C32: Chile | D32: CHL | E32: =_xlfn.XLOOKUP(D32,[6]Feuil1!$C$2:$C$248,[6]Feuil1!$B$2:$B$248) -> CL | F32: Population | G32: =_xlfn.XLOOKUP(C32,[3]Sheet1!$B$2:$B$172,[3]Sheet1!$D$2:$D$172) -> Rest of South America | H32: million | I32: =[1]data!F33*(_xlfn.XLOOKUP([1]data!$C33,[2]data!$B$2:$B$218,[2]data!E$2:E$218)/100) -> 3.8333141 | J32: =[1]data!G33*(_xlfn.XLOOKUP([1]data!$C33,[2]data!$B$2:$B$218,[2]data!F$2:F$218)/100) -> 4.5870497 | K32: =[1]data!H33*(_xlfn.XLOOKUP([1]data!$C33,[2]data!$B$2:$B$218,[2]data!G$2:G$218)/100) -> 5.462227 | L32: =[1]data!I33*(_xlfn.XLOOKUP([1]data!$C33,[2]data!$B$2:$B$218,[2]data!H$2:H$218)/100) -> 6.3888335 | M32: =[1]data!J33*(_xlfn.XLOOKUP([1]data!$C33,[2]data!$B$2:$B$218,[2]data!I$2:I$218)/100) -> 7.3231241 | N32: =[1]data!K33*(_xlfn.XLOOKUP([1]data!$C33,[2]data!$B$2:$B$218,[2]data!J$2:J$218)/100) -> 8.2753889 | O32: =[1]data!L33*(_xlfn.XLOOKUP([1]data!$C33,[2]data!$B$2:$B$218,[2]data!K$2:K$218)/100) -> 9.2461352 | P32: =[1]data!M33*(_xlfn.XLOOKUP([1]data!$C33,[2]data!$B$2:$B$218,[2]data!L$2:L$218)/100) -> 10.106004 | ... AM32: =[1]data!AJ33*(_xlfn.XLOOKUP([1]data!$C33,[2]data!$B$2:$B$218,[2]data!AI$2:AI$218)/100) -> 16.221197
A33: IIASA-WiC POP 2023 | B33: SSP2 | C33: China | D33: CHN | E33: =_xlfn.XLOOKUP(D33,[6]Feuil1!$C$2:$C$248,[6]Feuil1!$B$2:$B$248) -> CN | F33: Population | G33: =_xlfn.XLOOKUP(C33,[3]Sheet1!$B$2:$B$172,[3]Sheet1!$D$2:$D$172) -> China region | H33: million | I33: =[1]data!F34*(_xlfn.XLOOKUP([1]data!$C34,[2]data!$B$2:$B$218,[2]data!E$2:E$218)/100) -> 63.624421 | J33: =[1]data!G34*(_xlfn.XLOOKUP([1]data!$C34,[2]data!$B$2:$B$218,[2]data!F$2:F$218)/100) -> 82.92242 | K33: =[1]data!H34*(_xlfn.XLOOKUP([1]data!$C34,[2]data!$B$2:$B$218,[2]data!G$2:G$218)/100) -> 105.9952 | L33: =[1]data!I34*(_xlfn.XLOOKUP([1]data!$C34,[2]data!$B$2:$B$218,[2]data!H$2:H$218)/100) -> 129.25916 | M33: =[1]data!J34*(_xlfn.XLOOKUP([1]data!$C34,[2]data!$B$2:$B$218,[2]data!I$2:I$218)/100) -> 141.25097 | N33: =[1]data!K34*(_xlfn.XLOOKUP([1]data!$C34,[2]data!$B$2:$B$218,[2]data!J$2:J$218)/100) -> 157.96117 | O33: =[1]data!L34*(_xlfn.XLOOKUP([1]data!$C34,[2]data!$B$2:$B$218,[2]data!K$2:K$218)/100) -> 189.18053 | P33: =[1]data!M34*(_xlfn.XLOOKUP([1]data!$C34,[2]data!$B$2:$B$218,[2]data!L$2:L$218)/100) -> 240.89093 | ... AM33: =[1]data!AJ34*(_xlfn.XLOOKUP([1]data!$C34,[2]data!$B$2:$B$218,[2]data!AI$2:AI$218)/100) -> 660.05001
A34: IIASA-WiC POP 2023 | B34: SSP2 | C34: Cote d'Ivoire | D34: CIV | E34: =_xlfn.XLOOKUP(D34,[6]Feuil1!$C$2:$C$248,[6]Feuil1!$B$2:$B$248) -> CI | F34: Population | G34: Western Africa | H34: million | I34: =[1]data!F35*(_xlfn.XLOOKUP([1]data!$C35,[2]data!$B$2:$B$218,[2]data!E$2:E$218)/100) -> 0.2698514 | J34: =[1]data!G35*(_xlfn.XLOOKUP([1]data!$C35,[2]data!$B$2:$B$218,[2]data!F$2:F$218)/100) -> 0.4070673 | K34: =[1]data!H35*(_xlfn.XLOOKUP([1]data!$C35,[2]data!$B$2:$B$218,[2]data!G$2:G$218)/100) -> 0.64455329 | L34: =[1]data!I35*(_xlfn.XLOOKUP([1]data!$C35,[2]data!$B$2:$B$218,[2]data!H$2:H$218)/100) -> 1.07935 | M34: =[1]data!J35*(_xlfn.XLOOKUP([1]data!$C35,[2]data!$B$2:$B$218,[2]data!I$2:I$218)/100) -> 1.5118976 | N34: =[1]data!K35*(_xlfn.XLOOKUP([1]data!$C35,[2]data!$B$2:$B$218,[2]data!J$2:J$218)/100) -> 2.1568107 | O34: =[1]data!L35*(_xlfn.XLOOKUP([1]data!$C35,[2]data!$B$2:$B$218,[2]data!K$2:K$218)/100) -> 2.9982123 | P34: =[1]data!M35*(_xlfn.XLOOKUP([1]data!$C35,[2]data!$B$2:$B$218,[2]data!L$2:L$218)/100) -> 3.7111703 | ... AM34: =[1]data!AJ35*(_xlfn.XLOOKUP([1]data!$C35,[2]data!$B$2:$B$218,[2]data!AI$2:AI$218)/100) -> 43.455607
A35: IIASA-WiC POP 2023 | B35: SSP2 | C35: Cameroon | D35: CMR | E35: =_xlfn.XLOOKUP(D35,[6]Feuil1!$C$2:$C$248,[6]Feuil1!$B$2:$B$248) -> CM | F35: Population | G35: =_xlfn.XLOOKUP(C35,[3]Sheet1!$B$2:$B$172,[3]Sheet1!$D$2:$D$172) -> Western Africa | H35: million | I35: =[1]data!F36*(_xlfn.XLOOKUP([1]data!$C36,[2]data!$B$2:$B$218,[2]data!E$2:E$218)/100) -> 0.39832337 | J35: =[1]data!G36*(_xlfn.XLOOKUP([1]data!$C36,[2]data!$B$2:$B$218,[2]data!F$2:F$218)/100) -> 0.52784428 | K35: =[1]data!H36*(_xlfn.XLOOKUP([1]data!$C36,[2]data!$B$2:$B$218,[2]data!G$2:G$218)/100) -> 0.70582004 | L35: =[1]data!I36*(_xlfn.XLOOKUP([1]data!$C36,[2]data!$B$2:$B$218,[2]data!H$2:H$218)/100) -> 0.9500744 | M35: =[1]data!J36*(_xlfn.XLOOKUP([1]data!$C36,[2]data!$B$2:$B$218,[2]data!I$2:I$218)/100) -> 1.2926072 | N35: =[1]data!K36*(_xlfn.XLOOKUP([1]data!$C36,[2]data!$B$2:$B$218,[2]data!J$2:J$218)/100) -> 1.991345 | O35: =[1]data!L36*(_xlfn.XLOOKUP([1]data!$C36,[2]data!$B$2:$B$218,[2]data!K$2:K$218)/100) -> 2.6663044 | P35: =[1]data!M36*(_xlfn.XLOOKUP([1]data!$C36,[2]data!$B$2:$B$218,[2]data!L$2:L$218)/100) -> 3.4944352 | ... AM35: =[1]data!AJ36*(_xlfn.XLOOKUP([1]data!$C36,[2]data!$B$2:$B$218,[2]data!AI$2:AI$218)/100) -> 49.049704
A36: IIASA-WiC POP 2023 | B36: SSP2 | C36: Democratic Republic of the Congo | D36: COD | E36: =_xlfn.XLOOKUP(D36,[6]Feuil1!$C$2:$C$248,[6]Feuil1!$B$2:$B$248) -> CD | F36: Population | G36: Western Africa | H36: million | I36: =[1]data!F37*(_xlfn.XLOOKUP([1]data!$C37,[2]data!$B$2:$B$218,[2]data!E$2:E$218)/100) -> 2.3252434 | J36: =[1]data!G37*(_xlfn.XLOOKUP([1]data!$C37,[2]data!$B$2:$B$218,[2]data!F$2:F$218)/100) -> 2.7926954 | K36: =[1]data!H37*(_xlfn.XLOOKUP([1]data!$C37,[2]data!$B$2:$B$218,[2]data!G$2:G$218)/100) -> 3.3631767 | L36: =[1]data!I37*(_xlfn.XLOOKUP([1]data!$C37,[2]data!$B$2:$B$218,[2]data!H$2:H$218)/100) -> 4.0231447 | M36: =[1]data!J37*(_xlfn.XLOOKUP([1]data!$C37,[2]data!$B$2:$B$218,[2]data!I$2:I$218)/100) -> 4.8867807 | N36: =[1]data!K37*(_xlfn.XLOOKUP([1]data!$C37,[2]data!$B$2:$B$218,[2]data!J$2:J$218)/100) -> 5.8690967 | O36: =[1]data!L37*(_xlfn.XLOOKUP([1]data!$C37,[2]data!$B$2:$B$218,[2]data!K$2:K$218)/100) -> 7.1367641 | P36: =[1]data!M37*(_xlfn.XLOOKUP([1]data!$C37,[2]data!$B$2:$B$218,[2]data!L$2:L$218)/100) -> 8.6510829 | ... AM36: =[1]data!AJ37*(_xlfn.XLOOKUP([1]data!$C37,[2]data!$B$2:$B$218,[2]data!AI$2:AI$218)/100) -> 271.37087
A37: IIASA-WiC POP 2023 | B37: SSP2 | C37: Congo | D37: COG | E37: =_xlfn.XLOOKUP(D37,[6]Feuil1!$C$2:$C$248,[6]Feuil1!$B$2:$B$248) -> CG | F37: Population | G37: Western Africa | H37: million | I37: =[1]data!F38*(_xlfn.XLOOKUP([1]data!$C38,[2]data!$B$2:$B$218,[2]data!E$2:E$218)/100) -> 0.20573351 | J37: =[1]data!G38*(_xlfn.XLOOKUP([1]data!$C38,[2]data!$B$2:$B$218,[2]data!F$2:F$218)/100) -> 0.25923009 | K37: =[1]data!H38*(_xlfn.XLOOKUP([1]data!$C38,[2]data!$B$2:$B$218,[2]data!G$2:G$218)/100) -> 0.32930518 | L37: =[1]data!I38*(_xlfn.XLOOKUP([1]data!$C38,[2]data!$B$2:$B$218,[2]data!H$2:H$218)/100) -> 0.42022991 | M37: =[1]data!J38*(_xlfn.XLOOKUP([1]data!$C38,[2]data!$B$2:$B$218,[2]data!I$2:I$218)/100) -> 0.53797768 | N37: =[1]data!K38*(_xlfn.XLOOKUP([1]data!$C38,[2]data!$B$2:$B$218,[2]data!J$2:J$218)/100) -> 0.69484722 | O37: =[1]data!L38*(_xlfn.XLOOKUP([1]data!$C38,[2]data!$B$2:$B$218,[2]data!K$2:K$218)/100) -> 0.86636299 | P37: =[1]data!M38*(_xlfn.XLOOKUP([1]data!$C38,[2]data!$B$2:$B$218,[2]data!L$2:L$218)/100) -> 1.0605933 | ... AM37: =[1]data!AJ38*(_xlfn.XLOOKUP([1]data!$C38,[2]data!$B$2:$B$218,[2]data!AI$2:AI$218)/100) -> 11.318779
A38: IIASA-WiC POP 2023 | B38: SSP2 | C38: Colombia | D38: COL | E38: =_xlfn.XLOOKUP(D38,[6]Feuil1!$C$2:$C$248,[6]Feuil1!$B$2:$B$248) -> CO | F38: Population | G38: =_xlfn.XLOOKUP(C38,[3]Sheet1!$B$2:$B$172,[3]Sheet1!$D$2:$D$172) -> Rest of South America | H38: million | I38: =[1]data!F39*(_xlfn.XLOOKUP([1]data!$C39,[2]data!$B$2:$B$218,[2]data!E$2:E$218)/100) -> 3.7864391 | J38: =[1]data!G39*(_xlfn.XLOOKUP([1]data!$C39,[2]data!$B$2:$B$218,[2]data!F$2:F$218)/100) -> 5.2203808 | K38: =[1]data!H39*(_xlfn.XLOOKUP([1]data!$C39,[2]data!$B$2:$B$218,[2]data!G$2:G$218)/100) -> 7.1507577 | L38: =[1]data!I39*(_xlfn.XLOOKUP([1]data!$C39,[2]data!$B$2:$B$218,[2]data!H$2:H$218)/100) -> 9.5073301 | M38: =[1]data!J39*(_xlfn.XLOOKUP([1]data!$C39,[2]data!$B$2:$B$218,[2]data!I$2:I$218)/100) -> 11.687872 | N38: =[1]data!K39*(_xlfn.XLOOKUP([1]data!$C39,[2]data!$B$2:$B$218,[2]data!J$2:J$218)/100) -> 13.958816 | O38: =[1]data!L39*(_xlfn.XLOOKUP([1]data!$C39,[2]data!$B$2:$B$218,[2]data!K$2:K$218)/100) -> 16.48033 | P38: =[1]data!M39*(_xlfn.XLOOKUP([1]data!$C39,[2]data!$B$2:$B$218,[2]data!L$2:L$218)/100) -> 19.438327 | ... AM38: =[1]data!AJ39*(_xlfn.XLOOKUP([1]data!$C39,[2]data!$B$2:$B$218,[2]data!AI$2:AI$218)/100) -> 46.815044
A39: IIASA-WiC POP 2023 | B39: SSP2 | C39: Comoros | D39: COM | E39: =_xlfn.XLOOKUP(D39,[6]Feuil1!$C$2:$C$248,[6]Feuil1!$B$2:$B$248) -> KM | F39: Population | G39: Eastern Africa | H39: million | I39: =[1]data!F40*(_xlfn.XLOOKUP([1]data!$C40,[2]data!$B$2:$B$218,[2]data!E$2:E$218)/100) -> 0.010557294 | J39: =[1]data!G40*(_xlfn.XLOOKUP([1]data!$C40,[2]data!$B$2:$B$218,[2]data!F$2:F$218)/100) -> 0.016226132 | K39: =[1]data!H40*(_xlfn.XLOOKUP([1]data!$C40,[2]data!$B$2:$B$218,[2]data!G$2:G$218)/100) -> 0.024319638 | L39: =[1]data!I40*(_xlfn.XLOOKUP([1]data!$C40,[2]data!$B$2:$B$218,[2]data!H$2:H$218)/100) -> 0.03616767 | M39: =[1]data!J40*(_xlfn.XLOOKUP([1]data!$C40,[2]data!$B$2:$B$218,[2]data!I$2:I$218)/100) -> 0.046383848 | N39: =[1]data!K40*(_xlfn.XLOOKUP([1]data!$C40,[2]data!$B$2:$B$218,[2]data!J$2:J$218)/100) -> 0.058476172 | O39: =[1]data!L40*(_xlfn.XLOOKUP([1]data!$C40,[2]data!$B$2:$B$218,[2]data!K$2:K$218)/100) -> 0.07500444 | P39: =[1]data!M40*(_xlfn.XLOOKUP([1]data!$C40,[2]data!$B$2:$B$218,[2]data!L$2:L$218)/100) -> 0.094490505 | ... AM39: =[1]data!AJ40*(_xlfn.XLOOKUP([1]data!$C40,[2]data!$B$2:$B$218,[2]data!AI$2:AI$218)/100) -> 1.0234322
A40: IIASA-WiC POP 2023 | B40: SSP2 | C40: Cabo Verde | D40: CPV | E40: =_xlfn.XLOOKUP(D40,[6]Feuil1!$C$2:$C$248,[6]Feuil1!$B$2:$B$248) -> CV | F40: Population | G40: Western Africa | H40: million | I40: =[1]data!F41*(_xlfn.XLOOKUP([1]data!$C41,[2]data!$B$2:$B$218,[2]data!E$2:E$218)/100) -> 0.026112522 | J40: =[1]data!G41*(_xlfn.XLOOKUP([1]data!$C41,[2]data!$B$2:$B$218,[2]data!F$2:F$218)/100) -> 0.029940372 | K40: =[1]data!H41*(_xlfn.XLOOKUP([1]data!$C41,[2]data!$B$2:$B$218,[2]data!G$2:G$218)/100) -> 0.03473433 | L40: =[1]data!I41*(_xlfn.XLOOKUP([1]data!$C41,[2]data!$B$2:$B$218,[2]data!H$2:H$218)/100) -> 0.043475295 | M40: =[1]data!J41*(_xlfn.XLOOKUP([1]data!$C41,[2]data!$B$2:$B$218,[2]data!I$2:I$218)/100) -> 0.055501712 | N40: =[1]data!K41*(_xlfn.XLOOKUP([1]data!$C41,[2]data!$B$2:$B$218,[2]data!J$2:J$218)/100) -> 0.06483344 | O40: =[1]data!L41*(_xlfn.XLOOKUP([1]data!$C41,[2]data!$B$2:$B$218,[2]data!K$2:K$218)/100) -> 0.0740626 | P40: =[1]data!M41*(_xlfn.XLOOKUP([1]data!$C41,[2]data!$B$2:$B$218,[2]data!L$2:L$218)/100) -> 0.10637014 | ... AM40: =[1]data!AJ41*(_xlfn.XLOOKUP([1]data!$C41,[2]data!$B$2:$B$218,[2]data!AI$2:AI$218)/100) -> 0.53752033
A41: IIASA-WiC POP 2023 | B41: SSP2 | C41: Costa Rica | D41: CRI | E41: =_xlfn.XLOOKUP(D41,[6]Feuil1!$C$2:$C$248,[6]Feuil1!$B$2:$B$248) -> CR | F41: Population | G41: =_xlfn.XLOOKUP(C41,[3]Sheet1!$B$2:$B$172,[3]Sheet1!$D$2:$D$172) -> Central America | H41: million | I41: =[1]data!F42*(_xlfn.XLOOKUP([1]data!$C42,[2]data!$B$2:$B$218,[2]data!E$2:E$218)/100) -> 0.31266254 | J41: =[1]data!G42*(_xlfn.XLOOKUP([1]data!$C42,[2]data!$B$2:$B$218,[2]data!F$2:F$218)/100) -> 0.3743021 | K41: =[1]data!H42*(_xlfn.XLOOKUP([1]data!$C42,[2]data!$B$2:$B$218,[2]data!G$2:G$218)/100) -> 0.45334756 | L41: =[1]data!I42*(_xlfn.XLOOKUP([1]data!$C42,[2]data!$B$2:$B$218,[2]data!H$2:H$218)/100) -> 0.56446612 | M41: =[1]data!J42*(_xlfn.XLOOKUP([1]data!$C42,[2]data!$B$2:$B$218,[2]data!I$2:I$218)/100) -> 0.7103923 | N41: =[1]data!K42*(_xlfn.XLOOKUP([1]data!$C42,[2]data!$B$2:$B$218,[2]data!J$2:J$218)/100) -> 0.86093402 | O41: =[1]data!L42*(_xlfn.XLOOKUP([1]data!$C42,[2]data!$B$2:$B$218,[2]data!K$2:K$218)/100) -> 1.0263748 | P41: =[1]data!M42*(_xlfn.XLOOKUP([1]data!$C42,[2]data!$B$2:$B$218,[2]data!L$2:L$218)/100) -> 1.2409872 | ... AM41: =[1]data!AJ42*(_xlfn.XLOOKUP([1]data!$C42,[2]data!$B$2:$B$218,[2]data!AI$2:AI$218)/100) -> 4.6161457
A42: IIASA-WiC POP 2023 | B42: SSP2 | C42: Cuba | D42: CUB | E42: =_xlfn.XLOOKUP(D42,[6]Feuil1!$C$2:$C$248,[6]Feuil1!$B$2:$B$248) -> CU | F42: Population | G42: =_xlfn.XLOOKUP(C42,[3]Sheet1!$B$2:$B$172,[3]Sheet1!$D$2:$D$172) -> Central America | H42: million | I42: =[1]data!F43*(_xlfn.XLOOKUP([1]data!$C43,[2]data!$B$2:$B$218,[2]data!E$2:E$218)/100) -> 3.3142352 | J42: =[1]data!G43*(_xlfn.XLOOKUP([1]data!$C43,[2]data!$B$2:$B$218,[2]data!F$2:F$218)/100) -> 3.7330869 | K42: =[1]data!H43*(_xlfn.XLOOKUP([1]data!$C43,[2]data!$B$2:$B$218,[2]data!G$2:G$218)/100) -> 4.200462 | L42: =[1]data!I43*(_xlfn.XLOOKUP([1]data!$C43,[2]data!$B$2:$B$218,[2]data!H$2:H$218)/100) -> 4.7354478 | M42: =[1]data!J43*(_xlfn.XLOOKUP([1]data!$C43,[2]data!$B$2:$B$218,[2]data!I$2:I$218)/100) -> 5.3000601 | N42: =[1]data!K43*(_xlfn.XLOOKUP([1]data!$C43,[2]data!$B$2:$B$218,[2]data!J$2:J$218)/100) -> 6.0780124 | O42: =[1]data!L43*(_xlfn.XLOOKUP([1]data!$C43,[2]data!$B$2:$B$218,[2]data!K$2:K$218)/100) -> 6.6697944 | P42: =[1]data!M43*(_xlfn.XLOOKUP([1]data!$C43,[2]data!$B$2:$B$218,[2]data!L$2:L$218)/100) -> 7.1655943 | ... AM42: =[1]data!AJ43*(_xlfn.XLOOKUP([1]data!$C43,[2]data!$B$2:$B$218,[2]data!AI$2:AI$218)/100) -> 7.441229
A43: IIASA-WiC POP 2023 | B43: SSP2 | C43: Curacao | D43: CUW | E43: =_xlfn.XLOOKUP(D43,[6]Feuil1!$C$2:$C$248,[6]Feuil1!$B$2:$B$248) -> #N/A | F43: Population | G43: Rest of South America | H43: million | I43: =[1]data!F44*(_xlfn.XLOOKUP([1]data!$C44,[2]data!$B$2:$B$218,[2]data!E$2:E$218)/100) -> 0.069153406 | J43: =[1]data!G44*(_xlfn.XLOOKUP([1]data!$C44,[2]data!$B$2:$B$218,[2]data!F$2:F$218)/100) -> 0.082235332 | K43: =[1]data!H44*(_xlfn.XLOOKUP([1]data!$C44,[2]data!$B$2:$B$218,[2]data!G$2:G$218)/100) -> 0.09743121 | L43: =[1]data!I44*(_xlfn.XLOOKUP([1]data!$C44,[2]data!$B$2:$B$218,[2]data!H$2:H$218)/100) -> 0.10729132 | M43: =[1]data!J44*(_xlfn.XLOOKUP([1]data!$C44,[2]data!$B$2:$B$218,[2]data!I$2:I$218)/100) -> 0.11724798 | N43: =[1]data!K44*(_xlfn.XLOOKUP([1]data!$C44,[2]data!$B$2:$B$218,[2]data!J$2:J$218)/100) -> 0.12426268 | O43: =[1]data!L44*(_xlfn.XLOOKUP([1]data!$C44,[2]data!$B$2:$B$218,[2]data!K$2:K$218)/100) -> 0.12820105 | P43: =[1]data!M44*(_xlfn.XLOOKUP([1]data!$C44,[2]data!$B$2:$B$218,[2]data!L$2:L$218)/100) -> 0.13054859 | ... AM43: =[1]data!AJ44*(_xlfn.XLOOKUP([1]data!$C44,[2]data!$B$2:$B$218,[2]data!AI$2:AI$218)/100) -> 0.22172259
A44: IIASA-WiC POP 2023 | B44: SSP2 | C44: Cyprus | D44: CYP | E44: =_xlfn.XLOOKUP(D44,[6]Feuil1!$C$2:$C$248,[6]Feuil1!$B$2:$B$248) -> CY | F44: Population | G44: =_xlfn.XLOOKUP(C44,[3]Sheet1!$B$2:$B$172,[3]Sheet1!$D$2:$D$172) -> Central Europe | H44: million | I44: =[1]data!F45*(_xlfn.XLOOKUP([1]data!$C45,[2]data!$B$2:$B$218,[2]data!E$2:E$218)/100) -> 0.13927218 | J44: =[1]data!G45*(_xlfn.XLOOKUP([1]data!$C45,[2]data!$B$2:$B$218,[2]data!F$2:F$218)/100) -> 0.17108406 | K44: =[1]data!H45*(_xlfn.XLOOKUP([1]data!$C45,[2]data!$B$2:$B$218,[2]data!G$2:G$218)/100) -> 0.20642696 | L44: =[1]data!I45*(_xlfn.XLOOKUP([1]data!$C45,[2]data!$B$2:$B$218,[2]data!H$2:H$218)/100) -> 0.23484558 | M44: =[1]data!J45*(_xlfn.XLOOKUP([1]data!$C45,[2]data!$B$2:$B$218,[2]data!I$2:I$218)/100) -> 0.26067365 | N44: =[1]data!K45*(_xlfn.XLOOKUP([1]data!$C45,[2]data!$B$2:$B$218,[2]data!J$2:J$218)/100) -> 0.30502682 | O44: =[1]data!L45*(_xlfn.XLOOKUP([1]data!$C45,[2]data!$B$2:$B$218,[2]data!K$2:K$218)/100) -> 0.39581429 | P44: =[1]data!M45*(_xlfn.XLOOKUP([1]data!$C45,[2]data!$B$2:$B$218,[2]data!L$2:L$218)/100) -> 0.46954149 | ... AM44: =[1]data!AJ45*(_xlfn.XLOOKUP([1]data!$C45,[2]data!$B$2:$B$218,[2]data!AI$2:AI$218)/100) -> 1.1762813
...

Sheet Rural population
A1: Model | B1: Scenario | C1: Region | D1: ISO-3code | E1: ISO-2code | F1: Variable | G1: IMAGE | H1: Unit | I1: 1950 | J1: 1955 | K1: 1960 | L1: 1965 | M1: 1970 | N1: 1975 | O1: 1980 | P1: 1985 | Q1: 1990 | R1: 1995 | S1: 2000 | T1: 2005 | U1: 2010 | V1: 2015 | W1: 2020 | X1: 2025 | Y1: 2030 | Z1: 2035 | AA1: 2040 | AB1: 2045 | AC1: 2050 | AD1: 2055 | AE1: 2060 | AF1: 2065 | AG1: 2070 | AH1: 2075 | AI1: 2080 | AJ1: 2085 | AK1: 2090 | AL1: 2095 | AM1: 2100
A2: IIASA-WiC POP 2023 | B2: SSP2 | C2: Aruba | D2: =_xlfn.XLOOKUP(C2,'[5]Country Codes'!$A$2:$A$267,'[5]Country Codes'!$B$2:$B$267) -> ABW | E2: =_xlfn.XLOOKUP(D2,[6]Feuil1!$C$2:$C$248,[6]Feuil1!$B$2:$B$248) -> AW | F2: Population | G2: =_xlfn.XLOOKUP(C2,'Urban population'!C2:C200,'Urban population'!G2:G200) -> Central America | H2: million | I2: =[1]data!F2-'Urban population'!I2 -> 0.018718393 | J2: =[1]data!G2-'Urban population'!J2 -> 0.022416114 | K2: =[1]data!H2-'Urban population'!K2 -> 0.02649912 | L2: =[1]data!I2-'Urban population'!L2 -> 0.028842472 | M2: =[1]data!J2-'Urban population'!M2 -> 0.02926456 | N2: =[1]data!K2-'Urban population'!N2 -> 0.029885625 | O2: =[1]data!L2-'Urban population'!O2 -> 0.03075831 | P2: =[1]data!M2-'Urban population'!P2 -> 0.031933968 | ... AM2: =[1]data!AJ2-'Urban population'!AM2 -> 0.029215479
A3: IIASA-WiC POP 2023 | B3: SSP2 | C3: Angola | D3: =_xlfn.XLOOKUP(C3,'[5]Country Codes'!$A$2:$A$267,'[5]Country Codes'!$B$2:$B$267) -> AGO | E3: =_xlfn.XLOOKUP(D3,[6]Feuil1!$C$2:$C$248,[6]Feuil1!$B$2:$B$248) -> AO | F3: Population | G3: =_xlfn.XLOOKUP(C3,'Urban population'!C3:C202,'Urban population'!G3:G202) -> Rest of Southern Africa | H3: million | I3: =[1]data!F4-'Urban population'!I3 -> 4.0960107 | J3: =[1]data!G4-'Urban population'!J3 -> 4.4596766 | K3: =[1]data!H4-'Urban population'!K3 -> 4.7609184 | L3: =[1]data!I4-'Urban population'!L3 -> 4.994276 | M3: =[1]data!J4-'Urban population'!M3 -> 5.071695 | N3: =[1]data!K4-'Urban population'!N3 -> 5.5955262 | O3: =[1]data!L4-'Urban population'!O3 -> 6.1940117 | P3: =[1]data!M4-'Urban population'!P3 -> 6.8244392 | ... AM3: =[1]data!AJ4-'Urban population'!AM3 -> 14.703046
A4: IIASA-WiC POP 2023 | B4: SSP2 | C4: Albania | D4: =_xlfn.XLOOKUP(C4,'[5]Country Codes'!$A$2:$A$267,'[5]Country Codes'!$B$2:$B$267) -> ALB | E4: =_xlfn.XLOOKUP(D4,[6]Feuil1!$C$2:$C$248,[6]Feuil1!$B$2:$B$248) -> AL | F4: Population | G4: =_xlfn.XLOOKUP(C4,'Urban population'!C4:C203,'Urban population'!G4:G203) -> Central Europe | H4: million | I4: =[1]data!F5-'Urban population'!I4 -> 0.98140683 | J4: =[1]data!G5-'Urban population'!J4 -> 1.0458951 | K4: =[1]data!H5-'Urban population'!K4 -> 1.1660813 | L4: =[1]data!I5-'Urban population'!L4 -> 1.3618616 | M4: =[1]data!J5-'Urban population'!M4 -> 1.5656416 | N4: =[1]data!K5-'Urban population'!N4 -> 1.7618534 | O4: =[1]data!L5-'Urban population'!O4 -> 1.9301954 | P4: =[1]data!M5-'Urban population'!P4 -> 2.0461737 | ... AM4: =[1]data!AJ5-'Urban population'!AM4 -> 0.20755741
A5: IIASA-WiC POP 2023 | B5: SSP2 | C5: United Arab Emirates | D5: =_xlfn.XLOOKUP(C5,'[5]Country Codes'!$A$2:$A$267,'[5]Country Codes'!$B$2:$B$267) -> ARE | E5: =_xlfn.XLOOKUP(D5,[6]Feuil1!$C$2:$C$248,[6]Feuil1!$B$2:$B$248) -> AE | F5: Population | G5: =_xlfn.XLOOKUP(C5,'Urban population'!C5:C204,'Urban population'!G5:G204) -> Middle East | H5: million | I5: =[1]data!F6-'Urban population'!I5 -> 0.03278184 | J5: =[1]data!G6-'Urban population'!J5 -> 0.035027238 | K5: =[1]data!H6-'Urban population'!K5 -> 0.034381365 | L5: =[1]data!I6-'Urban population'!L5 -> 0.037797608 | M5: =[1]data!J6-'Urban population'!M5 -> 0.055599288 | N5: =[1]data!K6-'Urban population'!N5 -> 0.10452591 | O5: =[1]data!L6-'Urban population'!O5 -> 0.18550021 | P5: =[1]data!M6-'Urban population'!P5 -> 0.27145285 | ... AM5: =[1]data!AJ6-'Urban population'!AM5 -> 0.39987851
A6: IIASA-WiC POP 2023 | B6: SSP2 | C6: Argentina | D6: =_xlfn.XLOOKUP(C6,'[5]Country Codes'!$A$2:$A$267,'[5]Country Codes'!$B$2:$B$267) -> ARG | E6: =_xlfn.XLOOKUP(D6,[6]Feuil1!$C$2:$C$248,[6]Feuil1!$B$2:$B$248) -> AR | F6: Population | G6: =_xlfn.XLOOKUP(C6,'Urban population'!C6:C205,'Urban population'!G6:G205) -> Rest of South America | H6: million | I6: =[1]data!F7-'Urban population'!I6 -> 5.8468397 | J6: =[1]data!G7-'Urban population'!J6 -> 5.6353392 | K6: =[1]data!H7-'Urban population'!K6 -> 5.3295282 | L6: =[1]data!I7-'Urban population'!L6 -> 5.1637352 | M6: =[1]data!J7-'Urban population'!M6 -> 4.9907824 | N6: =[1]data!K7-'Urban population'!N6 -> 4.8772567 | O6: =[1]data!L7-'Urban population'!O6 -> 4.7545553 | P6: =[1]data!M7-'Urban population'!P6 -> 4.5087393 | ... AM6: =[1]data!AJ7-'Urban population'!AM6 -> 3.0275398
A7: IIASA-WiC POP 2023 | B7: SSP2 | C7: Armenia | D7: =_xlfn.XLOOKUP(C7,'[5]Country Codes'!$A$2:$A$267,'[5]Country Codes'!$B$2:$B$267) -> ARM | E7: =_xlfn.XLOOKUP(D7,[6]Feuil1!$C$2:$C$248,[6]Feuil1!$B$2:$B$248) -> AM | F7: Population | G7: =_xlfn.XLOOKUP(C7,'Urban population'!C7:C206,'Urban population'!G7:G206) -> Russia region | H7: million | I7: =[1]data!F8-'Urban population'!I7 -> 0.81555036 | J7: =[1]data!G8-'Urban population'!J7 -> 0.85257684 | K7: =[1]data!H8-'Urban population'!K7 -> 0.91106791 | L7: =[1]data!I8-'Urban population'!L7 -> 0.97809959 | M7: =[1]data!J8-'Urban population'!M7 -> 1.0048952 | N7: =[1]data!K8-'Urban population'!N7 -> 1.0186984 | O7: =[1]data!L8-'Urban population'!O7 -> 1.0573644 | P7: =[1]data!M8-'Urban population'!P7 -> 1.0814457 | ... AM7: =[1]data!AJ8-'Urban population'!AM7 -> 0.30823906
A8: IIASA-WiC POP 2023 | B8: SSP2 | C8: Antigua and Barbuda | D8: =_xlfn.XLOOKUP(C8,'[5]Country Codes'!$A$2:$A$267,'[5]Country Codes'!$B$2:$B$267) -> ATG | E8: =_xlfn.XLOOKUP(D8,[6]Feuil1!$C$2:$C$248,[6]Feuil1!$B$2:$B$248) -> AG | F8: Population | G8: =_xlfn.XLOOKUP(C8,'Urban population'!C8:C207,'Urban population'!G8:G207) -> #N/A | H8: million | I8: =[1]data!F9-'Urban population'!I8 -> 0.031418652 | J8: =[1]data!G9-'Urban population'!J8 -> 0.03240027 | K8: =[1]data!H9-'Urban population'!K8 -> 0.03305646 | L8: =[1]data!I9-'Urban population'!L8 -> 0.037508708 | M8: =[1]data!J9-'Urban population'!M8 -> 0.042563952 | N8: =[1]data!K9-'Urban population'!N8 -> 0.042178458 | O8: =[1]data!L9-'Urban population'!O8 -> 0.042367428 | P8: =[1]data!M9-'Urban population'!P8 -> 0.0423878 | ... AM8: =[1]data!AJ9-'Urban population'!AM8 -> 0.034236277
A9: IIASA-WiC POP 2023 | B9: SSP2 | C9: Australia | D9: =_xlfn.XLOOKUP(C9,'[5]Country Codes'!$A$2:$A$267,'[5]Country Codes'!$B$2:$B$267) -> AUS | E9: =_xlfn.XLOOKUP(D9,[6]Feuil1!$C$2:$C$248,[6]Feuil1!$B$2:$B$248) -> AU | F9: Population | G9: =_xlfn.XLOOKUP(C9,'Urban population'!C9:C208,'Urban population'!G9:G208) -> Oceania | H9: million | I9: =[1]data!F10-'Urban population'!I9 -> 1.851247 | J9: =[1]data!G10-'Urban population'!J9 -> 1.8745528 | K9: =[1]data!H10-'Urban population'!K9 -> 1.8821447 | L9: =[1]data!I10-'Urban population'!L9 -> 1.899562 | M9: =[1]data!J10-'Urban population'!M9 -> 1.9830266 | N9: =[1]data!K10-'Urban population'!N9 -> 2.0990046 | O9: =[1]data!L10-'Urban population'!O9 -> 2.1030453 | P9: =[1]data!M10-'Urban population'!P9 -> 2.2575956 | ... AM9: =[1]data!AJ10-'Urban population'!AM9 -> 1.3189844
A10: IIASA-WiC POP 2023 | B10: SSP2 | C10: Austria | D10: =_xlfn.XLOOKUP(C10,'[5]Country Codes'!$A$2:$A$267,'[5]Country Codes'!$B$2:$B$267) -> AUT | E10: =_xlfn.XLOOKUP(D10,[6]Feuil1!$C$2:$C$248,[6]Feuil1!$B$2:$B$248) -> AT | F10: Population | G10: =_xlfn.XLOOKUP(C10,'Urban population'!C10:C209,'Urban population'!G10:G209) -> Western Europe | H10: million | I10: =[1]data!F11-'Urban population'!I10 -> 2.5253625 | J10: =[1]data!G11-'Urban population'!J10 -> 2.4859277 | K10: =[1]data!H11-'Urban population'!K10 -> 2.4813662 | L10: =[1]data!I11-'Urban population'!L10 -> 2.5364049 | M10: =[1]data!J11-'Urban population'!M10 -> 2.5863187 | N10: =[1]data!K11-'Urban population'!N10 -> 2.6338417 | O10: =[1]data!L11-'Urban population'!O10 -> 2.6101157 | P10: =[1]data!M11-'Urban population'!P10 -> 2.6990221 | ... AM10: =[1]data!AJ11-'Urban population'!AM10 -> 1.7464895
A11: IIASA-WiC POP 2023 | B11: SSP2 | C11: Azerbaijan | D11: =_xlfn.XLOOKUP(C11,'[5]Country Codes'!$A$2:$A$267,'[5]Country Codes'!$B$2:$B$267) -> AZE | E11: =_xlfn.XLOOKUP(D11,[6]Feuil1!$C$2:$C$248,[6]Feuil1!$B$2:$B$248) -> AZ | F11: Population | G11: =_xlfn.XLOOKUP(C11,'Urban population'!C11:C210,'Urban population'!G11:G210) -> Russia region | H11: million | I11: =[1]data!F12-'Urban population'!I11 -> 1.6979512 | J11: =[1]data!G12-'Urban population'!J11 -> 1.751056 | K11: =[1]data!H12-'Urban population'!K11 -> 1.9221102 | L11: =[1]data!I12-'Urban population'!L11 -> 2.3279479 | M11: =[1]data!J12-'Urban population'!M11 -> 2.6863245 | N11: =[1]data!K12-'Urban population'!N11 -> 2.8263993 | O11: =[1]data!L12-'Urban population'!O11 -> 2.9923346 | P11: =[1]data!M12-'Urban population'!P11 -> 3.1772794 | ... AM11: =[1]data!AJ12-'Urban population'!AM11 -> 1.9683585
A12: IIASA-WiC POP 2023 | B12: SSP2 | C12: Burundi | D12: =_xlfn.XLOOKUP(C12,'[5]Country Codes'!$A$2:$A$267,'[5]Country Codes'!$B$2:$B$267) -> BDI | E12: =_xlfn.XLOOKUP(D12,[6]Feuil1!$C$2:$C$248,[6]Feuil1!$B$2:$B$248) -> BI | F12: Population | G12: =_xlfn.XLOOKUP(C12,'Urban population'!C12:C211,'Urban population'!G12:G211) -> Eastern Africa | H12: million | I12: =[1]data!F13-'Urban population'!I12 -> 2.1914235 | J12: =[1]data!G13-'Urban population'!J12 -> 2.4238489 | K12: =[1]data!H13-'Urban population'!K12 -> 2.6626186 | L12: =[1]data!I13-'Urban population'!L12 -> 3.0155603 | M12: =[1]data!J13-'Urban population'!M12 -> 3.3592417 | N12: =[1]data!K13-'Urban population'!N12 -> 3.5811835 | O12: =[1]data!L13-'Urban population'!O12 -> 3.9969354 | P12: =[1]data!M13-'Urban population'!P12 -> 4.6487304 | ... AM12: =[1]data!AJ13-'Urban population'!AM12 -> 13.871706
A13: IIASA-WiC POP 2023 | B13: SSP2 | C13: Belgium | D13: =_xlfn.XLOOKUP(C13,'[5]Country Codes'!$A$2:$A$267,'[5]Country Codes'!$B$2:$B$267) -> BEL | E13: =_xlfn.XLOOKUP(D13,[6]Feuil1!$C$2:$C$248,[6]Feuil1!$B$2:$B$248) -> BE | F13: Population | G13: =_xlfn.XLOOKUP(C13,'Urban population'!C13:C212,'Urban population'!G13:G212) -> Western Europe | H13: million | I13: =[1]data!F14-'Urban population'!I13 -> 0.73075724 | J13: =[1]data!G14-'Urban population'!J13 -> 0.70492288 | K13: =[1]data!H14-'Urban population'!K13 -> 0.68114175 | L13: =[1]data!I14-'Urban population'!L13 -> 0.64748006 | M13: =[1]data!J14-'Urban population'!M13 -> 0.59584027 | N13: =[1]data!K14-'Urban population'!N13 -> 0.536712 | O13: =[1]data!L14-'Urban population'!O13 -> 0.45181172 | P13: =[1]data!M14-'Urban population'!P13 -> 0.40498217 | ... AM13: =[1]data!AJ14-'Urban population'!AM13 -> 0.1821827
A14: IIASA-WiC POP 2023 | B14: SSP2 | C14: Benin | D14: =_xlfn.XLOOKUP(C14,'[5]Country Codes'!$A$2:$A$267,'[5]Country Codes'!$B$2:$B$267) -> BEN | E14: =_xlfn.XLOOKUP(D14,[6]Feuil1!$C$2:$C$248,[6]Feuil1!$B$2:$B$248) -> BJ | F14: Population | G14: =_xlfn.XLOOKUP(C14,'Urban population'!C14:C213,'Urban population'!G14:G213) -> Western Africa | H14: million | I14: =[1]data!F15-'Urban population'!I14 -> 2.1436152 | J14: =[1]data!G15-'Urban population'!J14 -> 2.1884767 | K14: =[1]data!H15-'Urban population'!K14 -> 2.2618176 | L14: =[1]data!I15-'Urban population'!L14 -> 2.3713174 | M14: =[1]data!J15-'Urban population'!M14 -> 2.4920861 | N14: =[1]data!K15-'Urban population'!N14 -> 2.6077863 | O14: =[1]data!L15-'Urban population'!O14 -> 2.7491905 | P14: =[1]data!M15-'Urban population'!P14 -> 3.0136884 | ... AM14: =[1]data!AJ15-'Urban population'!AM14 -> 8.6654049
... A35: IIASA-WiC POP 2023 | B35: SSP2 | C35: Cameroon | D35: =_xlfn.XLOOKUP(C35,'[5]Country Codes'!$A$2:$A$267,'[5]Country Codes'!$B$2:$B$267) -> CMR | E35: =_xlfn.XLOOKUP(D35,[6]Feuil1!$C$2:$C$248,[6]Feuil1!$B$2:$B$248) -> CM | F35: Population | G35: =_xlfn.XLOOKUP(C35,'Urban population'!C35:C234,'Urban population'!G35:G234) -> Western Africa | H35: million | I35: =[1]data!F36-'Urban population'!I35 -> 3.8847236 | J35: =[1]data!G36-'Urban population'!J35 -> 4.1023687 | K35: =[1]data!H36-'Urban population'!K35 -> 4.372022 | L35: =[1]data!I36-'Urban population'!L35 -> 4.6716676 | M35: =[1]data!J36-'Urban population'!M35 -> 5.0749158 | N35: =[1]data!K36-'Urban population'!N35 -> 5.302959 | O35: =[1]data!L36-'Urban population'!O35 -> 5.6920166 | P35: =[1]data!M36-'Urban population'!P35 -> 6.1587008 | ... AM35: =[1]data!AJ36-'Urban population'!AM35 -> 12.964739
