Workbook

Sheet Sheet1
A1: years | B1: Canada | C1: USA | D1: Mexico | E1: Central America | F1: Brazil | G1: Rest of South America | H1: Northern Africa | I1: Western Africa | J1: Eastern Africa | K1: South Africa | L1: Western Europe | M1: Central Europe | N1: Turkey | O1: Ukraine region | P1: Central Asia | Q1: Russia Region | R1: Middle East | S1: India | T1: Korea | U1: China | V1: South Eastern Asia | W1: Indonesia Region | X1: Japan | Y1: Oceania | Z1: Rest of South Asia | AA1: Rest of Southern Africa
A2: 1971 | B2: 1.7000499e+08 | C2: 1.0629722e+09 | D2: 7488257 | E2: 1512953.5 | F2: 60148285 | G2: 58449159 | H2: 14112624 | I2: 14614227 | J2: 10726997 | K2: 4.3026606e+08 | L2: 2.0857562e+09 | M2: 1.6833446e+09 | N2: 1.8351137e+08 | O2: 1.071386e+09 | P2: 5.2515344e+08 | Q2: 3.0117168e+09 | R2: 1027753.8 | S2: 1.5978797e+09 | T2: 6697825 | U2: 2.1457168e+09 | V2: 0 | W2: 7282985 | X2: 5.5842724e+08 | Y2: 55078213 | Z2: 37372294 | AA2: 49510078
A3: 1972 | B3: 1.7478383e+08 | C3: 1.1787348e+09 | D3: 8997222 | E3: 1569378.1 | F3: 58701953 | G3: 44613135 | H3: 15030320 | I3: 16564109 | J3: 5840518.5 | K3: 3.8752626e+08 | L3: 1.9432301e+09 | M3: 1.5625884e+09 | N3: 1.8813306e+08 | O3: 1.0914123e+09 | P3: 5.3548276e+08 | Q3: 3.0545843e+09 | R3: 1007629.8 | S3: 1.5729135e+09 | T3: 4838768.5 | U3: 2.2544833e+09 | V3: 0 | W3: 6904220 | X3: 5.3901258e+08 | Y3: 43701607 | Z3: 17102333 | AA3: 50229656
A4: 1973 | B4: 1.8161757e+08 | C4: 1.2460582e+09 | D4: 10718511 | E4: 1626142.2 | F4: 59602175 | G4: 52804413 | H4: 16086519 | I4: 15758797 | J4: 8730771.1 | K4: 3.595989e+08 | L4: 1.9083567e+09 | M4: 1.4609991e+09 | N4: 1.856971e+08 | O4: 1.090972e+09 | P4: 5.3686373e+08 | Q4: 3.0493353e+09 | R4: 992728.52 | S4: 1.4488418e+09 | T4: 4689946 | U4: 2.2654516e+09 | V4: 0 | W4: 4388715 | X4: 4.6349884e+08 | Y4: 49057529 | Z4: 18821807 | AA4: 45660038
A5: 1974 | B5: 1.8637796e+08 | C5: 1.2477877e+09 | D5: 10779677 | E5: 1623569.7 | F5: 65806092 | G5: 61091512 | H5: 17093666 | I5: 6260508.1 | J5: 8430647.2 | K5: 3.0435993e+08 | L5: 1.8027394e+09 | M5: 1.4197727e+09 | N5: 1.8543397e+08 | O5: 1.0987236e+09 | P5: 5.4136989e+08 | Q5: 3.0780924e+09 | R5: 983084.77 | S5: 1.4781351e+09 | T5: 7135656.1 | U5: 2.2406883e+09 | V5: 0 | W5: 4908565 | X5: 4.5992991e+08 | Y5: 52721605 | Z5: 24229803 | AA5: 34711640
A6: 1975 | B6: 1.7196511e+08 | C6: 1.1327358e+09 | D6: 10789158 | E6: 1753588.4 | F6: 66397311 | G6: 55038360 | H6: 17459064 | I6: 4815816.2 | J6: 5818836.9 | K6: 3.3034654e+08 | L6: 1.6478381e+09 | M6: 1.3314729e+09 | N6: 1.7172478e+08 | O6: 1.1628142e+09 | P6: 5.7494087e+08 | Q6: 3.2581662e+09 | R6: 995156.77 | S6: 1.4955781e+09 | T6: 8949211 | U6: 2.6215322e+09 | V6: 0 | W6: 7120355 | X6: 4.0371786e+08 | Y6: 54928271 | Z6: 27095659 | AA6: 35585829
A7: 1976 | B7: 1.5248136e+08 | C7: 1.1734168e+09 | D7: 10407701 | E7: 1940559.2 | F7: 68232049 | G7: 59407664 | H7: 18633560 | I7: 6588498.9 | J7: 7186221.8 | K7: 2.5200753e+08 | L7: 1.585547e+09 | M7: 1.1825462e+09 | N7: 1.6751704e+08 | O7: 1.1129792e+09 | P7: 5.5189667e+08 | Q7: 3.1185027e+09 | R7: 974690.52 | S7: 1.4152423e+09 | T7: 7144055.7 | U7: 2.671236e+09 | V7: 0 | W7: 5955500 | X7: 4.1700562e+08 | Y7: 55546036 | Z7: 27009400 | AA7: 32847749
A8: 1977 | B8: 1.4861683e+08 | C8: 1.1707675e+09 | D8: 11052717 | E8: 2022298.8 | F8: 65547278 | G8: 55526821 | H8: 19112629 | I8: 6755650.8 | J8: 7082444.1 | K8: 2.3441701e+08 | L8: 1.5596372e+09 | M8: 1.1026194e+09 | N8: 1.415065e+08 | O8: 1.1142348e+09 | P8: 5.5344451e+08 | Q8: 3.1237948e+09 | R8: 1098380.4 | S8: 1.3918459e+09 | T8: 5955276 | U8: 2.9917335e+09 | V8: 0 | W8: 5887277.5 | X8: 4.2536118e+08 | Y8: 56279931 | Z8: 29029215 | AA8: 26501439
A9: 1978 | B9: 1.5313354e+08 | C9: 1.1615235e+09 | D9: 12360713 | E9: 2107347.2 | F9: 66935169 | G9: 50566743 | H9: 19595835 | I9: 1337979.4 | J9: 5850231.5 | K9: 2.0723464e+08 | L9: 1.5674798e+09 | M9: 1.0281655e+09 | N9: 90177841 | O9: 1.1168184e+09 | P9: 5.5633588e+08 | Q9: 3.1321363e+09 | R9: 1239119.2 | S9: 1.3460377e+09 | T9: 6619366.1 | U9: 2.4637591e+09 | V9: 0 | W9: 4918647.5 | X9: 4.3906969e+08 | Y9: 56393631 | Z9: 33683003 | AA9: 26257281
A10: 1979 | B10: 1.5930512e+08 | C10: 1.1904744e+09 | D10: 11989067 | E10: 2365707.6 | F10: 71505693 | G10: 48353631 | H10: 20308588 | I10: 1014071.9 | J10: 870395.32 | K10: 1.8470073e+08 | L10: 1.5738779e+09 | M10: 9.3495004e+08 | N10: 84619335 | O10: 1.043831e+09 | P10: 5.2856811e+08 | Q10: 2.9465821e+09 | R10: 1235174.5 | S10: 1.3187682e+09 | T10: 6853532.3 | U10: 2.467558e+09 | V10: 0 | W10: 4223422.5 | X10: 4.4754122e+08 | Y10: 56877048 | Z10: 35413930 | AA10: 29802267
A11: 1980 | B11: 1.6084744e+08 | C11: 1.1324994e+09 | D11: 12499712 | E11: 2399288.7 | F11: 74981376 | G11: 45647541 | H11: 21032960 | I11: 823522.06 | J11: 958019.7 | K11: 1.7393074e+08 | L11: 1.5612847e+09 | M11: 8.9292949e+08 | N11: 76780542 | O11: 9.708435e+08 | P11: 5.0080034e+08 | Q11: 2.7610278e+09 | R11: 1249807.7 | S11: 1.3365405e+09 | T11: 7558940.3 | U11: 2.2765332e+09 | V11: 17518445 | W11: 2994000 | X11: 4.4509528e+08 | Y11: 58077404 | Z11: 37864794 | AA11: 32856194
A12: 1981 | B12: 1.5534616e+08 | C12: 1.0961948e+09 | D12: 12979068 | E12: 2646174.1 | F12: 74797713 | G12: 44354908 | H12: 22831407 | I12: 964654.05 | J12: 733215.32 | K12: 1.6503013e+08 | L12: 1.5218649e+09 | M12: 8.3048477e+08 | N12: 84395313 | O12: 8.9785603e+08 | P12: 4.7303258e+08 | Q12: 2.5754736e+09 | R12: 1264805.5 | S12: 1.2952618e+09 | T12: 29995782 | U12: 2.4048305e+09 | V12: 13550468 | W12: 2318857 | X12: 4.3351772e+08 | Y12: 58729137 | Z12: 40521054 | AA12: 27528976
A13: 1982 | B13: 1.4378617e+08 | C13: 9.9336505e+08 | D13: 12846875 | E13: 2587023.9 | F13: 76589370 | G13: 35456736 | H13: 21195181 | I13: 866903.05 | J13: 611570.94 | K13: 1.4535026e+08 | L13: 1.4883765e+09 | M13: 7.9258423e+08 | N13: 86944973 | O13: 8.2486857e+08 | P13: 4.4526481e+08 | Q13: 2.3899193e+09 | R13: 1931699.7 | S13: 1.3011771e+09 | T13: 30318309 | U13: 2.44414e+09 | V13: 17656670 | W13: 1932774.2 | X13: 4.3028231e+08 | Y13: 60084745 | Z13: 48181452 | AA13: 29923732
... A21: 1990 | B21: 1.4755339e+08 | C21: 8.4244362e+08 | D21: 97637197 | E21: 5120370.2 | F21: 76682297 | G21: 25149461 | H21: 10751667 | I21: 1076595.4 | J21: 411946.64 | K21: 21312324 | L21: 1.5316516e+09 | M21: 5.0668386e+08 | N21: 49593708 | O21: 2.4096887e+08 | P21: 2.2312266e+08 | Q21: 9.0548532e+08 | R21: 2242482.2 | S21: 8.5587317e+08 | T21: 43623467 | U21: 1.8685109e+09 | V21: 22841260 | W21: 169209.51 | X21: 4.3056879e+08 | Y21: 80096583 | Z21: 63307590 | AA21: 25899782
A22: 1991 | B22: 1.3697899e+08 | C22: 7.9639497e+08 | D22: 82214628 | E22: 3710021.8 | F22: 73870221 | G22: 21159282 | H22: 9291160.8 | I22: 727315.31 | J22: 322273.78 | K22: 17121627 | L22: 1.591854e+09 | M22: 4.6006713e+08 | N22: 47086900 | O22: 2.2476543e+08 | P22: 2.4593104e+08 | Q22: =($Q$26-$Q$21)/5+Q21 -> 9.2309678e+08 | R22: 2368158.6 | S22: 8.6345033e+08 | T22: 44505204 | U22: 1.6294785e+09 | V22: 25983724 | W22: 180185.48 | X22: 4.5166098e+08 | Y22: 81485346 | Z22: 65019314 | AA22: 25218693
A23: 1992 | B23: 1.4297949e+08 | C23: 8.4683157e+08 | D23: 81710197 | E23: 2069501.7 | F23: 77231964 | G23: 22712733 | H23: 10396682 | I23: 860073.2 | J23: 383662.59 | K23: 14743010 | L23: 1.5706274e+09 | M23: 4.8820813e+08 | N23: 47620243 | O23: 1.8663552e+08 | P23: 2.3511052e+08 | Q23: =($Q$26-$Q$21)/5+Q22 -> 9.4070824e+08 | R23: 1955135.5 | S23: 7.9702773e+08 | T23: 45915455 | U23: 1.4291793e+09 | V23: 25235120 | W23: 201208.46 | X23: 4.514342e+08 | Y23: 78007420 | Z23: 61555406 | AA23: 23395679
A24: 1993 | B24: 1.4176312e+08 | C24: 7.6992577e+08 | D24: 80246522 | E24: 1715321.1 | F24: 77905319 | G24: 24112360 | H24: 9102412.4 | I24: 775458.73 | J24: 407949.24 | K24: 27256110 | L24: 1.5600901e+09 | M24: 5.1659814e+08 | N24: 49706400 | O24: 2.1986885e+08 | P24: 1.785247e+08 | Q24: =($Q$26-$Q$21)/5+Q23 -> 9.583197e+08 | R24: 71976.403 | S24: 5.9510511e+08 | T24: 48023027 | U24: 1.3022454e+09 | V24: 22841853 | W24: 234558.51 | X24: 4.6131204e+08 | Y24: 77073845 | Z24: 61473021 | AA24: 20609887
A25: 1994 | B25: 1.4552545e+08 | C25: 8.0827322e+08 | D25: 85335042 | E25: 1713337.4 | F25: 63827576 | G25: 20477634 | H25: 9142820.7 | I25: 711792.98 | J25: 292398.8 | K25: 22761440 | L25: 1.5671404e+09 | M25: 4.783089e+08 | N25: 50161072 | O25: 2.7326063e+08 | P25: 1.3556307e+08 | Q25: =($Q$26-$Q$21)/5+Q24 -> 9.7593116e+08 | R25: 0 | S25: 4.6357984e+08 | T25: 49054178 | U25: 1.0900291e+09 | V25: 20234689 | W25: 262812.05 | X25: 4.6803518e+08 | Y25: 77276427 | Z25: 62721868 | AA25: 4990132.8
A26: 1995 | B26: 1.3116096e+08 | C26: 8.3502815e+08 | D26: 76872520 | E26: 1881076.5 | F26: 67864230 | G26: 22279761 | H26: 10076244 | I26: 687520.66 | J26: 204680.06 | K26: 22635301 | L26: 1.6110418e+09 | M26: 4.6867298e+08 | N26: 53024142 | O26: 2.6997585e+08 | P26: 1.5264639e+08 | Q26: 9.9354262e+08 | R26: 0 | S26: 4.3447892e+08 | T26: 51132800 | U26: 9.5132369e+08 | V26: 19796642 | W26: 42967.026 | X26: 4.7777552e+08 | Y26: 76747625 | Z26: 63760954 | AA26: 4555940.9
A27: 1996 | B27: 1.2779795e+08 | C27: 8.4697871e+08 | D27: 78318295 | E27: 1756351.2 | F27: 63841119 | G27: 24584137 | H27: 10438662 | I27: 759395.96 | J27: 253755.22 | K27: 18073086 | L27: 1.6440498e+09 | M27: 4.734088e+08 | N27: 57560942 | O27: 2.4354225e+08 | P27: 1.4372555e+08 | Q27: 9.9113492e+08 | R27: 0 | S27: 4.4754976e+08 | T27: 51534428 | U27: 9.194571e+08 | V27: 22851765 | W27: 0 | X27: 4.7630826e+08 | Y27: 77946372 | Z27: 63382588 | AA27: 3919053.1
A28: 1997 | B28: 1.289202e+08 | C28: 7.9777307e+08 | D28: 83537892 | E28: 1920871.8 | F28: 56400314 | G28: 27367939 | H28: 11993047 | I28: 833898.88 | J28: 278558.98 | K28: 15509908 | L28: 1.6614718e+09 | M28: 4.6174836e+08 | N28: 45651137 | O28: 2.5745014e+08 | P28: 1.3158367e+08 | Q28: 9.5202437e+08 | R28: 0 | S28: 4.3275482e+08 | T28: 52756724 | U28: 7.2147684e+08 | V28: 20954582 | W28: 0 | X28: 4.7766565e+08 | Y28: 79585150 | Z28: 63822815 | AA28: 4040981.8
A29: 1998 | B29: 1.2271786e+08 | C29: 7.3645303e+08 | D29: 70529492 | E29: 2340925 | F29: 60322689 | G29: 29635636 | H29: 12591313 | I29: 851363.31 | J29: 253144.73 | K29: 19095776 | L29: 1.645886e+09 | M29: 4.3733542e+08 | N29: 45179485 | O29: 2.4254886e+08 | P29: 1.5841179e+08 | Q29: 8.5911573e+08 | R29: 0 | S29: 4.4117079e+08 | T29: 50470699 | U29: 5.7562014e+08 | V29: 19754849 | W29: 0 | X29: 4.8035809e+08 | Y29: 79057319 | Z29: 66635126 | AA29: 3369969.4
A30: 1999 | B30: 1.2933886e+08 | C30: 7.2545461e+08 | D30: 66951910 | E30: 2800527.1 | F30: 61260803 | G30: 33657169 | H30: 12425447 | I30: 1004503.2 | J30: 686702.5 | K30: 16026989 | L30: 1.6298566e+09 | M30: 4.1297275e+08 | N30: 46955531 | O30: 2.3215317e+08 | P30: 1.4221141e+08 | Q30: 9.5289143e+08 | R30: 0 | S30: 4.511963e+08 | T30: 53653237 | U30: 5.0458958e+08 | V30: 21410760 | W30: 0 | X30: 4.7950733e+08 | Y30: 83413723 | Z30: 69485082 | AA30: 3012648.1
A31: 2000 | B31: 1.3180743e+08 | C31: 7.9357313e+08 | D31: 69174390 | E31: 2974886.4 | F31: 67821213 | G31: 37016169 | H31: 13222757 | I31: 944335.57 | J31: 468664.56 | K31: 16318030 | L31: 1.6427418e+09 | M31: 4.0386436e+08 | N31: 53416782 | O31: 2.1862189e+08 | P31: 1.1448502e+08 | Q31: 1.0826203e+09 | R31: 0 | S31: 4.7338504e+08 | T31: 59310611 | U31: 7.8689269e+08 | V31: 22191254 | W31: 0 | X31: 4.7313602e+08 | Y31: 86264100 | Z31: 68940025 | AA31: 2683884.2
A32: 2001 | B32: 1.2793062e+08 | C32: 7.686829e+08 | D32: 66474342 | E32: 2917594.2 | F32: 71137412 | G32: 37042355 | H32: 20579173 | I32: 949479.22 | J32: 275389.08 | K32: 16703878 | L32: 1.6274618e+09 | M32: 3.6352476e+08 | N32: 46401831 | O32: 2.1663577e+08 | P32: 1.177317e+08 | Q32: 1.0638087e+09 | R32: 0 | S32: 5.094647e+08 | T32: 63725218 | U32: 7.2835895e+08 | V32: 24160849 | W32: 0 | X32: 4.6703276e+08 | Y32: 86333714 | Z32: 74168381 | AA32: 2691315.9
A33: 2002 | B33: 1.1435171e+08 | C33: 8.1696741e+08 | D33: 68008064 | E33: 3234861.7 | F33: 64699801 | G33: 35295872 | H33: 22486483 | I33: 1040737.7 | J33: 377915.54 | K33: 16886443 | L33: 1.6219103e+09 | M33: 3.8416863e+08 | N33: 49313945 | O33: 2.3008439e+08 | P33: 1.2194524e+08 | Q33: 1.1400136e+09 | R33: 0 | S33: 5.4922517e+08 | T33: 64678843 | U33: 7.1926785e+08 | V33: 25342136 | W33: 0 | X33: 4.6634157e+08 | Y33: 76369170 | Z33: 75108894 | AA33: 2305865.6
A34: 2003 | B34: 1.121782e+08 | C34: 8.1159121e+08 | D34: 69101954 | E34: 3050627.9 | F34: 73932719 | G34: 34362019 | H34: 24577300 | I34: 1021464.5 | J34: 430376.53 | K34: 16822963 | L34: 1.5589056e+09 | M34: 3.830346e+08 | N34: 51339125 | O34: 2.3926742e+08 | P34: 1.2054604e+08 | Q34: 1.214509e+09 | R34: 0 | S34: 5.5395716e+08 | T34: 67660833 | U34: 8.9465365e+08 | V34: 24142764 | W34: 0 | X34: 4.5720621e+08 | Y34: 84503851 | Z34: 72652317 | AA34: 2053981.7
A35: 2004 | B35: 1.1233573e+08 | C35: 8.4789305e+08 | D35: 72933446 | E35: 2648574.3 | F35: 73557823 | G35: 37141156 | H35: 20330672 | I35: 1025611.8 | J35: 401925.14 | K35: 16754547 | L35: 1.5955739e+09 | M35: 3.7958604e+08 | N35: 40176500 | O35: 2.607185e+08 | P35: 1.0533384e+08 | Q35: 1.3177395e+09 | R35: 0 | S35: 5.6399548e+08 | T35: 67138743 | U35: 1.0418263e+09 | V35: 24852279 | W35: 0 | X35: 4.6056666e+08 | Y35: 90679790 | Z35: 83828236 | AA35: 1854780.4
A36: 2005 | B36: 1.2528503e+08 | C36: 9.2096105e+08 | D36: 73818853 | E36: 2949290.6 | F36: 75561077 | G36: 37750630 | H36: 20837974 | I36: 1068294.1 | J36: 390055.96 | K36: 15140884 | L36: 1.5841768e+09 | M36: 3.4007619e+08 | N36: 46063632 | O36: 2.6400783e+08 | P36: 87702461 | Q36: 1.4038418e+09 | R36: 0 | S36: 6.3163282e+08 | T36: 69692419 | U36: 9.9037539e+08 | V36: 42384886 | W36: 0 | X36: 4.639181e+08 | Y36: 89509053 | Z36: 74957529 | AA36: 2117357.8
A37: 2006 | B37: 1.2916862e+08 | C37: 9.9860094e+08 | D37: 76163133 | E37: 3131895 | F37: 79511058 | G37: 38549502 | H37: 23758818 | I37: 1186601.4 | J37: 467892.22 | K37: 15096875 | L37: 1.5200071e+09 | M37: 3.2218277e+08 | N37: 45159237 | O37: 2.898448e+08 | P37: 86776185 | Q37: 1.4793636e+09 | R37: 0 | S37: 6.4814966e+08 | T37: 67590663 | U37: 1.0421546e+09 | V37: 44999102 | W37: 0 | X37: 4.5251844e+08 | Y37: 90177108 | Z37: 74677388 | AA37: 2088644.5
... A131: 2100 | B131: 2.1428705e+08 | C131: 1.7711099e+09 | D131: 5.2415044e+08 | E131: 2.5826575e+08 | F131: 6.4977001e+08 | G131: 6.544e+08 | H131: 1.0086828e+09 | I131: 3.0387325e+09 | J131: 1.3866124e+09 | K131: 1.8643957e+08 | L131: 1.4468267e+09 | M131: 2.7667232e+08 | N131: 2.4853459e+08 | O131: 1.8826301e+08 | P131: 4.7859043e+08 | Q131: 8.5449412e+08 | R131: 9.8503364e+08 | S131: 5.8174319e+09 | T131: 1.2111945e+08 | U131: 2.9303778e+09 | V131: 1.3027888e+09 | W131: 8.1591902e+08 | X131: 1.7275832e+08 | Y131: 1.8433793e+08 | Z131: 3.1144146e+09 | AA131: 1.1505272e+09

Sheet Sheet1 (2)
A1: years | B1: Canada | C1: USA | D1: Mexico | E1: Central America | F1: Brazil | G1: Rest of South America | H1: Northern Africa | I1: Western Africa | J1: Eastern Africa | K1: South Africa | L1: Western Europe | M1: Central Europe | N1: Turkey | O1: Ukraine region | P1: Central Asia | Q1: Russia Region | R1: Middle East | S1: India | T1: Korea | U1: China | V1: South Eastern Asia | W1: Indonesia Region | X1: Japan | Y1: Oceania | Z1: Rest of South Asia | AA1: Rest of Southern Africa
A2: 1971 | B2: 1.7000499e+08 | C2: 1.0629722e+09 | D2: 7488257 | E2: 1512953.5 | F2: 60148285 | G2: 58449159 | H2: 14112624 | I2: 14614227 | J2: 10726997 | K2: 4.3026606e+08 | L2: 2.0857562e+09 | M2: 1.6833446e+09 | N2: 1.8351137e+08 | O2: 1.071386e+09 | P2: 5.2515344e+08 | Q2: 3.0117168e+09 | R2: 1027753.8 | S2: 1.5978797e+09 | T2: 6697825 | U2: 2.1457168e+09 | V2: 0 | W2: 7282985 | X2: 5.5842724e+08 | Y2: 55078213 | Z2: 37372294 | AA2: 49510078
A3: 1972 | B3: 1.7478383e+08 | C3: 1.1787348e+09 | D3: 8997222 | E3: 1569378.1 | F3: 58701953 | G3: 44613135 | H3: 15030320 | I3: 16564109 | J3: 5840518.5 | K3: 3.8752626e+08 | L3: 1.9432301e+09 | M3: 1.5625884e+09 | N3: 1.8813306e+08 | O3: 1.0914123e+09 | P3: 5.3548276e+08 | Q3: 3.0545843e+09 | R3: 1007629.8 | S3: 1.5729135e+09 | T3: 4838768.5 | U3: 2.2544833e+09 | V3: 0 | W3: 6904220 | X3: 5.3901258e+08 | Y3: 43701607 | Z3: 17102333 | AA3: 50229656
A4: 1973 | B4: 1.8161757e+08 | C4: 1.2460582e+09 | D4: 10718511 | E4: 1626142.2 | F4: 59602175 | G4: 52804413 | H4: 16086519 | I4: 15758797 | J4: 8730771.1 | K4: 3.595989e+08 | L4: 1.9083567e+09 | M4: 1.4609991e+09 | N4: 1.856971e+08 | O4: 1.090972e+09 | P4: 5.3686373e+08 | Q4: 3.0493353e+09 | R4: 992728.52 | S4: 1.4488418e+09 | T4: 4689946 | U4: 2.2654516e+09 | V4: 0 | W4: 4388715 | X4: 4.6349884e+08 | Y4: 49057529 | Z4: 18821807 | AA4: 45660038
A5: 1974 | B5: 1.8637796e+08 | C5: 1.2477877e+09 | D5: 10779677 | E5: 1623569.7 | F5: 65806092 | G5: 61091512 | H5: 17093666 | I5: 6260508.1 | J5: 8430647.2 | K5: 3.0435993e+08 | L5: 1.8027394e+09 | M5: 1.4197727e+09 | N5: 1.8543397e+08 | O5: 1.0987236e+09 | P5: 5.4136989e+08 | Q5: 3.0780924e+09 | R5: 983084.77 | S5: 1.4781351e+09 | T5: 7135656.1 | U5: 2.2406883e+09 | V5: 0 | W5: 4908565 | X5: 4.5992991e+08 | Y5: 52721605 | Z5: 24229803 | AA5: 34711640
A6: 1975 | B6: 1.7196511e+08 | C6: 1.1327358e+09 | D6: 10789158 | E6: 1753588.4 | F6: 66397311 | G6: 55038360 | H6: 17459064 | I6: 4815816.2 | J6: 5818836.9 | K6: 3.3034654e+08 | L6: 1.6478381e+09 | M6: 1.3314729e+09 | N6: 1.7172478e+08 | O6: 1.1628142e+09 | P6: 5.7494087e+08 | Q6: 3.2581662e+09 | R6: 995156.77 | S6: 1.4955781e+09 | T6: 8949211 | U6: 2.6215322e+09 | V6: 0 | W6: 7120355 | X6: 4.0371786e+08 | Y6: 54928271 | Z6: 27095659 | AA6: 35585829
A7: 1976 | B7: 1.5248136e+08 | C7: 1.1734168e+09 | D7: 10407701 | E7: 1940559.2 | F7: 68232049 | G7: 59407664 | H7: 18633560 | I7: 6588498.9 | J7: 7186221.8 | K7: 2.5200753e+08 | L7: 1.585547e+09 | M7: 1.1825462e+09 | N7: 1.6751704e+08 | O7: 1.1129792e+09 | P7: 5.5189667e+08 | Q7: 3.1185027e+09 | R7: 974690.52 | S7: 1.4152423e+09 | T7: 7144055.7 | U7: 2.671236e+09 | V7: 0 | W7: 5955500 | X7: 4.1700562e+08 | Y7: 55546036 | Z7: 27009400 | AA7: 32847749
A8: 1977 | B8: 1.4861683e+08 | C8: 1.1707675e+09 | D8: 11052717 | E8: 2022298.8 | F8: 65547278 | G8: 55526821 | H8: 19112629 | I8: 6755650.8 | J8: 7082444.1 | K8: 2.3441701e+08 | L8: 1.5596372e+09 | M8: 1.1026194e+09 | N8: 1.415065e+08 | O8: 1.1142348e+09 | P8: 5.5344451e+08 | Q8: 3.1237948e+09 | R8: 1098380.4 | S8: 1.3918459e+09 | T8: 5955276 | U8: 2.9917335e+09 | V8: 0 | W8: 5887277.5 | X8: 4.2536118e+08 | Y8: 56279931 | Z8: 29029215 | AA8: 26501439
A9: 1978 | B9: 1.5313354e+08 | C9: 1.1615235e+09 | D9: 12360713 | E9: 2107347.2 | F9: 66935169 | G9: 50566743 | H9: 19595835 | I9: 1337979.4 | J9: 5850231.5 | K9: 2.0723464e+08 | L9: 1.5674798e+09 | M9: 1.0281655e+09 | N9: 90177841 | O9: 1.1168184e+09 | P9: 5.5633588e+08 | Q9: 3.1321363e+09 | R9: 1239119.2 | S9: 1.3460377e+09 | T9: 6619366.1 | U9: 2.4637591e+09 | V9: 0 | W9: 4918647.5 | X9: 4.3906969e+08 | Y9: 56393631 | Z9: 33683003 | AA9: 26257281
A10: 1979 | B10: 1.5930512e+08 | C10: 1.1904744e+09 | D10: 11989067 | E10: 2365707.6 | F10: 71505693 | G10: 48353631 | H10: 20308588 | I10: 1014071.9 | J10: 870395.32 | K10: 1.8470073e+08 | L10: 1.5738779e+09 | M10: 9.3495004e+08 | N10: 84619335 | O10: 1.043831e+09 | P10: 5.2856811e+08 | Q10: 2.9465821e+09 | R10: 1235174.5 | S10: 1.3187682e+09 | T10: 6853532.3 | U10: 2.467558e+09 | V10: 0 | W10: 4223422.5 | X10: 4.4754122e+08 | Y10: 56877048 | Z10: 35413930 | AA10: 29802267
A11: 1980 | B11: 1.6084744e+08 | C11: 1.1324994e+09 | D11: 12499712 | E11: 2399288.7 | F11: 74981376 | G11: 45647541 | H11: 21032960 | I11: 823522.06 | J11: 958019.7 | K11: 1.7393074e+08 | L11: 1.5612847e+09 | M11: 8.9292949e+08 | N11: 76780542 | O11: 9.708435e+08 | P11: 5.0080034e+08 | Q11: 2.7610278e+09 | R11: 1249807.7 | S11: 1.3365405e+09 | T11: 7558940.3 | U11: 2.2765332e+09 | V11: 17518445 | W11: 2994000 | X11: 4.4509528e+08 | Y11: 58077404 | Z11: 37864794 | AA11: 32856194
A12: 1981 | B12: 1.5534616e+08 | C12: 1.0961948e+09 | D12: 12979068 | E12: 2646174.1 | F12: 74797713 | G12: 44354908 | H12: 22831407 | I12: 964654.05 | J12: 733215.32 | K12: 1.6503013e+08 | L12: 1.5218649e+09 | M12: 8.3048477e+08 | N12: 84395313 | O12: 8.9785603e+08 | P12: 4.7303258e+08 | Q12: 2.5754736e+09 | R12: 1264805.5 | S12: 1.2952618e+09 | T12: 29995782 | U12: 2.4048305e+09 | V12: 13550468 | W12: 2318857 | X12: 4.3351772e+08 | Y12: 58729137 | Z12: 40521054 | AA12: 27528976
A13: 1982 | B13: 1.4378617e+08 | C13: 9.9336505e+08 | D13: 12846875 | E13: 2587023.9 | F13: 76589370 | G13: 35456736 | H13: 21195181 | I13: 866903.05 | J13: 611570.94 | K13: 1.4535026e+08 | L13: 1.4883765e+09 | M13: 7.9258423e+08 | N13: 86944973 | O13: 8.2486857e+08 | P13: 4.4526481e+08 | Q13: 2.3899193e+09 | R13: 1931699.7 | S13: 1.3011771e+09 | T13: 30318309 | U13: 2.44414e+09 | V13: 17656670 | W13: 1932774.2 | X13: 4.3028231e+08 | Y13: 60084745 | Z13: 48181452 | AA13: 29923732
... A21: 1990 | B21: 1.4755339e+08 | C21: 8.4244362e+08 | D21: 97637197 | E21: 5120370.2 | F21: 76682297 | G21: 25149461 | H21: 10751667 | I21: 1076595.4 | J21: 411946.64 | K21: 21312324 | L21: 1.5316516e+09 | M21: 5.0668386e+08 | N21: 49593708 | O21: 2.4096887e+08 | P21: 2.2312266e+08 | Q21: 9.0548532e+08 | R21: 2242482.2 | S21: 8.5587317e+08 | T21: 43623467 | U21: 1.8685109e+09 | V21: 22841260 | W21: 169209.51 | X21: 4.3056879e+08 | Y21: 80096583 | Z21: 63307590 | AA21: 25899782
A22: 1991 | B22: 1.3697899e+08 | C22: 7.9639497e+08 | D22: 82214628 | E22: 3710021.8 | F22: 73870221 | G22: 21159282 | H22: 9291160.8 | I22: 727315.31 | J22: 322273.78 | K22: 17121627 | L22: 1.591854e+09 | M22: 4.6006713e+08 | N22: 47086900 | O22: 2.2476543e+08 | P22: 2.4593104e+08 | Q22: =($Q$26-$Q$21)/5+Q21 -> 9.2309678e+08 | R22: 2368158.6 | S22: 8.6345033e+08 | T22: 44505204 | U22: 1.6294785e+09 | V22: 25983724 | W22: 180185.48 | X22: 4.5166098e+08 | Y22: 81485346 | Z22: 65019314 | AA22: 25218693
A23: 1992 | B23: 1.4297949e+08 | C23: 8.4683157e+08 | D23: 81710197 | E23: 2069501.7 | F23: 77231964 | G23: 22712733 | H23: 10396682 | I23: 860073.2 | J23: 383662.59 | K23: 14743010 | L23: 1.5706274e+09 | M23: 4.8820813e+08 | N23: 47620243 | O23: 1.8663552e+08 | P23: 2.3511052e+08 | Q23: =($Q$26-$Q$21)/5+Q22 -> 9.4070824e+08 | R23: 1955135.5 | S23: 7.9702773e+08 | T23: 45915455 | U23: 1.4291793e+09 | V23: 25235120 | W23: 201208.46 | X23: 4.514342e+08 | Y23: 78007420 | Z23: 61555406 | AA23: 23395679
A24: 1993 | B24: 1.4176312e+08 | C24: 7.6992577e+08 | D24: 80246522 | E24: 1715321.1 | F24: 77905319 | G24: 24112360 | H24: 9102412.4 | I24: 775458.73 | J24: 407949.24 | K24: 27256110 | L24: 1.5600901e+09 | M24: 5.1659814e+08 | N24: 49706400 | O24: 2.1986885e+08 | P24: 1.785247e+08 | Q24: =($Q$26-$Q$21)/5+Q23 -> 9.583197e+08 | R24: 71976.403 | S24: 5.9510511e+08 | T24: 48023027 | U24: 1.3022454e+09 | V24: 22841853 | W24: 234558.51 | X24: 4.6131204e+08 | Y24: 77073845 | Z24: 61473021 | AA24: 20609887
A25: 1994 | B25: 1.4552545e+08 | C25: 8.0827322e+08 | D25: 85335042 | E25: 1713337.4 | F25: 63827576 | G25: 20477634 | H25: 9142820.7 | I25: 711792.98 | J25: 292398.8 | K25: 22761440 | L25: 1.5671404e+09 | M25: 4.783089e+08 | N25: 50161072 | O25: 2.7326063e+08 | P25: 1.3556307e+08 | Q25: =($Q$26-$Q$21)/5+Q24 -> 9.7593116e+08 | R25: 0 | S25: 4.6357984e+08 | T25: 49054178 | U25: 1.0900291e+09 | V25: 20234689 | W25: 262812.05 | X25: 4.6803518e+08 | Y25: 77276427 | Z25: 62721868 | AA25: 4990132.8
A26: 1995 | B26: 1.3116096e+08 | C26: 8.3502815e+08 | D26: 76872520 | E26: 1881076.5 | F26: 67864230 | G26: 22279761 | H26: 10076244 | I26: 687520.66 | J26: 204680.06 | K26: 22635301 | L26: 1.6110418e+09 | M26: 4.6867298e+08 | N26: 53024142 | O26: 2.6997585e+08 | P26: 1.5264639e+08 | Q26: 9.9354262e+08 | R26: 0 | S26: 4.3447892e+08 | T26: 51132800 | U26: 9.5132369e+08 | V26: 19796642 | W26: 42967.026 | X26: 4.7777552e+08 | Y26: 76747625 | Z26: 63760954 | AA26: 4555940.9
A27: 1996 | B27: 1.2779795e+08 | C27: 8.4697871e+08 | D27: 78318295 | E27: 1756351.2 | F27: 63841119 | G27: 24584137 | H27: 10438662 | I27: 759395.96 | J27: 253755.22 | K27: 18073086 | L27: 1.6440498e+09 | M27: 4.734088e+08 | N27: 57560942 | O27: 2.4354225e+08 | P27: 1.4372555e+08 | Q27: 9.9113492e+08 | R27: 0 | S27: 4.4754976e+08 | T27: 51534428 | U27: 9.194571e+08 | V27: 22851765 | W27: 0 | X27: 4.7630826e+08 | Y27: 77946372 | Z27: 63382588 | AA27: 3919053.1
A28: 1997 | B28: 1.289202e+08 | C28: 7.9777307e+08 | D28: 83537892 | E28: 1920871.8 | F28: 56400314 | G28: 27367939 | H28: 11993047 | I28: 833898.88 | J28: 278558.98 | K28: 15509908 | L28: 1.6614718e+09 | M28: 4.6174836e+08 | N28: 45651137 | O28: 2.5745014e+08 | P28: 1.3158367e+08 | Q28: 9.5202437e+08 | R28: 0 | S28: 4.3275482e+08 | T28: 52756724 | U28: 7.2147684e+08 | V28: 20954582 | W28: 0 | X28: 4.7766565e+08 | Y28: 79585150 | Z28: 63822815 | AA28: 4040981.8
A29: 1998 | B29: 1.2271786e+08 | C29: 7.3645303e+08 | D29: 70529492 | E29: 2340925 | F29: 60322689 | G29: 29635636 | H29: 12591313 | I29: 851363.31 | J29: 253144.73 | K29: 19095776 | L29: 1.645886e+09 | M29: 4.3733542e+08 | N29: 45179485 | O29: 2.4254886e+08 | P29: 1.5841179e+08 | Q29: 8.5911573e+08 | R29: 0 | S29: 4.4117079e+08 | T29: 50470699 | U29: 5.7562014e+08 | V29: 19754849 | W29: 0 | X29: 4.8035809e+08 | Y29: 79057319 | Z29: 66635126 | AA29: 3369969.4
A30: 1999 | B30: 1.2933886e+08 | C30: 7.2545461e+08 | D30: 66951910 | E30: 2800527.1 | F30: 61260803 | G30: 33657169 | H30: 12425447 | I30: 1004503.2 | J30: 686702.5 | K30: 16026989 | L30: 1.6298566e+09 | M30: 4.1297275e+08 | N30: 46955531 | O30: 2.3215317e+08 | P30: 1.4221141e+08 | Q30: 9.5289143e+08 | R30: 0 | S30: 4.511963e+08 | T30: 53653237 | U30: 5.0458958e+08 | V30: 21410760 | W30: 0 | X30: 4.7950733e+08 | Y30: 83413723 | Z30: 69485082 | AA30: 3012648.1
A31: 2000 | B31: 1.3180743e+08 | C31: 7.9357313e+08 | D31: 69174390 | E31: 2974886.4 | F31: 67821213 | G31: 37016169 | H31: 13222757 | I31: 944335.57 | J31: 468664.56 | K31: 16318030 | L31: 1.6427418e+09 | M31: 4.0386436e+08 | N31: 53416782 | O31: 2.1862189e+08 | P31: 1.1448502e+08 | Q31: 1.0826203e+09 | R31: 0 | S31: 4.7338504e+08 | T31: 59310611 | U31: 7.8689269e+08 | V31: 22191254 | W31: 0 | X31: 4.7313602e+08 | Y31: 86264100 | Z31: 68940025 | AA31: 2683884.2
A32: 2001 | B32: 1.2793062e+08 | C32: 7.686829e+08 | D32: 66474342 | E32: 2917594.2 | F32: 71137412 | G32: 37042355 | H32: 20579173 | I32: 949479.22 | J32: 275389.08 | K32: 16703878 | L32: 1.6274618e+09 | M32: 3.6352476e+08 | N32: 46401831 | O32: 2.1663577e+08 | P32: 1.177317e+08 | Q32: 1.0638087e+09 | R32: 0 | S32: 5.094647e+08 | T32: 63725218 | U32: 7.2835895e+08 | V32: 24160849 | W32: 0 | X32: 4.6703276e+08 | Y32: 86333714 | Z32: 74168381 | AA32: 2691315.9
A33: 2002 | B33: 1.1435171e+08 | C33: 8.1696741e+08 | D33: 68008064 | E33: 3234861.7 | F33: 64699801 | G33: 35295872 | H33: 22486483 | I33: 1040737.7 | J33: 377915.54 | K33: 16886443 | L33: 1.6219103e+09 | M33: 3.8416863e+08 | N33: 49313945 | O33: 2.3008439e+08 | P33: 1.2194524e+08 | Q33: 1.1400136e+09 | R33: 0 | S33: 5.4922517e+08 | T33: 64678843 | U33: 7.1926785e+08 | V33: 25342136 | W33: 0 | X33: 4.6634157e+08 | Y33: 76369170 | Z33: 75108894 | AA33: 2305865.6
A34: 2003 | B34: 1.121782e+08 | C34: 8.1159121e+08 | D34: 69101954 | E34: 3050627.9 | F34: 73932719 | G34: 34362019 | H34: 24577300 | I34: 1021464.5 | J34: 430376.53 | K34: 16822963 | L34: 1.5589056e+09 | M34: 3.830346e+08 | N34: 51339125 | O34: 2.3926742e+08 | P34: 1.2054604e+08 | Q34: 1.214509e+09 | R34: 0 | S34: 5.5395716e+08 | T34: 67660833 | U34: 8.9465365e+08 | V34: 24142764 | W34: 0 | X34: 4.5720621e+08 | Y34: 84503851 | Z34: 72652317 | AA34: 2053981.7
A35: 2004 | B35: 1.1233573e+08 | C35: 8.4789305e+08 | D35: 72933446 | E35: 2648574.3 | F35: 73557823 | G35: 37141156 | H35: 20330672 | I35: 1025611.8 | J35: 401925.14 | K35: 16754547 | L35: 1.5955739e+09 | M35: 3.7958604e+08 | N35: 40176500 | O35: 2.607185e+08 | P35: 1.0533384e+08 | Q35: 1.3177395e+09 | R35: 0 | S35: 5.6399548e+08 | T35: 67138743 | U35: 1.0418263e+09 | V35: 24852279 | W35: 0 | X35: 4.6056666e+08 | Y35: 90679790 | Z35: 83828236 | AA35: 1854780.4
A36: 2005 | B36: 1.2528503e+08 | C36: 9.2096105e+08 | D36: 73818853 | E36: 2949290.6 | F36: 75561077 | G36: 37750630 | H36: 20837974 | I36: 1068294.1 | J36: 390055.96 | K36: 15140884 | L36: 1.5841768e+09 | M36: 3.4007619e+08 | N36: 46063632 | O36: 2.6400783e+08 | P36: 87702461 | Q36: 1.4038418e+09 | R36: 0 | S36: 6.3163282e+08 | T36: 69692419 | U36: 9.9037539e+08 | V36: 42384886 | W36: 0 | X36: 4.639181e+08 | Y36: 89509053 | Z36: 74957529 | AA36: 2117357.8
A37: 2006 | B37: 1.2916862e+08 | C37: 9.9860094e+08 | D37: 76163133 | E37: 3131895 | F37: 79511058 | G37: 38549502 | H37: 23758818 | I37: 1186601.4 | J37: 467892.22 | K37: 15096875 | L37: 1.5200071e+09 | M37: 3.2218277e+08 | N37: 45159237 | O37: 2.898448e+08 | P37: 86776185 | Q37: 1.4793636e+09 | R37: 0 | S37: 6.4814966e+08 | T37: 67590663 | U37: 1.0421546e+09 | V37: 44999102 | W37: 0 | X37: 4.5251844e+08 | Y37: 90177108 | Z37: 74677388 | AA37: 2088644.5
... A55: 2024 | B55: 1.4316872e+08 | C55: 9.7659401e+08 | D55: 76414878 | E55: 11149287 | F55: 1.3387102e+08 | G55: 36347455 | H55: 89200161 | I55: 4823544.5 | J55: 1815663.7 | K55: 19658125 | L55: 1.3244261e+09 | M55: 3.5449757e+08 | N55: 76648007 | O55: 2.2752114e+08 | P55: 1.4059011e+08 | Q55: 1.5564212e+09 | R55: 11037162 | S55: 1.328664e+09 | T55: 54140543 | U55: 1.9527781e+09 | V55: 1.5193556e+08 | W55: 34150041 | X55: 3.1658497e+08 | Y55: 1.3870077e+08 | Z55: 1.3608192e+08 | AA55: 3764499.2
A56: 2025 | B56: =Sheet1!B56*'Sheet1 (3)'!B56 -> 1.4799632e+08 | C56: =Sheet1!C56*'Sheet1 (3)'!C56 -> 9.9153047e+08 | D56: =Sheet1!D56*'Sheet1 (3)'!D56 -> 77762177 | E56: =Sheet1!E56*'Sheet1 (3)'!E56 -> 11355317 | F56: =Sheet1!F56*'Sheet1 (3)'!F56 -> 1.3576043e+08 | G56: =Sheet1!G56*'Sheet1 (3)'!G56 -> 38020627 | H56: =Sheet1!H56*'Sheet1 (3)'!H56 -> 89590624 | I56: =Sheet1!I56*'Sheet1 (3)'!I56 -> 4981211.5 | ... AA56: =Sheet1!AA56*'Sheet1 (3)'!AA56 -> 3908723.6
A57: 2026 | B57: =Sheet1!B57*'Sheet1 (3)'!B57 -> 1.5420636e+08 | C57: =Sheet1!C57*'Sheet1 (3)'!C57 -> 1.0161421e+09 | D57: =Sheet1!D57*'Sheet1 (3)'!D57 -> 80580637 | E57: =Sheet1!E57*'Sheet1 (3)'!E57 -> 11960468 | F57: =Sheet1!F57*'Sheet1 (3)'!F57 -> 1.3986265e+08 | G57: =Sheet1!G57*'Sheet1 (3)'!G57 -> 40673374 | H57: =Sheet1!H57*'Sheet1 (3)'!H57 -> 92540729 | I57: =Sheet1!I57*'Sheet1 (3)'!I57 -> 5240071.1 | ... AA57: =Sheet1!AA57*'Sheet1 (3)'!AA57 -> 4212826
A58: 2027 | B58: =Sheet1!B58*'Sheet1 (3)'!B58 -> 1.5978425e+08 | C58: =Sheet1!C58*'Sheet1 (3)'!C58 -> 1.037288e+09 | D58: =Sheet1!D58*'Sheet1 (3)'!D58 -> 82016015 | E58: =Sheet1!E58*'Sheet1 (3)'!E58 -> 12380961 | F58: =Sheet1!F58*'Sheet1 (3)'!F58 -> 1.4348551e+08 | G58: =Sheet1!G58*'Sheet1 (3)'!G58 -> 42712099 | H58: =Sheet1!H58*'Sheet1 (3)'!H58 -> 94079171 | I58: =Sheet1!I58*'Sheet1 (3)'!I58 -> 5479323.7 | ... AA58: =Sheet1!AA58*'Sheet1 (3)'!AA58 -> 4543856.8
A59: 2028 | B59: =Sheet1!B59*'Sheet1 (3)'!B59 -> 1.6495138e+08 | C59: =Sheet1!C59*'Sheet1 (3)'!C59 -> 1.0632648e+09 | D59: =Sheet1!D59*'Sheet1 (3)'!D59 -> 84297621 | E59: =Sheet1!E59*'Sheet1 (3)'!E59 -> 12874817 | F59: =Sheet1!F59*'Sheet1 (3)'!F59 -> 1.4714462e+08 | G59: =Sheet1!G59*'Sheet1 (3)'!G59 -> 44658905 | H59: =Sheet1!H59*'Sheet1 (3)'!H59 -> 96698548 | I59: =Sheet1!I59*'Sheet1 (3)'!I59 -> 5750704 | ... AA59: =Sheet1!AA59*'Sheet1 (3)'!AA59 -> 4899557.9
A60: 2029 | B60: =Sheet1!B60*'Sheet1 (3)'!B60 -> 1.6980923e+08 | C60: =Sheet1!C60*'Sheet1 (3)'!C60 -> 1.0860102e+09 | D60: =Sheet1!D60*'Sheet1 (3)'!D60 -> 86900860 | E60: =Sheet1!E60*'Sheet1 (3)'!E60 -> 13343234 | F60: =Sheet1!F60*'Sheet1 (3)'!F60 -> 1.5035069e+08 | G60: =Sheet1!G60*'Sheet1 (3)'!G60 -> 46726817 | H60: =Sheet1!H60*'Sheet1 (3)'!H60 -> 98798645 | I60: =Sheet1!I60*'Sheet1 (3)'!I60 -> 6095689.1 | ... AA60: =Sheet1!AA60*'Sheet1 (3)'!AA60 -> 5283439.6
A61: 2030 | B61: =Sheet1!B61*'Sheet1 (3)'!B61 -> 1.7444429e+08 | C61: =Sheet1!C61*'Sheet1 (3)'!C61 -> 1.1095843e+09 | D61: =Sheet1!D61*'Sheet1 (3)'!D61 -> 90088668 | E61: =Sheet1!E61*'Sheet1 (3)'!E61 -> 13812248 | F61: =Sheet1!F61*'Sheet1 (3)'!F61 -> 1.5328682e+08 | G61: =Sheet1!G61*'Sheet1 (3)'!G61 -> 48704841 | H61: =Sheet1!H61*'Sheet1 (3)'!H61 -> 1.0070146e+08 | I61: =Sheet1!I61*'Sheet1 (3)'!I61 -> 6443603.4 | ... AA61: =Sheet1!AA61*'Sheet1 (3)'!AA61 -> 5687225.6
A62: 2031 | B62: =Sheet1!B62*'Sheet1 (3)'!B62 -> 1.7899507e+08 | C62: =Sheet1!C62*'Sheet1 (3)'!C62 -> 1.1330507e+09 | D62: =Sheet1!D62*'Sheet1 (3)'!D62 -> 93284105 | E62: =Sheet1!E62*'Sheet1 (3)'!E62 -> 14140730 | F62: =Sheet1!F62*'Sheet1 (3)'!F62 -> 1.5585482e+08 | G62: =Sheet1!G62*'Sheet1 (3)'!G62 -> 50537169 | H62: =Sheet1!H62*'Sheet1 (3)'!H62 -> 1.0183588e+08 | I62: =Sheet1!I62*'Sheet1 (3)'!I62 -> 6827780.9 | ... AA62: =Sheet1!AA62*'Sheet1 (3)'!AA62 -> 6077891.5
A63: 2032 | B63: =Sheet1!B63*'Sheet1 (3)'!B63 -> 1.8449206e+08 | C63: =Sheet1!C63*'Sheet1 (3)'!C63 -> 1.1625125e+09 | D63: =Sheet1!D63*'Sheet1 (3)'!D63 -> 97752035 | E63: =Sheet1!E63*'Sheet1 (3)'!E63 -> 14595589 | F63: =Sheet1!F63*'Sheet1 (3)'!F63 -> 1.5912305e+08 | G63: =Sheet1!G63*'Sheet1 (3)'!G63 -> 52895249 | H63: =Sheet1!H63*'Sheet1 (3)'!H63 -> 1.0320337e+08 | I63: =Sheet1!I63*'Sheet1 (3)'!I63 -> 7238067.7 | ... AA63: =Sheet1!AA63*'Sheet1 (3)'!AA63 -> 6528067.6
A64: 2033 | B64: =Sheet1!B64*'Sheet1 (3)'!B64 -> 1.8999995e+08 | C64: =Sheet1!C64*'Sheet1 (3)'!C64 -> 1.191125e+09 | D64: =Sheet1!D64*'Sheet1 (3)'!D64 -> 1.0107124e+08 | E64: =Sheet1!E64*'Sheet1 (3)'!E64 -> 14997077 | F64: =Sheet1!F64*'Sheet1 (3)'!F64 -> 1.6237676e+08 | G64: =Sheet1!G64*'Sheet1 (3)'!G64 -> 55175702 | H64: =Sheet1!H64*'Sheet1 (3)'!H64 -> 1.0459853e+08 | I64: =Sheet1!I64*'Sheet1 (3)'!I64 -> 7658028.8 | ... AA64: =Sheet1!AA64*'Sheet1 (3)'!AA64 -> 6980155.8
...

Sheet Sheet1 (3)
A1: years | B1: Canada | C1: USA | D1: Mexico | E1: Central America | F1: Brazil | G1: Rest of South America | H1: Northern Africa | I1: Western Africa | J1: Eastern Africa | K1: South Africa | L1: Western Europe | M1: Central Europe | N1: Turkey | O1: Ukraine region | P1: Central Asia | Q1: Russia Region | R1: Middle East | S1: India | T1: Korea | U1: China | V1: South Eastern Asia | W1: Indonesia Region | X1: Japan | Y1: Oceania | Z1: Rest of South Asia | AA1: Rest of Southern Africa
A2: 1971 | B2: 1.7000499e+08 | C2: 1.0629722e+09 | D2: 7488257 | E2: 1512953.5 | F2: 60148285 | G2: 58449159 | H2: 14112624 | I2: 14614227 | J2: 10726997 | K2: 4.3026606e+08 | L2: 2.0857562e+09 | M2: 1.6833446e+09 | N2: 1.8351137e+08 | O2: 1.071386e+09 | P2: 5.2515344e+08 | Q2: 3.0117168e+09 | R2: 1027753.8 | S2: 1.5978797e+09 | T2: 6697825 | U2: 2.1457168e+09 | V2: 0 | W2: 7282985 | X2: 5.5842724e+08 | Y2: 55078213 | Z2: 37372294 | AA2: 49510078
A3: 1972 | B3: 1.7478383e+08 | C3: 1.1787348e+09 | D3: 8997222 | E3: 1569378.1 | F3: 58701953 | G3: 44613135 | H3: 15030320 | I3: 16564109 | J3: 5840518.5 | K3: 3.8752626e+08 | L3: 1.9432301e+09 | M3: 1.5625884e+09 | N3: 1.8813306e+08 | O3: 1.0914123e+09 | P3: 5.3548276e+08 | Q3: 3.0545843e+09 | R3: 1007629.8 | S3: 1.5729135e+09 | T3: 4838768.5 | U3: 2.2544833e+09 | V3: 0 | W3: 6904220 | X3: 5.3901258e+08 | Y3: 43701607 | Z3: 17102333 | AA3: 50229656
A4: 1973 | B4: 1.8161757e+08 | C4: 1.2460582e+09 | D4: 10718511 | E4: 1626142.2 | F4: 59602175 | G4: 52804413 | H4: 16086519 | I4: 15758797 | J4: 8730771.1 | K4: 3.595989e+08 | L4: 1.9083567e+09 | M4: 1.4609991e+09 | N4: 1.856971e+08 | O4: 1.090972e+09 | P4: 5.3686373e+08 | Q4: 3.0493353e+09 | R4: 992728.52 | S4: 1.4488418e+09 | T4: 4689946 | U4: 2.2654516e+09 | V4: 0 | W4: 4388715 | X4: 4.6349884e+08 | Y4: 49057529 | Z4: 18821807 | AA4: 45660038
A5: 1974 | B5: 1.8637796e+08 | C5: 1.2477877e+09 | D5: 10779677 | E5: 1623569.7 | F5: 65806092 | G5: 61091512 | H5: 17093666 | I5: 6260508.1 | J5: 8430647.2 | K5: 3.0435993e+08 | L5: 1.8027394e+09 | M5: 1.4197727e+09 | N5: 1.8543397e+08 | O5: 1.0987236e+09 | P5: 5.4136989e+08 | Q5: 3.0780924e+09 | R5: 983084.77 | S5: 1.4781351e+09 | T5: 7135656.1 | U5: 2.2406883e+09 | V5: 0 | W5: 4908565 | X5: 4.5992991e+08 | Y5: 52721605 | Z5: 24229803 | AA5: 34711640
A6: 1975 | B6: 1.7196511e+08 | C6: 1.1327358e+09 | D6: 10789158 | E6: 1753588.4 | F6: 66397311 | G6: 55038360 | H6: 17459064 | I6: 4815816.2 | J6: 5818836.9 | K6: 3.3034654e+08 | L6: 1.6478381e+09 | M6: 1.3314729e+09 | N6: 1.7172478e+08 | O6: 1.1628142e+09 | P6: 5.7494087e+08 | Q6: 3.2581662e+09 | R6: 995156.77 | S6: 1.4955781e+09 | T6: 8949211 | U6: 2.6215322e+09 | V6: 0 | W6: 7120355 | X6: 4.0371786e+08 | Y6: 54928271 | Z6: 27095659 | AA6: 35585829
A7: 1976 | B7: 1.5248136e+08 | C7: 1.1734168e+09 | D7: 10407701 | E7: 1940559.2 | F7: 68232049 | G7: 59407664 | H7: 18633560 | I7: 6588498.9 | J7: 7186221.8 | K7: 2.5200753e+08 | L7: 1.585547e+09 | M7: 1.1825462e+09 | N7: 1.6751704e+08 | O7: 1.1129792e+09 | P7: 5.5189667e+08 | Q7: 3.1185027e+09 | R7: 974690.52 | S7: 1.4152423e+09 | T7: 7144055.7 | U7: 2.671236e+09 | V7: 0 | W7: 5955500 | X7: 4.1700562e+08 | Y7: 55546036 | Z7: 27009400 | AA7: 32847749
A8: 1977 | B8: 1.4861683e+08 | C8: 1.1707675e+09 | D8: 11052717 | E8: 2022298.8 | F8: 65547278 | G8: 55526821 | H8: 19112629 | I8: 6755650.8 | J8: 7082444.1 | K8: 2.3441701e+08 | L8: 1.5596372e+09 | M8: 1.1026194e+09 | N8: 1.415065e+08 | O8: 1.1142348e+09 | P8: 5.5344451e+08 | Q8: 3.1237948e+09 | R8: 1098380.4 | S8: 1.3918459e+09 | T8: 5955276 | U8: 2.9917335e+09 | V8: 0 | W8: 5887277.5 | X8: 4.2536118e+08 | Y8: 56279931 | Z8: 29029215 | AA8: 26501439
A9: 1978 | B9: 1.5313354e+08 | C9: 1.1615235e+09 | D9: 12360713 | E9: 2107347.2 | F9: 66935169 | G9: 50566743 | H9: 19595835 | I9: 1337979.4 | J9: 5850231.5 | K9: 2.0723464e+08 | L9: 1.5674798e+09 | M9: 1.0281655e+09 | N9: 90177841 | O9: 1.1168184e+09 | P9: 5.5633588e+08 | Q9: 3.1321363e+09 | R9: 1239119.2 | S9: 1.3460377e+09 | T9: 6619366.1 | U9: 2.4637591e+09 | V9: 0 | W9: 4918647.5 | X9: 4.3906969e+08 | Y9: 56393631 | Z9: 33683003 | AA9: 26257281
A10: 1979 | B10: 1.5930512e+08 | C10: 1.1904744e+09 | D10: 11989067 | E10: 2365707.6 | F10: 71505693 | G10: 48353631 | H10: 20308588 | I10: 1014071.9 | J10: 870395.32 | K10: 1.8470073e+08 | L10: 1.5738779e+09 | M10: 9.3495004e+08 | N10: 84619335 | O10: 1.043831e+09 | P10: 5.2856811e+08 | Q10: 2.9465821e+09 | R10: 1235174.5 | S10: 1.3187682e+09 | T10: 6853532.3 | U10: 2.467558e+09 | V10: 0 | W10: 4223422.5 | X10: 4.4754122e+08 | Y10: 56877048 | Z10: 35413930 | AA10: 29802267
A11: 1980 | B11: 1.6084744e+08 | C11: 1.1324994e+09 | D11: 12499712 | E11: 2399288.7 | F11: 74981376 | G11: 45647541 | H11: 21032960 | I11: 823522.06 | J11: 958019.7 | K11: 1.7393074e+08 | L11: 1.5612847e+09 | M11: 8.9292949e+08 | N11: 76780542 | O11: 9.708435e+08 | P11: 5.0080034e+08 | Q11: 2.7610278e+09 | R11: 1249807.7 | S11: 1.3365405e+09 | T11: 7558940.3 | U11: 2.2765332e+09 | V11: 17518445 | W11: 2994000 | X11: 4.4509528e+08 | Y11: 58077404 | Z11: 37864794 | AA11: 32856194
A12: 1981 | B12: 1.5534616e+08 | C12: 1.0961948e+09 | D12: 12979068 | E12: 2646174.1 | F12: 74797713 | G12: 44354908 | H12: 22831407 | I12: 964654.05 | J12: 733215.32 | K12: 1.6503013e+08 | L12: 1.5218649e+09 | M12: 8.3048477e+08 | N12: 84395313 | O12: 8.9785603e+08 | P12: 4.7303258e+08 | Q12: 2.5754736e+09 | R12: 1264805.5 | S12: 1.2952618e+09 | T12: 29995782 | U12: 2.4048305e+09 | V12: 13550468 | W12: 2318857 | X12: 4.3351772e+08 | Y12: 58729137 | Z12: 40521054 | AA12: 27528976
A13: 1982 | B13: 1.4378617e+08 | C13: 9.9336505e+08 | D13: 12846875 | E13: 2587023.9 | F13: 76589370 | G13: 35456736 | H13: 21195181 | I13: 866903.05 | J13: 611570.94 | K13: 1.4535026e+08 | L13: 1.4883765e+09 | M13: 7.9258423e+08 | N13: 86944973 | O13: 8.2486857e+08 | P13: 4.4526481e+08 | Q13: 2.3899193e+09 | R13: 1931699.7 | S13: 1.3011771e+09 | T13: 30318309 | U13: 2.44414e+09 | V13: 17656670 | W13: 1932774.2 | X13: 4.3028231e+08 | Y13: 60084745 | Z13: 48181452 | AA13: 29923732
... A21: 1990 | B21: 1.4755339e+08 | C21: 8.4244362e+08 | D21: 97637197 | E21: 5120370.2 | F21: 76682297 | G21: 25149461 | H21: 10751667 | I21: 1076595.4 | J21: 411946.64 | K21: 21312324 | L21: 1.5316516e+09 | M21: 5.0668386e+08 | N21: 49593708 | O21: 2.4096887e+08 | P21: 2.2312266e+08 | Q21: 9.0548532e+08 | R21: 2242482.2 | S21: 8.5587317e+08 | T21: 43623467 | U21: 1.8685109e+09 | V21: 22841260 | W21: 169209.51 | X21: 4.3056879e+08 | Y21: 80096583 | Z21: 63307590 | AA21: 25899782
A22: 1991 | B22: 1.3697899e+08 | C22: 7.9639497e+08 | D22: 82214628 | E22: 3710021.8 | F22: 73870221 | G22: 21159282 | H22: 9291160.8 | I22: 727315.31 | J22: 322273.78 | K22: 17121627 | L22: 1.591854e+09 | M22: 4.6006713e+08 | N22: 47086900 | O22: 2.2476543e+08 | P22: 2.4593104e+08 | Q22: =($Q$26-$Q$21)/5+Q21 -> 9.2309678e+08 | R22: 2368158.6 | S22: 8.6345033e+08 | T22: 44505204 | U22: 1.6294785e+09 | V22: 25983724 | W22: 180185.48 | X22: 4.5166098e+08 | Y22: 81485346 | Z22: 65019314 | AA22: 25218693
A23: 1992 | B23: 1.4297949e+08 | C23: 8.4683157e+08 | D23: 81710197 | E23: 2069501.7 | F23: 77231964 | G23: 22712733 | H23: 10396682 | I23: 860073.2 | J23: 383662.59 | K23: 14743010 | L23: 1.5706274e+09 | M23: 4.8820813e+08 | N23: 47620243 | O23: 1.8663552e+08 | P23: 2.3511052e+08 | Q23: =($Q$26-$Q$21)/5+Q22 -> 9.4070824e+08 | R23: 1955135.5 | S23: 7.9702773e+08 | T23: 45915455 | U23: 1.4291793e+09 | V23: 25235120 | W23: 201208.46 | X23: 4.514342e+08 | Y23: 78007420 | Z23: 61555406 | AA23: 23395679
A24: 1993 | B24: 1.4176312e+08 | C24: 7.6992577e+08 | D24: 80246522 | E24: 1715321.1 | F24: 77905319 | G24: 24112360 | H24: 9102412.4 | I24: 775458.73 | J24: 407949.24 | K24: 27256110 | L24: 1.5600901e+09 | M24: 5.1659814e+08 | N24: 49706400 | O24: 2.1986885e+08 | P24: 1.785247e+08 | Q24: =($Q$26-$Q$21)/5+Q23 -> 9.583197e+08 | R24: 71976.403 | S24: 5.9510511e+08 | T24: 48023027 | U24: 1.3022454e+09 | V24: 22841853 | W24: 234558.51 | X24: 4.6131204e+08 | Y24: 77073845 | Z24: 61473021 | AA24: 20609887
A25: 1994 | B25: 1.4552545e+08 | C25: 8.0827322e+08 | D25: 85335042 | E25: 1713337.4 | F25: 63827576 | G25: 20477634 | H25: 9142820.7 | I25: 711792.98 | J25: 292398.8 | K25: 22761440 | L25: 1.5671404e+09 | M25: 4.783089e+08 | N25: 50161072 | O25: 2.7326063e+08 | P25: 1.3556307e+08 | Q25: =($Q$26-$Q$21)/5+Q24 -> 9.7593116e+08 | R25: 0 | S25: 4.6357984e+08 | T25: 49054178 | U25: 1.0900291e+09 | V25: 20234689 | W25: 262812.05 | X25: 4.6803518e+08 | Y25: 77276427 | Z25: 62721868 | AA25: 4990132.8
A26: 1995 | B26: 1.3116096e+08 | C26: 8.3502815e+08 | D26: 76872520 | E26: 1881076.5 | F26: 67864230 | G26: 22279761 | H26: 10076244 | I26: 687520.66 | J26: 204680.06 | K26: 22635301 | L26: 1.6110418e+09 | M26: 4.6867298e+08 | N26: 53024142 | O26: 2.6997585e+08 | P26: 1.5264639e+08 | Q26: 9.9354262e+08 | R26: 0 | S26: 4.3447892e+08 | T26: 51132800 | U26: 9.5132369e+08 | V26: 19796642 | W26: 42967.026 | X26: 4.7777552e+08 | Y26: 76747625 | Z26: 63760954 | AA26: 4555940.9
A27: 1996 | B27: 1.2779795e+08 | C27: 8.4697871e+08 | D27: 78318295 | E27: 1756351.2 | F27: 63841119 | G27: 24584137 | H27: 10438662 | I27: 759395.96 | J27: 253755.22 | K27: 18073086 | L27: 1.6440498e+09 | M27: 4.734088e+08 | N27: 57560942 | O27: 2.4354225e+08 | P27: 1.4372555e+08 | Q27: 9.9113492e+08 | R27: 0 | S27: 4.4754976e+08 | T27: 51534428 | U27: 9.194571e+08 | V27: 22851765 | W27: 0 | X27: 4.7630826e+08 | Y27: 77946372 | Z27: 63382588 | AA27: 3919053.1
A28: 1997 | B28: 1.289202e+08 | C28: 7.9777307e+08 | D28: 83537892 | E28: 1920871.8 | F28: 56400314 | G28: 27367939 | H28: 11993047 | I28: 833898.88 | J28: 278558.98 | K28: 15509908 | L28: 1.6614718e+09 | M28: 4.6174836e+08 | N28: 45651137 | O28: 2.5745014e+08 | P28: 1.3158367e+08 | Q28: 9.5202437e+08 | R28: 0 | S28: 4.3275482e+08 | T28: 52756724 | U28: 7.2147684e+08 | V28: 20954582 | W28: 0 | X28: 4.7766565e+08 | Y28: 79585150 | Z28: 63822815 | AA28: 4040981.8
A29: 1998 | B29: 1.2271786e+08 | C29: 7.3645303e+08 | D29: 70529492 | E29: 2340925 | F29: 60322689 | G29: 29635636 | H29: 12591313 | I29: 851363.31 | J29: 253144.73 | K29: 19095776 | L29: 1.645886e+09 | M29: 4.3733542e+08 | N29: 45179485 | O29: 2.4254886e+08 | P29: 1.5841179e+08 | Q29: 8.5911573e+08 | R29: 0 | S29: 4.4117079e+08 | T29: 50470699 | U29: 5.7562014e+08 | V29: 19754849 | W29: 0 | X29: 4.8035809e+08 | Y29: 79057319 | Z29: 66635126 | AA29: 3369969.4
A30: 1999 | B30: 1.2933886e+08 | C30: 7.2545461e+08 | D30: 66951910 | E30: 2800527.1 | F30: 61260803 | G30: 33657169 | H30: 12425447 | I30: 1004503.2 | J30: 686702.5 | K30: 16026989 | L30: 1.6298566e+09 | M30: 4.1297275e+08 | N30: 46955531 | O30: 2.3215317e+08 | P30: 1.4221141e+08 | Q30: 9.5289143e+08 | R30: 0 | S30: 4.511963e+08 | T30: 53653237 | U30: 5.0458958e+08 | V30: 21410760 | W30: 0 | X30: 4.7950733e+08 | Y30: 83413723 | Z30: 69485082 | AA30: 3012648.1
A31: 2000 | B31: 1.3180743e+08 | C31: 7.9357313e+08 | D31: 69174390 | E31: 2974886.4 | F31: 67821213 | G31: 37016169 | H31: 13222757 | I31: 944335.57 | J31: 468664.56 | K31: 16318030 | L31: 1.6427418e+09 | M31: 4.0386436e+08 | N31: 53416782 | O31: 2.1862189e+08 | P31: 1.1448502e+08 | Q31: 1.0826203e+09 | R31: 0 | S31: 4.7338504e+08 | T31: 59310611 | U31: 7.8689269e+08 | V31: 22191254 | W31: 0 | X31: 4.7313602e+08 | Y31: 86264100 | Z31: 68940025 | AA31: 2683884.2
A32: 2001 | B32: 1.2793062e+08 | C32: 7.686829e+08 | D32: 66474342 | E32: 2917594.2 | F32: 71137412 | G32: 37042355 | H32: 20579173 | I32: 949479.22 | J32: 275389.08 | K32: 16703878 | L32: 1.6274618e+09 | M32: 3.6352476e+08 | N32: 46401831 | O32: 2.1663577e+08 | P32: 1.177317e+08 | Q32: 1.0638087e+09 | R32: 0 | S32: 5.094647e+08 | T32: 63725218 | U32: 7.2835895e+08 | V32: 24160849 | W32: 0 | X32: 4.6703276e+08 | Y32: 86333714 | Z32: 74168381 | AA32: 2691315.9
A33: 2002 | B33: 1.1435171e+08 | C33: 8.1696741e+08 | D33: 68008064 | E33: 3234861.7 | F33: 64699801 | G33: 35295872 | H33: 22486483 | I33: 1040737.7 | J33: 377915.54 | K33: 16886443 | L33: 1.6219103e+09 | M33: 3.8416863e+08 | N33: 49313945 | O33: 2.3008439e+08 | P33: 1.2194524e+08 | Q33: 1.1400136e+09 | R33: 0 | S33: 5.4922517e+08 | T33: 64678843 | U33: 7.1926785e+08 | V33: 25342136 | W33: 0 | X33: 4.6634157e+08 | Y33: 76369170 | Z33: 75108894 | AA33: 2305865.6
A34: 2003 | B34: 1.121782e+08 | C34: 8.1159121e+08 | D34: 69101954 | E34: 3050627.9 | F34: 73932719 | G34: 34362019 | H34: 24577300 | I34: 1021464.5 | J34: 430376.53 | K34: 16822963 | L34: 1.5589056e+09 | M34: 3.830346e+08 | N34: 51339125 | O34: 2.3926742e+08 | P34: 1.2054604e+08 | Q34: 1.214509e+09 | R34: 0 | S34: 5.5395716e+08 | T34: 67660833 | U34: 8.9465365e+08 | V34: 24142764 | W34: 0 | X34: 4.5720621e+08 | Y34: 84503851 | Z34: 72652317 | AA34: 2053981.7
A35: 2004 | B35: 1.1233573e+08 | C35: 8.4789305e+08 | D35: 72933446 | E35: 2648574.3 | F35: 73557823 | G35: 37141156 | H35: 20330672 | I35: 1025611.8 | J35: 401925.14 | K35: 16754547 | L35: 1.5955739e+09 | M35: 3.7958604e+08 | N35: 40176500 | O35: 2.607185e+08 | P35: 1.0533384e+08 | Q35: 1.3177395e+09 | R35: 0 | S35: 5.6399548e+08 | T35: 67138743 | U35: 1.0418263e+09 | V35: 24852279 | W35: 0 | X35: 4.6056666e+08 | Y35: 90679790 | Z35: 83828236 | AA35: 1854780.4
A36: 2005 | B36: 1.2528503e+08 | C36: 9.2096105e+08 | D36: 73818853 | E36: 2949290.6 | F36: 75561077 | G36: 37750630 | H36: 20837974 | I36: 1068294.1 | J36: 390055.96 | K36: 15140884 | L36: 1.5841768e+09 | M36: 3.4007619e+08 | N36: 46063632 | O36: 2.6400783e+08 | P36: 87702461 | Q36: 1.4038418e+09 | R36: 0 | S36: 6.3163282e+08 | T36: 69692419 | U36: 9.9037539e+08 | V36: 42384886 | W36: 0 | X36: 4.639181e+08 | Y36: 89509053 | Z36: 74957529 | AA36: 2117357.8
A37: 2006 | B37: 1.2916862e+08 | C37: 9.9860094e+08 | D37: 76163133 | E37: 3131895 | F37: 79511058 | G37: 38549502 | H37: 23758818 | I37: 1186601.4 | J37: 467892.22 | K37: 15096875 | L37: 1.5200071e+09 | M37: 3.2218277e+08 | N37: 45159237 | O37: 2.898448e+08 | P37: 86776185 | Q37: 1.4793636e+09 | R37: 0 | S37: 6.4814966e+08 | T37: 67590663 | U37: 1.0421546e+09 | V37: 44999102 | W37: 0 | X37: 4.5251844e+08 | Y37: 90177108 | Z37: 74677388 | AA37: 2088644.5
... A55: 2024 | B55: 1 | C55: 1 | D55: 1 | E55: 1 | F55: 1 | G55: 1 | H55: 1 | I55: 1 | J55: 1 | K55: 1 | L55: 1 | M55: 1 | N55: 1 | O55: 1 | P55: 1 | Q55: 1 | R55: 1 | S55: 1 | T55: 1 | U55: 1 | V55: 1 | W55: 1 | X55: 1 | Y55: 1 | Z55: 1 | AA55: 1
A56: 2025 | B56: =(B$101-B$55)/46+B55 -> 1.0065217 | C56: =(C$101-C$55)/46+C55 -> 1.0065217 | D56: =(D$101-D$55)/46+D55 -> 1.0065217 | E56: =(E$101-E$55)/46+E55 -> 1.0065217 | F56: =(F$101-F$55)/46+F55 -> 1.0065217 | G56: =(G$101-G$55)/46+G55 -> 1.0065217 | H56: =(H$101-H$55)/46+H55 -> 1.0065217 | I56: =(I$101-I$55)/46+I55 -> 1.0065217 | ... AA56: =(AA$101-AA$55)/46+AA55 -> 1.0065217
A57: 2026 | B57: =(B$101-B$55)/46+B56 -> 1.0130435 | C57: =(C$101-C$55)/46+C56 -> 1.0130435 | D57: =(D$101-D$55)/46+D56 -> 1.0130435 | E57: =(E$101-E$55)/46+E56 -> 1.0130435 | F57: =(F$101-F$55)/46+F56 -> 1.0130435 | G57: =(G$101-G$55)/46+G56 -> 1.0130435 | H57: =(H$101-H$55)/46+H56 -> 1.0130435 | I57: =(I$101-I$55)/46+I56 -> 1.0130435 | ... AA57: =(AA$101-AA$55)/46+AA56 -> 1.0130435
A58: 2027 | B58: =(B$101-B$55)/46+B57 -> 1.0195652 | C58: =(C$101-C$55)/46+C57 -> 1.0195652 | D58: =(D$101-D$55)/46+D57 -> 1.0195652 | E58: =(E$101-E$55)/46+E57 -> 1.0195652 | F58: =(F$101-F$55)/46+F57 -> 1.0195652 | G58: =(G$101-G$55)/46+G57 -> 1.0195652 | H58: =(H$101-H$55)/46+H57 -> 1.0195652 | I58: =(I$101-I$55)/46+I57 -> 1.0195652 | ... AA58: =(AA$101-AA$55)/46+AA57 -> 1.0195652
A59: 2028 | B59: =(B$101-B$55)/46+B58 -> 1.026087 | C59: =(C$101-C$55)/46+C58 -> 1.026087 | D59: =(D$101-D$55)/46+D58 -> 1.026087 | E59: =(E$101-E$55)/46+E58 -> 1.026087 | F59: =(F$101-F$55)/46+F58 -> 1.026087 | G59: =(G$101-G$55)/46+G58 -> 1.026087 | H59: =(H$101-H$55)/46+H58 -> 1.026087 | I59: =(I$101-I$55)/46+I58 -> 1.026087 | ... AA59: =(AA$101-AA$55)/46+AA58 -> 1.026087
A60: 2029 | B60: =(B$101-B$55)/46+B59 -> 1.0326087 | C60: =(C$101-C$55)/46+C59 -> 1.0326087 | D60: =(D$101-D$55)/46+D59 -> 1.0326087 | E60: =(E$101-E$55)/46+E59 -> 1.0326087 | F60: =(F$101-F$55)/46+F59 -> 1.0326087 | G60: =(G$101-G$55)/46+G59 -> 1.0326087 | H60: =(H$101-H$55)/46+H59 -> 1.0326087 | I60: =(I$101-I$55)/46+I59 -> 1.0326087 | ... AA60: =(AA$101-AA$55)/46+AA59 -> 1.0326087
A61: 2030 | B61: =(B$101-B$55)/46+B60 -> 1.0391304 | C61: =(C$101-C$55)/46+C60 -> 1.0391304 | D61: =(D$101-D$55)/46+D60 -> 1.0391304 | E61: =(E$101-E$55)/46+E60 -> 1.0391304 | F61: =(F$101-F$55)/46+F60 -> 1.0391304 | G61: =(G$101-G$55)/46+G60 -> 1.0391304 | H61: =(H$101-H$55)/46+H60 -> 1.0391304 | I61: =(I$101-I$55)/46+I60 -> 1.0391304 | ... AA61: =(AA$101-AA$55)/46+AA60 -> 1.0391304
A62: 2031 | B62: =(B$101-B$55)/46+B61 -> 1.0456522 | C62: =(C$101-C$55)/46+C61 -> 1.0456522 | D62: =(D$101-D$55)/46+D61 -> 1.0456522 | E62: =(E$101-E$55)/46+E61 -> 1.0456522 | F62: =(F$101-F$55)/46+F61 -> 1.0456522 | G62: =(G$101-G$55)/46+G61 -> 1.0456522 | H62: =(H$101-H$55)/46+H61 -> 1.0456522 | I62: =(I$101-I$55)/46+I61 -> 1.0456522 | ... AA62: =(AA$101-AA$55)/46+AA61 -> 1.0456522
A63: 2032 | B63: =(B$101-B$55)/46+B62 -> 1.0521739 | C63: =(C$101-C$55)/46+C62 -> 1.0521739 | D63: =(D$101-D$55)/46+D62 -> 1.0521739 | E63: =(E$101-E$55)/46+E62 -> 1.0521739 | F63: =(F$101-F$55)/46+F62 -> 1.0521739 | G63: =(G$101-G$55)/46+G62 -> 1.0521739 | H63: =(H$101-H$55)/46+H62 -> 1.0521739 | I63: =(I$101-I$55)/46+I62 -> 1.0521739 | ... AA63: =(AA$101-AA$55)/46+AA62 -> 1.0521739
A64: 2033 | B64: =(B$101-B$55)/46+B63 -> 1.0586957 | C64: =(C$101-C$55)/46+C63 -> 1.0586957 | D64: =(D$101-D$55)/46+D63 -> 1.0586957 | E64: =(E$101-E$55)/46+E63 -> 1.0586957 | F64: =(F$101-F$55)/46+F63 -> 1.0586957 | G64: =(G$101-G$55)/46+G63 -> 1.0586957 | H64: =(H$101-H$55)/46+H63 -> 1.0586957 | I64: =(I$101-I$55)/46+I63 -> 1.0586957 | ... AA64: =(AA$101-AA$55)/46+AA63 -> 1.0586957
...
