Workbook

Sheet Fishman 2021
B1: Historical | E1: 2050 LED | H1: 2050 SSP1 | K1: 2050 SSP2 | R1: Chosen 2050 target
B2: SFH | C2: MFH | D2: RT | E2: SFH | F2: MFH | G2: RT | H2: SFH | I2: MFH | J2: RT | K2: SFH | L2: MFH | M2: RT | O2: Method | R2: SFH | S2: MFH | T2: RT
A3: 1 | B3: 0.84667228 | C3: 0.11682393 | D3: 0.0023841618 | E3: 0.1 | F3: 0.765 | G3: 0.135 | H3: 0.35 | I3: 0.5525 | J3: 0.0975 | K3: 0.55 | L3: 0.3825 | M3: 0.0675 | O3: 2 | Q3: 1 | R3: =K3 -> 0.55 | S3: =L3 -> 0.3825 | T3: =M3 -> 0.0675
A4: 2 | B4: 0.84667228 | C4: 0.11682393 | D4: 0.0023841618 | E4: 0.1 | F4: 0.765 | G4: 0.135 | H4: 0.35 | I4: 0.5525 | J4: 0.0975 | K4: 0.55 | L4: 0.3825 | M4: 0.0675 | O4: 2 | Q4: 2 | R4: =K4 -> 0.55 | S4: =L4 -> 0.3825 | T4: =M4 -> 0.0675
A5: 3 | B5: 0.4 | C5: 0.588 | D5: 0.012 | E5: 0.2 | F5: 0.64 | G5: 0.16 | H5: 0.35 | I5: 0.52 | J5: 0.13 | K5: 0.4 | L5: 0.48 | M5: 0.12 | O5: 2 | Q5: 3 | R5: =K5 -> 0.4 | S5: =L5 -> 0.48 | T5: =M5 -> 0.12
A6: 4 | B6: 0.25 | C6: 0.735 | D6: 0.015 | E6: 0.2 | F6: 0.64 | G6: 0.16 | H6: 0.35 | I6: 0.52 | J6: 0.13 | K6: 0.4 | L6: 0.48 | M6: 0.12 | O6: 2 | Q6: 4 | R6: =K6 -> 0.4 | S6: =L6 -> 0.48 | T6: =M6 -> 0.12
A7: 5 | B7: 0.25 | C7: 0.735 | D7: 0.015 | E7: 0.2 | F7: 0.64 | G7: 0.16 | H7: 0.35 | I7: 0.52 | J7: 0.13 | K7: 0.4 | L7: 0.48 | M7: 0.12 | O7: 2 | Q7: 5 | R7: =K7 -> 0.4 | S7: =L7 -> 0.48 | T7: =M7 -> 0.12
A8: 6 | B8: 0.25 | C8: 0.735 | D8: 0.015 | E8: 0.2 | F8: 0.64 | G8: 0.16 | H8: 0.35 | I8: 0.52 | J8: 0.13 | K8: 0.4 | L8: 0.48 | M8: 0.12 | O8: 2 | Q8: 6 | R8: =K8 -> 0.4 | S8: =L8 -> 0.48 | T8: =M8 -> 0.12
A9: 7 | B9: 0.5 | C9: 0.49 | D9: 0.01 | E9: 0.2 | F9: 0.68 | G9: 0.12 | H9: 0.3 | I9: 0.595 | J9: 0.105 | K9: 0.4 | L9: 0.51 | M9: 0.09 | O9: 2 | Q9: 7 | R9: =K9 -> 0.4 | S9: =L9 -> 0.51 | T9: =M9 -> 0.09
A10: 8 | B10: 0.75 | C10: 0.245 | D10: 0.005 | E10: 0.2 | F10: 0.68 | G10: 0.12 | H10: 0.3 | I10: 0.595 | J10: 0.105 | K10: 0.4 | L10: 0.51 | M10: 0.09 | O10: 2 | Q10: 8 | R10: =K10 -> 0.4 | S10: =L10 -> 0.51 | T10: =M10 -> 0.09
A11: 9 | B11: 0.75 | C11: 0.245 | D11: 0.005 | E11: 0.2 | F11: 0.68 | G11: 0.12 | H11: 0.3 | I11: 0.595 | J11: 0.105 | K11: 0.4 | L11: 0.51 | M11: 0.09 | O11: 2 | Q11: 9 | R11: =K11 -> 0.4 | S11: =L11 -> 0.51 | T11: =M11 -> 0.09
A12: 10 | B12: 0.75 | C12: 0.245 | D12: 0.005 | E12: 0.2 | F12: 0.68 | G12: 0.12 | H12: 0.3 | I12: 0.595 | J12: 0.105 | K12: 0.4 | L12: 0.51 | M12: 0.09 | O12: 2 | Q12: 10 | R12: =K12 -> 0.4 | S12: =L12 -> 0.51 | T12: =M12 -> 0.09
A13: 11 | B13: 0.42313698 | C13: 0.56532576 | D13: 0.01153726 | E13: 0.16666667 | F13: 0.70833333 | G13: 0.125 | H13: 0.225 | I13: 0.65875 | J13: 0.11625 | K13: 0.30833333 | L13: 0.58791667 | M13: 0.10375 | O13: 2 | Q13: 11 | R13: =K13 -> 0.30833333 | S13: =L13 -> 0.58791667 | T13: =M13 -> 0.10375
A14: 12 | B14: 0.44639478 | C14: 0.54253311 | D14: 0.011072104 | E14: 0.2 | F14: 0.68 | G14: 0.12 | H14: 0.25 | I14: 0.6375 | J14: 0.1125 | K14: 0.3 | L14: 0.595 | M14: 0.105 | O14: 2 | Q14: 12 | R14: =K14 -> 0.3 | S14: =L14 -> 0.595 | T14: =M14 -> 0.105
... A28: 26 | B28: 0.75 | C28: 0.245 | D28: 0.005 | E28: 0.2 | F28: 0.68 | G28: 0.12 | H28: 0.3 | I28: 0.595 | J28: 0.105 | K28: 0.4 | L28: 0.51 | M28: 0.09 | O28: 2 | Q28: 26 | R28: =K28 -> 0.4 | S28: =L28 -> 0.51 | T28: =M28 -> 0.09
B31: Methods
B32: 1 | D32: (Original + SSP2)/2
B33: 2 | D33: SSP2
B34: 3 | D34: SSP1
B36: Based on Fishman et al. 2021 | E36: https://doi.org/10.1111/jiec.13122
A38: Note: | B38: Values represent proxies as the Fishman et al study does not distinguish between urban and rural fractions of the stock, while we apply this to the urban fraction only. Also, a slightly different definition of building types is used, so it cannot be seen as a 1/1 implemenation of the study. Another thing that is unclear is whether the Fishman numbers relate to the stock or to the annual inflow.
A39: Assumptions: | C39: We assume that the SFH refers to both detached and semi-detached SFHs, so we use apply the sum and the original distribution between detached & semi-detached houses

Sheet Housing_type_original
A1: Region | B1: Area | C1: Detached | D1: Semi-detached | E1: Appartment | F1: High-rise
A2: 1 | B2: Urban | C2: 0.294 | D2: 0.147 | E2: 0.126 | F2: 0.165
A3: 1 | B3: Rural | C3: 0.219 | D3: 0.02 | E3: 0.02 | F3: 0.01
A4: 2 | B4: Urban | C4: 0.527 | D4: 0.057 | E4: 0.071 | F4: 0.138
A5: 2 | B5: Rural | C5: 0.198 | D5: 0.003 | E5: 0.005 | F5: 0.001
A6: 3 | B6: Urban | C6: 0.294 | D6: 0.147 | E6: 0.126 | F6: 0.165
A7: 3 | B7: Rural | C7: 0.219 | D7: 0.02 | E7: 0.02 | F7: 0.01
A8: 4 | B8: Urban | C8: 0.294 | D8: 0.147 | E8: 0.126 | F8: 0.165
A9: 4 | B9: Rural | C9: 0.219 | D9: 0.02 | E9: 0.02 | F9: 0.01
A10: 5 | B10: Urban | C10: 0.294 | D10: 0.147 | E10: 0.126 | F10: 0.165
A11: 5 | B11: Rural | C11: 0.219 | D11: 0.02 | E11: 0.02 | F11: 0.01
A12: 6 | B12: Urban | C12: 0.294 | D12: 0.147 | E12: 0.126 | F12: 0.165
A13: 6 | B13: Rural | C13: 0.219 | D13: 0.02 | E13: 0.02 | F13: 0.01
... A53: 26 | B53: Rural | C53: 0.219 | D53: 0.02 | E53: 0.02 | F53: 0.01

Sheet Housing_type_dynamic
A1: time | B1: Region | C1: Area | D1: Detached | E1: Semi-detached | F1: Appartment | G1: High-rise
A2: 2020 | B2: 1 | C2: Urban | D2: =Housing_type_original!C2/SUM(Housing_type_original!$C2:$F2) -> 0.40163934 | E2: =Housing_type_original!D2/SUM(Housing_type_original!$C2:$F2) -> 0.20081967 | F2: =Housing_type_original!E2/SUM(Housing_type_original!$C2:$F2) -> 0.17213115 | G2: =Housing_type_original!F2/SUM(Housing_type_original!$C2:$F2) -> 0.22540984
A3: 2020 | B3: 1 | C3: Rural | D3: =Housing_type_original!C3/SUM(Housing_type_original!$C3:$F3) -> 0.81412639 | E3: =Housing_type_original!D3/SUM(Housing_type_original!$C3:$F3) -> 0.074349442 | F3: =Housing_type_original!E3/SUM(Housing_type_original!$C3:$F3) -> 0.074349442 | G3: =Housing_type_original!F3/SUM(Housing_type_original!$C3:$F3) -> 0.037174721
A4: 2020 | B4: 2 | C4: Urban | D4: =Housing_type_original!C4/SUM(Housing_type_original!$C4:$F4) -> 0.66456494 | E4: =Housing_type_original!D4/SUM(Housing_type_original!$C4:$F4) -> 0.071878941 | F4: =Housing_type_original!E4/SUM(Housing_type_original!$C4:$F4) -> 0.089533417 | G4: =Housing_type_original!F4/SUM(Housing_type_original!$C4:$F4) -> 0.1740227
A5: 2020 | B5: 2 | C5: Rural | D5: =Housing_type_original!C5/SUM(Housing_type_original!$C5:$F5) -> 0.95652174 | E5: =Housing_type_original!D5/SUM(Housing_type_original!$C5:$F5) -> 0.014492754 | F5: =Housing_type_original!E5/SUM(Housing_type_original!$C5:$F5) -> 0.024154589 | G5: =Housing_type_original!F5/SUM(Housing_type_original!$C5:$F5) -> 0.0048309179
A6: 2020 | B6: 3 | C6: Urban | D6: =Housing_type_original!C6/SUM(Housing_type_original!$C6:$F6) -> 0.40163934 | E6: =Housing_type_original!D6/SUM(Housing_type_original!$C6:$F6) -> 0.20081967 | F6: =Housing_type_original!E6/SUM(Housing_type_original!$C6:$F6) -> 0.17213115 | G6: =Housing_type_original!F6/SUM(Housing_type_original!$C6:$F6) -> 0.22540984
A7: 2020 | B7: 3 | C7: Rural | D7: =Housing_type_original!C7/SUM(Housing_type_original!$C7:$F7) -> 0.81412639 | E7: =Housing_type_original!D7/SUM(Housing_type_original!$C7:$F7) -> 0.074349442 | F7: =Housing_type_original!E7/SUM(Housing_type_original!$C7:$F7) -> 0.074349442 | G7: =Housing_type_original!F7/SUM(Housing_type_original!$C7:$F7) -> 0.037174721
A8: 2020 | B8: 4 | C8: Urban | D8: =Housing_type_original!C8/SUM(Housing_type_original!$C8:$F8) -> 0.40163934 | E8: =Housing_type_original!D8/SUM(Housing_type_original!$C8:$F8) -> 0.20081967 | F8: =Housing_type_original!E8/SUM(Housing_type_original!$C8:$F8) -> 0.17213115 | G8: =Housing_type_original!F8/SUM(Housing_type_original!$C8:$F8) -> 0.22540984
A9: 2020 | B9: 4 | C9: Rural | D9: =Housing_type_original!C9/SUM(Housing_type_original!$C9:$F9) -> 0.81412639 | E9: =Housing_type_original!D9/SUM(Housing_type_original!$C9:$F9) -> 0.074349442 | F9: =Housing_type_original!E9/SUM(Housing_type_original!$C9:$F9) -> 0.074349442 | G9: =Housing_type_original!F9/SUM(Housing_type_original!$C9:$F9) -> 0.037174721
A10: 2020 | B10: 5 | C10: Urban | D10: =Housing_type_original!C10/SUM(Housing_type_original!$C10:$F10) -> 0.40163934 | E10: =Housing_type_original!D10/SUM(Housing_type_original!$C10:$F10) -> 0.20081967 | F10: =Housing_type_original!E10/SUM(Housing_type_original!$C10:$F10) -> 0.17213115 | G10: =Housing_type_original!F10/SUM(Housing_type_original!$C10:$F10) -> 0.22540984
A11: 2020 | B11: 5 | C11: Rural | D11: =Housing_type_original!C11/SUM(Housing_type_original!$C11:$F11) -> 0.81412639 | E11: =Housing_type_original!D11/SUM(Housing_type_original!$C11:$F11) -> 0.074349442 | F11: =Housing_type_original!E11/SUM(Housing_type_original!$C11:$F11) -> 0.074349442 | G11: =Housing_type_original!F11/SUM(Housing_type_original!$C11:$F11) -> 0.037174721
A12: 2020 | B12: 6 | C12: Urban | D12: =Housing_type_original!C12/SUM(Housing_type_original!$C12:$F12) -> 0.40163934 | E12: =Housing_type_original!D12/SUM(Housing_type_original!$C12:$F12) -> 0.20081967 | F12: =Housing_type_original!E12/SUM(Housing_type_original!$C12:$F12) -> 0.17213115 | G12: =Housing_type_original!F12/SUM(Housing_type_original!$C12:$F12) -> 0.22540984
A13: 2020 | B13: 6 | C13: Rural | D13: =Housing_type_original!C13/SUM(Housing_type_original!$C13:$F13) -> 0.81412639 | E13: =Housing_type_original!D13/SUM(Housing_type_original!$C13:$F13) -> 0.074349442 | F13: =Housing_type_original!E13/SUM(Housing_type_original!$C13:$F13) -> 0.074349442 | G13: =Housing_type_original!F13/SUM(Housing_type_original!$C13:$F13) -> 0.037174721
... A53: 2020 | B53: 26 | C53: Rural | D53: =Housing_type_original!C53/SUM(Housing_type_original!$C53:$F53) -> 0.81412639 | E53: =Housing_type_original!D53/SUM(Housing_type_original!$C53:$F53) -> 0.074349442 | F53: =Housing_type_original!E53/SUM(Housing_type_original!$C53:$F53) -> 0.074349442 | G53: =Housing_type_original!F53/SUM(Housing_type_original!$C53:$F53) -> 0.037174721
A54: 2050 | B54: 1 | C54: Urban | D54: =D2 -> 0.40163934 | E54: =E2 -> 0.20081967 | F54: =F2 -> 0.17213115 | G54: =G2 -> 0.22540984
A55: 2050 | B55: 1 | C55: Rural | D55: =D3 -> 0.81412639 | E55: =E3 -> 0.074349442 | F55: =F3 -> 0.074349442 | G55: =G3 -> 0.037174721
A56: 2050 | B56: 2 | C56: Urban | D56: =D4 -> 0.66456494 | E56: =E4 -> 0.071878941 | F56: =F4 -> 0.089533417 | G56: =G4 -> 0.1740227
A57: 2050 | B57: 2 | C57: Rural | D57: =D5 -> 0.95652174 | E57: =E5 -> 0.014492754 | F57: =F5 -> 0.024154589 | G57: =G5 -> 0.0048309179
A58: 2050 | B58: 3 | C58: Urban | D58: =D6 -> 0.40163934 | E58: =E6 -> 0.20081967 | F58: =F6 -> 0.17213115 | G58: =G6 -> 0.22540984
A59: 2050 | B59: 3 | C59: Rural | D59: =D7 -> 0.81412639 | E59: =E7 -> 0.074349442 | F59: =F7 -> 0.074349442 | G59: =G7 -> 0.037174721
A60: 2050 | B60: 4 | C60: Urban | D60: =D8 -> 0.40163934 | E60: =E8 -> 0.20081967 | F60: =F8 -> 0.17213115 | G60: =G8 -> 0.22540984
A61: 2050 | B61: 4 | C61: Rural | D61: =D9 -> 0.81412639 | E61: =E9 -> 0.074349442 | F61: =F9 -> 0.074349442 | G61: =G9 -> 0.037174721
A62: 2050 | B62: 5 | C62: Urban | D62: =D10 -> 0.40163934 | E62: =E10 -> 0.20081967 | F62: =F10 -> 0.17213115 | G62: =G10 -> 0.22540984
A63: 2050 | B63: 5 | C63: Rural | D63: =D11 -> 0.81412639 | E63: =E11 -> 0.074349442 | F63: =F11 -> 0.074349442 | G63: =G11 -> 0.037174721
A64: 2050 | B64: 6 | C64: Urban | D64: =D12 -> 0.40163934 | E64: =E12 -> 0.20081967 | F64: =F12 -> 0.17213115 | G64: =G12 -> 0.22540984
A65: 2050 | B65: 6 | C65: Rural | D65: =D13 -> 0.81412639 | E65: =E13 -> 0.074349442 | F65: =F13 -> 0.074349442 | G65: =G13 -> 0.037174721
... A105: 2050 | B105: 26 | C105: Rural | D105: =D53 -> 0.81412639 | E105: =E53 -> 0.074349442 | F105: =F53 -> 0.074349442 | G105: =G53 -> 0.037174721

Sheet Housing_type_dynamic_SSP2
A1: time | B1: Region | C1: Area | D1: Detached | E1: Semi-detached | F1: Appartment | G1: High-rise
A2: 2020 | B2: 1 | C2: Urban | D2: =Housing_type_original!C2/SUM(Housing_type_original!$C2:$F2) -> 0.40163934 | E2: =Housing_type_original!D2/SUM(Housing_type_original!$C2:$F2) -> 0.20081967 | F2: =Housing_type_original!E2/SUM(Housing_type_original!$C2:$F2) -> 0.17213115 | G2: =Housing_type_original!F2/SUM(Housing_type_original!$C2:$F2) -> 0.22540984
A3: 2020 | B3: 1 | C3: Rural | D3: =Housing_type_original!C3/SUM(Housing_type_original!$C3:$F3) -> 0.81412639 | E3: =Housing_type_original!D3/SUM(Housing_type_original!$C3:$F3) -> 0.074349442 | F3: =Housing_type_original!E3/SUM(Housing_type_original!$C3:$F3) -> 0.074349442 | G3: =Housing_type_original!F3/SUM(Housing_type_original!$C3:$F3) -> 0.037174721
A4: 2020 | B4: 2 | C4: Urban | D4: =Housing_type_original!C4/SUM(Housing_type_original!$C4:$F4) -> 0.66456494 | E4: =Housing_type_original!D4/SUM(Housing_type_original!$C4:$F4) -> 0.071878941 | F4: =Housing_type_original!E4/SUM(Housing_type_original!$C4:$F4) -> 0.089533417 | G4: =Housing_type_original!F4/SUM(Housing_type_original!$C4:$F4) -> 0.1740227
A5: 2020 | B5: 2 | C5: Rural | D5: =Housing_type_original!C5/SUM(Housing_type_original!$C5:$F5) -> 0.95652174 | E5: =Housing_type_original!D5/SUM(Housing_type_original!$C5:$F5) -> 0.014492754 | F5: =Housing_type_original!E5/SUM(Housing_type_original!$C5:$F5) -> 0.024154589 | G5: =Housing_type_original!F5/SUM(Housing_type_original!$C5:$F5) -> 0.0048309179
A6: 2020 | B6: 3 | C6: Urban | D6: =Housing_type_original!C6/SUM(Housing_type_original!$C6:$F6) -> 0.40163934 | E6: =Housing_type_original!D6/SUM(Housing_type_original!$C6:$F6) -> 0.20081967 | F6: =Housing_type_original!E6/SUM(Housing_type_original!$C6:$F6) -> 0.17213115 | G6: =Housing_type_original!F6/SUM(Housing_type_original!$C6:$F6) -> 0.22540984
A7: 2020 | B7: 3 | C7: Rural | D7: =Housing_type_original!C7/SUM(Housing_type_original!$C7:$F7) -> 0.81412639 | E7: =Housing_type_original!D7/SUM(Housing_type_original!$C7:$F7) -> 0.074349442 | F7: =Housing_type_original!E7/SUM(Housing_type_original!$C7:$F7) -> 0.074349442 | G7: =Housing_type_original!F7/SUM(Housing_type_original!$C7:$F7) -> 0.037174721
A8: 2020 | B8: 4 | C8: Urban | D8: =Housing_type_original!C8/SUM(Housing_type_original!$C8:$F8) -> 0.40163934 | E8: =Housing_type_original!D8/SUM(Housing_type_original!$C8:$F8) -> 0.20081967 | F8: =Housing_type_original!E8/SUM(Housing_type_original!$C8:$F8) -> 0.17213115 | G8: =Housing_type_original!F8/SUM(Housing_type_original!$C8:$F8) -> 0.22540984
A9: 2020 | B9: 4 | C9: Rural | D9: =Housing_type_original!C9/SUM(Housing_type_original!$C9:$F9) -> 0.81412639 | E9: =Housing_type_original!D9/SUM(Housing_type_original!$C9:$F9) -> 0.074349442 | F9: =Housing_type_original!E9/SUM(Housing_type_original!$C9:$F9) -> 0.074349442 | G9: =Housing_type_original!F9/SUM(Housing_type_original!$C9:$F9) -> 0.037174721
A10: 2020 | B10: 5 | C10: Urban | D10: =Housing_type_original!C10/SUM(Housing_type_original!$C10:$F10) -> 0.40163934 | E10: =Housing_type_original!D10/SUM(Housing_type_original!$C10:$F10) -> 0.20081967 | F10: =Housing_type_original!E10/SUM(Housing_type_original!$C10:$F10) -> 0.17213115 | G10: =Housing_type_original!F10/SUM(Housing_type_original!$C10:$F10) -> 0.22540984
A11: 2020 | B11: 5 | C11: Rural | D11: =Housing_type_original!C11/SUM(Housing_type_original!$C11:$F11) -> 0.81412639 | E11: =Housing_type_original!D11/SUM(Housing_type_original!$C11:$F11) -> 0.074349442 | F11: =Housing_type_original!E11/SUM(Housing_type_original!$C11:$F11) -> 0.074349442 | G11: =Housing_type_original!F11/SUM(Housing_type_original!$C11:$F11) -> 0.037174721
A12: 2020 | B12: 6 | C12: Urban | D12: =Housing_type_original!C12/SUM(Housing_type_original!$C12:$F12) -> 0.40163934 | E12: =Housing_type_original!D12/SUM(Housing_type_original!$C12:$F12) -> 0.20081967 | F12: =Housing_type_original!E12/SUM(Housing_type_original!$C12:$F12) -> 0.17213115 | G12: =Housing_type_original!F12/SUM(Housing_type_original!$C12:$F12) -> 0.22540984
A13: 2020 | B13: 6 | C13: Rural | D13: =Housing_type_original!C13/SUM(Housing_type_original!$C13:$F13) -> 0.81412639 | E13: =Housing_type_original!D13/SUM(Housing_type_original!$C13:$F13) -> 0.074349442 | F13: =Housing_type_original!E13/SUM(Housing_type_original!$C13:$F13) -> 0.074349442 | G13: =Housing_type_original!F13/SUM(Housing_type_original!$C13:$F13) -> 0.037174721
... A53: 2020 | B53: 26 | C53: Rural | D53: =Housing_type_original!C53/SUM(Housing_type_original!$C53:$F53) -> 0.81412639 | E53: =Housing_type_original!D53/SUM(Housing_type_original!$C53:$F53) -> 0.074349442 | F53: =Housing_type_original!E53/SUM(Housing_type_original!$C53:$F53) -> 0.074349442 | G53: =Housing_type_original!F53/SUM(Housing_type_original!$C53:$F53) -> 0.037174721
A54: 2050 | B54: 1 | C54: Urban | D54: =VLOOKUP($B54,'Fishman 2021'!$Q$3:$T$28,2,FALSE)*(D2/SUM($D2:$E2)) -> 0.36666667 | E54: =VLOOKUP($B54,'Fishman 2021'!$Q$3:$T$28,2,FALSE)*(E2/SUM($D2:$E2)) -> 0.18333333 | F54: =(VLOOKUP($B54,'Fishman 2021'!$Q$3:$T$28,3,FALSE)+VLOOKUP($B54,'Fishman 2021'!$Q$3:$T$28,4,FALSE))*0.5 -> 0.225 | G54: =(VLOOKUP($B54,'Fishman 2021'!$Q$3:$T$28,3,FALSE)+VLOOKUP($B54,'Fishman 2021'!$Q$3:$T$28,4,FALSE))*0.5 -> 0.225
A55: 2050 | B55: 1 | C55: Rural | D55: =D3 -> 0.81412639 | E55: =E3 -> 0.074349442 | F55: =F3 -> 0.074349442 | G55: =G3 -> 0.037174721
A56: 2050 | B56: 2 | C56: Urban | D56: =VLOOKUP($B56,'Fishman 2021'!$Q$3:$T$28,2,FALSE)*(D4/SUM($D4:$E4)) -> 0.49631849 | E56: =VLOOKUP($B56,'Fishman 2021'!$Q$3:$T$28,2,FALSE)*(E4/SUM($D4:$E4)) -> 0.053681507 | F56: =(VLOOKUP($B56,'Fishman 2021'!$Q$3:$T$28,3,FALSE)+VLOOKUP($B56,'Fishman 2021'!$Q$3:$T$28,4,FALSE))*0.5 -> 0.225 | G56: =(VLOOKUP($B56,'Fishman 2021'!$Q$3:$T$28,3,FALSE)+VLOOKUP($B56,'Fishman 2021'!$Q$3:$T$28,4,FALSE))*0.5 -> 0.225
A57: 2050 | B57: 2 | C57: Rural | D57: =D5 -> 0.95652174 | E57: =E5 -> 0.014492754 | F57: =F5 -> 0.024154589 | G57: =G5 -> 0.0048309179
A58: 2050 | B58: 3 | C58: Urban | D58: =VLOOKUP($B58,'Fishman 2021'!$Q$3:$T$28,2,FALSE)*(D6/SUM($D6:$E6)) -> 0.26666667 | E58: =VLOOKUP($B58,'Fishman 2021'!$Q$3:$T$28,2,FALSE)*(E6/SUM($D6:$E6)) -> 0.13333333 | F58: =(VLOOKUP($B58,'Fishman 2021'!$Q$3:$T$28,3,FALSE)+VLOOKUP($B58,'Fishman 2021'!$Q$3:$T$28,4,FALSE))*0.5 -> 0.3 | G58: =(VLOOKUP($B58,'Fishman 2021'!$Q$3:$T$28,3,FALSE)+VLOOKUP($B58,'Fishman 2021'!$Q$3:$T$28,4,FALSE))*0.5 -> 0.3
A59: 2050 | B59: 3 | C59: Rural | D59: =D7 -> 0.81412639 | E59: =E7 -> 0.074349442 | F59: =F7 -> 0.074349442 | G59: =G7 -> 0.037174721
A60: 2050 | B60: 4 | C60: Urban | D60: =VLOOKUP($B60,'Fishman 2021'!$Q$3:$T$28,2,FALSE)*(D8/SUM($D8:$E8)) -> 0.26666667 | E60: =VLOOKUP($B60,'Fishman 2021'!$Q$3:$T$28,2,FALSE)*(E8/SUM($D8:$E8)) -> 0.13333333 | F60: =(VLOOKUP($B60,'Fishman 2021'!$Q$3:$T$28,3,FALSE)+VLOOKUP($B60,'Fishman 2021'!$Q$3:$T$28,4,FALSE))*0.5 -> 0.3 | G60: =(VLOOKUP($B60,'Fishman 2021'!$Q$3:$T$28,3,FALSE)+VLOOKUP($B60,'Fishman 2021'!$Q$3:$T$28,4,FALSE))*0.5 -> 0.3
A61: 2050 | B61: 4 | C61: Rural | D61: =D9 -> 0.81412639 | E61: =E9 -> 0.074349442 | F61: =F9 -> 0.074349442 | G61: =G9 -> 0.037174721
A62: 2050 | B62: 5 | C62: Urban | D62: =VLOOKUP($B62,'Fishman 2021'!$Q$3:$T$28,2,FALSE)*(D10/SUM($D10:$E10)) -> 0.26666667 | E62: =VLOOKUP($B62,'Fishman 2021'!$Q$3:$T$28,2,FALSE)*(E10/SUM($D10:$E10)) -> 0.13333333 | F62: =(VLOOKUP($B62,'Fishman 2021'!$Q$3:$T$28,3,FALSE)+VLOOKUP($B62,'Fishman 2021'!$Q$3:$T$28,4,FALSE))*0.5 -> 0.3 | G62: =(VLOOKUP($B62,'Fishman 2021'!$Q$3:$T$28,3,FALSE)+VLOOKUP($B62,'Fishman 2021'!$Q$3:$T$28,4,FALSE))*0.5 -> 0.3
A63: 2050 | B63: 5 | C63: Rural | D63: =D11 -> 0.81412639 | E63: =E11 -> 0.074349442 | F63: =F11 -> 0.074349442 | G63: =G11 -> 0.037174721
A64: 2050 | B64: 6 | C64: Urban | D64: =VLOOKUP($B64,'Fishman 2021'!$Q$3:$T$28,2,FALSE)*(D12/SUM($D12:$E12)) -> 0.26666667 | E64: =VLOOKUP($B64,'Fishman 2021'!$Q$3:$T$28,2,FALSE)*(E12/SUM($D12:$E12)) -> 0.13333333 | F64: =(VLOOKUP($B64,'Fishman 2021'!$Q$3:$T$28,3,FALSE)+VLOOKUP($B64,'Fishman 2021'!$Q$3:$T$28,4,FALSE))*0.5 -> 0.3 | G64: =(VLOOKUP($B64,'Fishman 2021'!$Q$3:$T$28,3,FALSE)+VLOOKUP($B64,'Fishman 2021'!$Q$3:$T$28,4,FALSE))*0.5 -> 0.3
A65: 2050 | B65: 6 | C65: Rural | D65: =D13 -> 0.81412639 | E65: =E13 -> 0.074349442 | F65: =F13 -> 0.074349442 | G65: =G13 -> 0.037174721
A66: 2050 | B66: 7 | C66: Urban | D66: =VLOOKUP($B66,'Fishman 2021'!$Q$3:$T$28,2,FALSE)*(D14/SUM($D14:$E14)) -> 0.26666667 | E66: =VLOOKUP($B66,'Fishman 2021'!$Q$3:$T$28,2,FALSE)*(E14/SUM($D14:$E14)) -> 0.13333333 | F66: =(VLOOKUP($B66,'Fishman 2021'!$Q$3:$T$28,3,FALSE)+VLOOKUP($B66,'Fishman 2021'!$Q$3:$T$28,4,FALSE))*0.5 -> 0.3 | G66: =(VLOOKUP($B66,'Fishman 2021'!$Q$3:$T$28,3,FALSE)+VLOOKUP($B66,'Fishman 2021'!$Q$3:$T$28,4,FALSE))*0.5 -> 0.3
A67: 2050 | B67: 7 | C67: Rural | D67: =D15 -> 0.81412639 | E67: =E15 -> 0.074349442 | F67: =F15 -> 0.074349442 | G67: =G15 -> 0.037174721
A68: 2050 | B68: 8 | C68: Urban | D68: =VLOOKUP($B68,'Fishman 2021'!$Q$3:$T$28,2,FALSE)*(D16/SUM($D16:$E16)) -> 0.26666667 | E68: =VLOOKUP($B68,'Fishman 2021'!$Q$3:$T$28,2,FALSE)*(E16/SUM($D16:$E16)) -> 0.13333333 | F68: =(VLOOKUP($B68,'Fishman 2021'!$Q$3:$T$28,3,FALSE)+VLOOKUP($B68,'Fishman 2021'!$Q$3:$T$28,4,FALSE))*0.5 -> 0.3 | G68: =(VLOOKUP($B68,'Fishman 2021'!$Q$3:$T$28,3,FALSE)+VLOOKUP($B68,'Fishman 2021'!$Q$3:$T$28,4,FALSE))*0.5 -> 0.3
A69: 2050 | B69: 8 | C69: Rural | D69: =D17 -> 0.81412639 | E69: =E17 -> 0.074349442 | F69: =F17 -> 0.074349442 | G69: =G17 -> 0.037174721
A70: 2050 | B70: 9 | C70: Urban | D70: =VLOOKUP($B70,'Fishman 2021'!$Q$3:$T$28,2,FALSE)*(D18/SUM($D18:$E18)) -> 0.26666667 | E70: =VLOOKUP($B70,'Fishman 2021'!$Q$3:$T$28,2,FALSE)*(E18/SUM($D18:$E18)) -> 0.13333333 | F70: =(VLOOKUP($B70,'Fishman 2021'!$Q$3:$T$28,3,FALSE)+VLOOKUP($B70,'Fishman 2021'!$Q$3:$T$28,4,FALSE))*0.5 -> 0.3 | G70: =(VLOOKUP($B70,'Fishman 2021'!$Q$3:$T$28,3,FALSE)+VLOOKUP($B70,'Fishman 2021'!$Q$3:$T$28,4,FALSE))*0.5 -> 0.3
A71: 2050 | B71: 9 | C71: Rural | D71: =D19 -> 0.81412639 | E71: =E19 -> 0.074349442 | F71: =F19 -> 0.074349442 | G71: =G19 -> 0.037174721
A72: 2050 | B72: 10 | C72: Urban | D72: =VLOOKUP($B72,'Fishman 2021'!$Q$3:$T$28,2,FALSE)*(D20/SUM($D20:$E20)) -> 0.26666667 | E72: =VLOOKUP($B72,'Fishman 2021'!$Q$3:$T$28,2,FALSE)*(E20/SUM($D20:$E20)) -> 0.13333333 | F72: =(VLOOKUP($B72,'Fishman 2021'!$Q$3:$T$28,3,FALSE)+VLOOKUP($B72,'Fishman 2021'!$Q$3:$T$28,4,FALSE))*0.5 -> 0.3 | G72: =(VLOOKUP($B72,'Fishman 2021'!$Q$3:$T$28,3,FALSE)+VLOOKUP($B72,'Fishman 2021'!$Q$3:$T$28,4,FALSE))*0.5 -> 0.3
A73: 2050 | B73: 10 | C73: Rural | D73: =D21 -> 0.81412639 | E73: =E21 -> 0.074349442 | F73: =F21 -> 0.074349442 | G73: =G21 -> 0.037174721
A74: 2050 | B74: 11 | C74: Urban | D74: =VLOOKUP($B74,'Fishman 2021'!$Q$3:$T$28,2,FALSE)*(D22/SUM($D22:$E22)) -> 0.1283377 | E74: =VLOOKUP($B74,'Fishman 2021'!$Q$3:$T$28,2,FALSE)*(E22/SUM($D22:$E22)) -> 0.17999564 | F74: =(VLOOKUP($B74,'Fishman 2021'!$Q$3:$T$28,3,FALSE)+VLOOKUP($B74,'Fishman 2021'!$Q$3:$T$28,4,FALSE))*0.5 -> 0.34583333 | G74: =(VLOOKUP($B74,'Fishman 2021'!$Q$3:$T$28,3,FALSE)+VLOOKUP($B74,'Fishman 2021'!$Q$3:$T$28,4,FALSE))*0.5 -> 0.34583333
A75: 2050 | B75: 11 | C75: Rural | D75: =D23 -> 0.55284553 | E75: =E23 -> 0.24796748 | F75: =F23 -> 0.14634146 | G75: =G23 -> 0.052845528
A76: 2050 | B76: 12 | C76: Urban | D76: =VLOOKUP($B76,'Fishman 2021'!$Q$3:$T$28,2,FALSE)*(D24/SUM($D24:$E24)) -> 0.25086207 | E76: =VLOOKUP($B76,'Fishman 2021'!$Q$3:$T$28,2,FALSE)*(E24/SUM($D24:$E24)) -> 0.049137931 | F76: =(VLOOKUP($B76,'Fishman 2021'!$Q$3:$T$28,3,FALSE)+VLOOKUP($B76,'Fishman 2021'!$Q$3:$T$28,4,FALSE))*0.5 -> 0.35 | G76: =(VLOOKUP($B76,'Fishman 2021'!$Q$3:$T$28,3,FALSE)+VLOOKUP($B76,'Fishman 2021'!$Q$3:$T$28,4,FALSE))*0.5 -> 0.35
A77: 2050 | B77: 12 | C77: Rural | D77: =D25 -> 0.81818182 | E77: =E25 -> 0.057416268 | F77: =F25 -> 0.050239234 | G77: =G25 -> 0.074162679
A78: 2050 | B78: 13 | C78: Urban | D78: =VLOOKUP($B78,'Fishman 2021'!$Q$3:$T$28,2,FALSE)*(D26/SUM($D26:$E26)) -> 0.26666667 | E78: =VLOOKUP($B78,'Fishman 2021'!$Q$3:$T$28,2,FALSE)*(E26/SUM($D26:$E26)) -> 0.13333333 | F78: =(VLOOKUP($B78,'Fishman 2021'!$Q$3:$T$28,3,FALSE)+VLOOKUP($B78,'Fishman 2021'!$Q$3:$T$28,4,FALSE))*0.5 -> 0.3 | G78: =(VLOOKUP($B78,'Fishman 2021'!$Q$3:$T$28,3,FALSE)+VLOOKUP($B78,'Fishman 2021'!$Q$3:$T$28,4,FALSE))*0.5 -> 0.3
A79: 2050 | B79: 13 | C79: Rural | D79: =D27 -> 0.81412639 | E79: =E27 -> 0.074349442 | F79: =F27 -> 0.074349442 | G79: =G27 -> 0.037174721
...

Sheet Pivot
A1: Area | B1: Urban
A2: Region | B2: 23
A4: Row Labels | B4: Sum of Detached | C4: Sum of Semi-detached | D4: Sum of Appartment | E4: Sum of High-rise
A5: 2020 | B5: 0.53846154 | C5: 0.017416546 | D5: 0.25689405 | E5: 0.18722787
A6: 2050 | B6: 0.4843342 | C6: 0.015665796 | D6: 0.25 | E6: 0.25
A7: Grand Total | B7: 1.0227957 | C7: 0.033082342 | D7: 0.50689405 | E7: 0.43722787
