Workbook

Sheet template_IRP_newest_CP_7reg
A1: model | B1: scenario | C1: region | D1: variable | E1: unit | F1: 2005 | G1: 2010 | H1: 2015 | I1: 2020 | J1: 2025 | K1: 2030 | L1: 2035 | M1: 2040 | N1: 2045 | O1: 2050 | P1: 2055 | Q1: 2060
A2: IMAGE | B2: SSP2_CP_RE | C2: North America | D2: Stock Addition|Transportation|Vehicles|Road|Passenger Cars | E2: thousand/yr | F2: 17158.933 | G2: 14575.792 | H2: 19916.75 | I2: 16617.956 | J2: 18354.73 | K2: 11117.182 | L2: 14730.5 | M2: 13007.512 | N2: 11992.839 | O2: 11451.338 | P2: 11036.857 | Q2: 10840.275
A3: IMAGE | B3: SSP2_CP_RE | C3: North America | D3: Stock Addition|Transportation|Vehicles|Road|Buses | E3: thousand/yr | F3: 24.117812 | G3: 23.642208 | H3: 25.217767 | I3: 22.158699 | J3: 42.455465 | K3: 31.090656 | L3: 34.350753 | M3: 33.6051 | N3: 36.601044 | O3: 38.847617 | P3: 40.61806 | Q3: 41.442674
A4: IMAGE | B4: SSP2_CP_RE | C4: North America | D4: Stock Addition|Transportation|Vehicles|Road|Bicycles | E4: thousand/yr | F4: 1204.266 | G4: 1431.7168 | H4: 1785.0889 | I4: 1446.5822 | J4: 2674.687 | K4: 1986.0955 | L4: 2116.3901 | M4: 2094.7063 | N4: 2452.2993 | O4: 2546.9259 | P4: 2812.8763 | Q4: 2988.5301
A5: IMAGE | B5: SSP2_CP_RE | C5: North America | D5: Stock Addition|Transportation|Vehicles|Road|Trucks | E5: thousand/yr | F5: 1684.2476 | G5: 1779.0502 | H5: 2347.8368 | I5: 2231.059 | J5: 1484.3736 | K5: 2863.8285 | L5: 2500.3939 | M5: 2320.3934 | N5: 2595.1161 | O5: 2652.664 | P5: 2391.8419 | Q5: 2533.5177
A6: IMAGE | B6: SSP2_CP_RE | C6: North America | D6: Stock Addition|Transportation|Vehicles|Rail|Trains | E6: thousand/yr | F6: 0.012282182 | G6: 0.023715814 | H6: 0.053994702 | I6: 0.030022869 | J6: 0.08688115 | K6: 0.046322051 | L6: 0.061691074 | M6: 0.083075841 | N6: 0.13335643 | O6: 0.19364848 | P6: 0.23693426 | Q6: 0.23058542
A7: IMAGE | B7: SSP2_CP_RE | C7: North America | D7: Stock Addition|Transportation|Vehicles|Rail|Cargo | E7: thousand/yr | F7: 0.73975731 | G7: 0.57435468 | H7: 0.70454718 | I7: 0.8104578 | J7: 0.92456556 | K7: 1.0154932 | L7: 1.1323625 | M7: 1.1864164 | N7: 1.0060919 | O7: 0.88097655 | P7: 0.93659496 | Q7: 0.95744548
A8: IMAGE | B8: SSP2_CP_RE | C8: North America | D8: Stock Addition|Transportation|Air|Planes | E8: thousand/yr | F8: 0.28560152 | G8: 0.16635477 | H8: 0.3253114 | I8: 0.7281161 | J8: 0.19775958 | K8: 0.00090527844 | L8: 0.084274588 | M8: 0.18391999 | N8: 0.20914016 | O8: 0.10636349 | P8: 0.067582463 | Q8: 0.095053127
A9: IMAGE | B9: SSP2_CP_RE | C9: North America | D9: Stock Addition|Transportation|Air|Cargo | E9: thousand/yr | F9: 0.064210424 | G9: 0.029537352 | H9: 0.080717453 | I9: 0.12331871 | J9: 0.064654945 | K9: 0.036357235 | L9: 0.052061476 | M9: 0.065990302 | N9: 0.070950464 | O9: 0.05604199 | P9: 0.048330141 | Q9: 0.051329842
A10: IMAGE | B10: SSP2_CP_RE | C10: North America | D10: Stock Addition|Transportation|Ships | E10: thousand/yr | F10: 1.3088772 | G10: 0.58576168 | H10: 1.2715574 | I10: 2.1257802 | J10: 1.3279813 | K10: 1.2823672 | L10: 1.2098236 | M10: 1.2662519 | N10: 1.3793221 | O10: 1.3600613 | P10: 1.3395608 | Q10: 1.3142955
A11: IMAGE | B11: SSP2_CP_RE | C11: North America | D11: Stock Addition|Buildings|Residential|Single-Family Houses | E11: m^2/yr | F11: 2.4388334e+08 | G11: 1.5088493e+08 | H11: 2.4379431e+08 | I11: 1.4382031e+08 | J11: 14005449 | K11: 7503102.2 | L11: 6689682.7 | M11: 5836470.3 | N11: 4853798.4 | O11: 66230447 | P11: 1.642835e+08 | Q11: 1.6845516e+08
A12: IMAGE | B12: SSP2_CP_RE | C12: North America | D12: Stock Addition|Buildings|Residential|Multi-Family Houses | E12: m^2/yr | F12: 54638311 | G12: 39465742 | H12: 58204934 | I12: 37471267 | J12: 11109428 | K12: 10374443 | L12: 9930625.9 | M12: 8868452.8 | N12: 7101521.1 | O12: 33228972 | P12: 77938255 | Q12: 81071981
... A1894: IMAGE | B1894: SSP2_CP_RE | C1894: World | D1894: Services|Transportation|Ships | E1894: Gtkm/yr | F1894: 57752.196 | G1894: 57773.87 | H1894: 61017.051 | I1894: 71857.319 | J1894: 78545.884 | K1894: 84647.541 | L1894: 91373.18 | M1894: 98737.244 | N1894: 106935.97 | O1894: 123114.09 | P1894: 133390.88 | Q1894: 138529.35
A1895: IMAGE | B1895: SSP2_CP_RE | C1895: World | D1895: Services|People Housed|Single-Family Houses | E1895: Million people | F1895: 4010.1255 | G1895: 4210.9265 | H1895: 4397.3634 | I1895: 4543.3728 | J1895: 4656.4434 | K1895: 4729.4722 | L1895: 4763.6929 | M1895: 4761.675 | N1895: 4726.2438 | O1895: 4658.3676 | P1895: 4563.354 | Q1895: 4470.3312 | S1895: Single-Family Houses
A1896: IMAGE | B1896: SSP2_CP_RE | C1896: World | D1896: Services|People Housed|Multi-Family Houses | E1896: Million people | F1896: 1676.165 | G1896: 1812.4931 | H1896: 1957.7762 | I1896: 2101.2516 | J1896: 2243.8314 | K1896: 2387.583 | L1896: 2532.5337 | M1896: 2676.797 | N1896: 2817.4311 | O1896: 2951.7001 | P1896: 3076.0658 | Q1896: 3171.3267 | S1896: Multi-Family Houses
A1897: IMAGE | B1897: SSP2_CP_RE | C1897: World | D1897: Services|People Housed|Residential Towers | E1897: Million people | F1897: 856.32657 | G1897: 934.68844 | H1897: 1021.4407 | I1897: 1110.6954 | J1897: 1203.5668 | K1897: 1303.1745 | L1897: 1408.8262 | M1897: 1518.202 | N1897: 1628.4004 | O1897: 1736.8412 | P1897: 1838.9374 | Q1897: 1918.4252 | S1897: Residential Towers
A1898: IMAGE | B1898: SSP2_CP_RE | C1898: World | D1898: Total flows|Virgin input|Steel | E1898: Mt/yr | F1898: 296.85801 | G1898: 282.55449 | H1898: 346.05437 | I1898: 322.09418 | J1898: 311.0204 | K1898: 290.56829 | L1898: 284.22559 | M1898: 267.61512 | N1898: 267.38222 | O1898: 265.39787 | P1898: 267.64262 | Q1898: 253.60451
A1899: IMAGE | B1899: SSP2_CP_RE | C1899: World | D1899: Total flows|Virgin input|Concrete | E1899: Mt/yr | F1899: 5407.3939 | G1899: 5832.5779 | H1899: 6235.416 | I1899: 5746.4627 | J1899: 5643.8407 | K1899: 5597.7412 | L1899: 5162.5024 | M1899: 4619.6334 | N1899: 4163.2194 | O1899: 3780.5154 | P1899: 3786.3807 | Q1899: 3791.1276
A1900: IMAGE | B1900: SSP2_CP_RE | C1900: World | D1900: Total flows|Virgin input|Non-Ferrous Metals|Aluminium | E1900: Mt/yr | F1900: 20.013841 | G1900: 19.614811 | H1900: 26.581076 | I1900: 23.734476 | J1900: 24.378899 | K1900: 17.254849 | L1900: 16.956571 | M1900: 15.867982 | N1900: 19.645439 | O1900: 21.713448 | P1900: 22.548262 | Q1900: 19.757507
A1901: IMAGE | B1901: SSP2_CP_RE | C1901: World | D1901: Total flows|Virgin input|Non-Ferrous Metals|Copper | E1901: Mt/yr | F1901: 8.7733509 | G1901: 9.449183 | H1901: 12.347827 | I1901: 12.250575 | J1901: 13.039949 | K1901: 10.119264 | L1901: 9.2605277 | M1901: 8.3874756 | N1901: 10.685016 | O1901: 12.295152 | P1901: 13.18651 | Q1901: 11.907449
A1902: IMAGE | B1902: SSP2_CP_RE | C1902: World | D1902: Total flows|Virgin input|Glass | E1902: Mt/yr | F1902: 21.956727 | G1902: 21.845997 | H1902: 25.128447 | I1902: 22.25706 | J1902: 22.042047 | K1902: 20.591912 | L1902: 18.372555 | M1902: 16.304601 | N1902: 15.053001 | O1902: 14.798024 | P1902: 15.181835 | Q1902: 14.837
A1903: IMAGE | B1903: SSP2_CP_RE | C1903: World | D1903: Total flows|Virgin input|Construction Wood | E1903: Mt/yr | F1903: 192.99885 | G1903: 195.52527 | H1903: 189.00556 | I1903: 166.15261 | J1903: 192.74303 | K1903: 239.07971 | L1903: 252.68933 | M1903: 269.48021 | N1903: 284.5326 | O1903: 302.86908 | P1903: 316.35298 | Q1903: 318.0684
A1904: IMAGE | B1904: SSP2_CP_RE | C1904: World | D1904: Total flows|Recycled|Steel | E1904: Mt/yr | F1904: 151.08227 | G1904: 179.68484 | H1904: 200.20344 | I1904: 226.95068 | J1904: 242.77568 | K1904: 261.30147 | L1904: 275.77642 | M1904: 288.17383 | N1904: 294.85462 | O1904: 295.76009 | P1904: 297.64631 | Q1904: 301.85248
A1905: IMAGE | B1905: SSP2_CP_RE | C1905: World | D1905: Total flows|Recycled|Concrete | E1905: Mt/yr | F1905: 0 | G1905: 0 | H1905: 0 | I1905: 24.410574 | J1905: 207.55941 | K1905: 425.62893 | L1905: 646.23561 | M1905: 858.5458 | N1905: 1049.6869 | O1905: 1190.3187 | P1905: 1195.2872 | Q1905: 1186.8615
A1906: IMAGE | B1906: SSP2_CP_RE | C1906: World | D1906: Total flows|Recycled|Non-Ferrous Metals|Aluminium | E1906: Mt/yr | F1906: 14.739969 | G1906: 16.853424 | H1906: 18.767983 | I1906: 21.13593 | J1906: 21.569829 | K1906: 22.759593 | L1906: 23.464022 | M1906: 23.47456 | N1906: 23.05777 | O1906: 22.715263 | P1906: 22.992112 | Q1906: 23.35834
A1907: IMAGE | B1907: SSP2_CP_RE | C1907: World | D1907: Total flows|Recycled|Non-Ferrous Metals|Copper | E1907: Mt/yr | F1907: 3.502363 | G1907: 4.1681866 | H1907: 4.6512264 | I1907: 5.9981289 | J1907: 5.82214 | K1907: 6.7445411 | L1907: 7.5935654 | M1907: 8.2239909 | N1907: 8.4820925 | O1907: 8.6257173 | P1907: 8.7948266 | Q1907: 8.9991654
A1908: IMAGE | B1908: SSP2_CP_RE | C1908: World | D1908: Total flows|Recycled|Glass | E1908: Mt/yr | F1908: 4.5252766 | G1908: 5.2828797 | H1908: 5.7039041 | I1908: 6.929968 | J1908: 7.309288 | K1908: 8.1785933 | L1908: 8.564231 | M1908: 8.3881032 | N1908: 7.6740732 | O1908: 6.6515974 | P1908: 6.4989717 | Q1908: 6.5304662
A1909: IMAGE | B1909: SSP2_CP_RE | C1909: World | D1909: Total flows|Recycled|Construction Wood | E1909: Mt/yr | F1909: 20.849467 | G1909: 23.467521 | H1909: 26.235094 | I1909: 28.61149 | J1909: 28.81153 | K1909: 29.914259 | L1909: 30.987007 | M1909: 31.65375 | N1909: 31.903614 | O1909: 31.703211 | P1909: 32.153051 | Q1909: 32.959177
... A1921: IMAGE | B1921: SSP2_CP_RE | C1921: World | D1921: Total flows|Losses|Construction Wood | E1921: Mt/yr | F1921: 61.461903 | G1921: 69.624505 | H1921: 78.389122 | I1921: 84.440498 | J1921: 81.554693 | K1921: 81.343178 | L1921: 81.023977 | M1921: 79.677956 | N1921: 78.066448 | O1921: 75.274297 | P1921: 75.023785 | Q1921: 76.904747

Sheet indicators
A1: Indicator | B1: region | C1: building type | D1: unit | E1: =template_IRP_newest_CP_7reg!I1 -> 2020 | F1: =template_IRP_newest_CP_7reg!J1 -> 2025 | G1: =template_IRP_newest_CP_7reg!K1 -> 2030 | H1: =template_IRP_newest_CP_7reg!L1 -> 2035 | I1: =template_IRP_newest_CP_7reg!M1 -> 2040 | J1: =template_IRP_newest_CP_7reg!N1 -> 2045 | K1: =template_IRP_newest_CP_7reg!O1 -> 2050 | L1: =template_IRP_newest_CP_7reg!P1 -> 2055 | M1: =template_IRP_newest_CP_7reg!Q1 -> 2060 | Q1: ResEff | U1: ResEff
A2: Per capita floorspace | B2: North America | C2: Single-Family Houses | D2: m2/cap | E2: =template_IRP_newest_CP_7reg!I147/(template_IRP_newest_CP_7reg!I215*1000000) -> 59.429951 | F2: =template_IRP_newest_CP_7reg!J147/(template_IRP_newest_CP_7reg!J215*1000000) -> 55.463603 | G2: =template_IRP_newest_CP_7reg!K147/(template_IRP_newest_CP_7reg!K215*1000000) -> 51.065593 | H2: =template_IRP_newest_CP_7reg!L147/(template_IRP_newest_CP_7reg!L215*1000000) -> 46.714215 | I2: =template_IRP_newest_CP_7reg!M147/(template_IRP_newest_CP_7reg!M215*1000000) -> 42.397503 | J2: =template_IRP_newest_CP_7reg!N147/(template_IRP_newest_CP_7reg!N215*1000000) -> 38.104583 | K2: =template_IRP_newest_CP_7reg!O147/(template_IRP_newest_CP_7reg!O215*1000000) -> 34.379609 | L2: =template_IRP_newest_CP_7reg!P147/(template_IRP_newest_CP_7reg!P215*1000000) -> 34.143383 | M2: =template_IRP_newest_CP_7reg!Q147/(template_IRP_newest_CP_7reg!Q215*1000000) -> 34.429421 | P2: 2020 | Q2: 2050 | T2: 2020 | U2: 2060
C3: Multi-Family Houses | D3: m2/cap | E3: =template_IRP_newest_CP_7reg!I148/(template_IRP_newest_CP_7reg!I216*1000000) -> 45.841358 | F3: =template_IRP_newest_CP_7reg!J148/(template_IRP_newest_CP_7reg!J216*1000000) -> 42.907485 | G3: =template_IRP_newest_CP_7reg!K148/(template_IRP_newest_CP_7reg!K216*1000000) -> 39.604647 | H3: =template_IRP_newest_CP_7reg!L148/(template_IRP_newest_CP_7reg!L216*1000000) -> 36.30192 | I3: =template_IRP_newest_CP_7reg!M148/(template_IRP_newest_CP_7reg!M216*1000000) -> 33.006619 | J3: =template_IRP_newest_CP_7reg!N148/(template_IRP_newest_CP_7reg!N216*1000000) -> 29.724853 | K3: =template_IRP_newest_CP_7reg!O148/(template_IRP_newest_CP_7reg!O216*1000000) -> 26.825684 | L3: =template_IRP_newest_CP_7reg!P148/(template_IRP_newest_CP_7reg!P216*1000000) -> 26.267222 | M3: =template_IRP_newest_CP_7reg!Q148/(template_IRP_newest_CP_7reg!Q216*1000000) -> 26.134586 | O3: =B2 -> North America | P3: =E5 -> 53.814247 | Q3: =M5 -> 30.365467 | S3: Steel | T3: =E49 -> 51.30897 | U3: =M49 -> 56.927264
C4: Residential Towers | D4: m2/cap | E4: =template_IRP_newest_CP_7reg!I149/(template_IRP_newest_CP_7reg!I217*1000000) -> 37.271638 | F4: =template_IRP_newest_CP_7reg!J149/(template_IRP_newest_CP_7reg!J217*1000000) -> 34.927848 | G4: =template_IRP_newest_CP_7reg!K149/(template_IRP_newest_CP_7reg!K217*1000000) -> 32.295255 | H4: =template_IRP_newest_CP_7reg!L149/(template_IRP_newest_CP_7reg!L217*1000000) -> 29.669177 | I4: =template_IRP_newest_CP_7reg!M149/(template_IRP_newest_CP_7reg!M217*1000000) -> 27.046858 | J4: =template_IRP_newest_CP_7reg!N149/(template_IRP_newest_CP_7reg!N217*1000000) -> 24.424044 | K4: =template_IRP_newest_CP_7reg!O149/(template_IRP_newest_CP_7reg!O217*1000000) -> 22.135249 | L4: =template_IRP_newest_CP_7reg!P149/(template_IRP_newest_CP_7reg!P217*1000000) -> 21.977908 | M4: =template_IRP_newest_CP_7reg!Q149/(template_IRP_newest_CP_7reg!Q217*1000000) -> 22.135719 | O4: =B7 -> Latin America + Caribbean | P4: =E10 -> 19.131339 | Q4: =M10 -> 27.581707 | S4: Al | T4: =E58 -> 2.9735131 | U4: =M58 -> 2.7610307
C5: Residential Total | D5: m2/cap | E5: =SUM(template_IRP_newest_CP_7reg!I147:I149)/(SUM(template_IRP_newest_CP_7reg!I215:I217)*1000000) -> 53.814247 | F5: =SUM(template_IRP_newest_CP_7reg!J147:J149)/(SUM(template_IRP_newest_CP_7reg!J215:J217)*1000000) -> 50.181664 | G5: =SUM(template_IRP_newest_CP_7reg!K147:K149)/(SUM(template_IRP_newest_CP_7reg!K215:K217)*1000000) -> 46.156683 | H5: =SUM(template_IRP_newest_CP_7reg!L147:L149)/(SUM(template_IRP_newest_CP_7reg!L215:L217)*1000000) -> 42.172877 | I5: =SUM(template_IRP_newest_CP_7reg!M147:M149)/(SUM(template_IRP_newest_CP_7reg!M215:M217)*1000000) -> 38.226063 | J5: =SUM(template_IRP_newest_CP_7reg!N147:N149)/(SUM(template_IRP_newest_CP_7reg!N215:N217)*1000000) -> 34.313043 | K5: =SUM(template_IRP_newest_CP_7reg!O147:O149)/(SUM(template_IRP_newest_CP_7reg!O215:O217)*1000000) -> 30.892852 | L5: =SUM(template_IRP_newest_CP_7reg!P147:P149)/(SUM(template_IRP_newest_CP_7reg!P215:P217)*1000000) -> 30.397425 | M5: =SUM(template_IRP_newest_CP_7reg!Q147:Q149)/(SUM(template_IRP_newest_CP_7reg!Q215:Q217)*1000000) -> 30.365467 | O5: =B12 -> Europe | P5: =E15 -> 41.139594 | Q5: =M15 -> 30.684671 | S5: Copper | T5: =E67 -> 1.087327 | U5: =M67 -> 0.94888234
C6: Commercial | D6: m2/cap | E6: =SUM(template_IRP_newest_CP_7reg!I150:I153)/(SUM(template_IRP_newest_CP_7reg!I215:I217)*1000000) -> 21.621853 | F6: =SUM(template_IRP_newest_CP_7reg!J150:J153)/(SUM(template_IRP_newest_CP_7reg!J215:J217)*1000000) -> 21.255439 | G6: =SUM(template_IRP_newest_CP_7reg!K150:K153)/(SUM(template_IRP_newest_CP_7reg!K215:K217)*1000000) -> 20.931466 | H6: =SUM(template_IRP_newest_CP_7reg!L150:L153)/(SUM(template_IRP_newest_CP_7reg!L215:L217)*1000000) -> 20.475084 | I6: =SUM(template_IRP_newest_CP_7reg!M150:M153)/(SUM(template_IRP_newest_CP_7reg!M215:M217)*1000000) -> 19.918141 | J6: =SUM(template_IRP_newest_CP_7reg!N150:N153)/(SUM(template_IRP_newest_CP_7reg!N215:N217)*1000000) -> 19.283652 | K6: =SUM(template_IRP_newest_CP_7reg!O150:O153)/(SUM(template_IRP_newest_CP_7reg!O215:O217)*1000000) -> 18.576315 | L6: =SUM(template_IRP_newest_CP_7reg!P150:P153)/(SUM(template_IRP_newest_CP_7reg!P215:P217)*1000000) -> 17.818811 | M6: =SUM(template_IRP_newest_CP_7reg!Q150:Q153)/(SUM(template_IRP_newest_CP_7reg!Q215:Q217)*1000000) -> 17.133002 | O6: =B17 -> EECCA | P6: =E20 -> 20.343442 | Q6: =M20 -> 24.808878 | S6: Concrete | T6: =E76 -> 1028.9594 | U6: =M76 -> 982.97831
B7: Latin America + Caribbean | C7: Single-Family Houses | D7: m2/cap | E7: =template_IRP_newest_CP_7reg!I387/(template_IRP_newest_CP_7reg!I455*1000000) -> 20.34355 | F7: =template_IRP_newest_CP_7reg!J387/(template_IRP_newest_CP_7reg!J455*1000000) -> 20.366347 | G7: =template_IRP_newest_CP_7reg!K387/(template_IRP_newest_CP_7reg!K455*1000000) -> 21.766658 | H7: =template_IRP_newest_CP_7reg!L387/(template_IRP_newest_CP_7reg!L455*1000000) -> 23.167414 | I7: =template_IRP_newest_CP_7reg!M387/(template_IRP_newest_CP_7reg!M455*1000000) -> 24.575694 | J7: =template_IRP_newest_CP_7reg!N387/(template_IRP_newest_CP_7reg!N455*1000000) -> 26.06247 | K7: =template_IRP_newest_CP_7reg!O387/(template_IRP_newest_CP_7reg!O455*1000000) -> 27.540211 | L7: =template_IRP_newest_CP_7reg!P387/(template_IRP_newest_CP_7reg!P455*1000000) -> 28.722729 | M7: =template_IRP_newest_CP_7reg!Q387/(template_IRP_newest_CP_7reg!Q455*1000000) -> 29.687581 | O7: =B22 -> Africa | P7: =E25 -> 10.34158 | Q7: =M25 -> 16.231561 | S7: Glass | T7: =E85 -> 3.6562775 | U7: =M85 -> 3.5723553
C8: Multi-Family Houses | D8: m2/cap | E8: =template_IRP_newest_CP_7reg!I388/(template_IRP_newest_CP_7reg!I456*1000000) -> 19.333491 | F8: =template_IRP_newest_CP_7reg!J388/(template_IRP_newest_CP_7reg!J456*1000000) -> 19.428097 | G8: =template_IRP_newest_CP_7reg!K388/(template_IRP_newest_CP_7reg!K456*1000000) -> 20.76585 | H8: =template_IRP_newest_CP_7reg!L388/(template_IRP_newest_CP_7reg!L456*1000000) -> 22.051145 | I8: =template_IRP_newest_CP_7reg!M388/(template_IRP_newest_CP_7reg!M456*1000000) -> 23.305222 | J8: =template_IRP_newest_CP_7reg!N388/(template_IRP_newest_CP_7reg!N456*1000000) -> 24.597388 | K8: =template_IRP_newest_CP_7reg!O388/(template_IRP_newest_CP_7reg!O456*1000000) -> 25.884025 | L8: =template_IRP_newest_CP_7reg!P388/(template_IRP_newest_CP_7reg!P456*1000000) -> 26.893523 | M8: =template_IRP_newest_CP_7reg!Q388/(template_IRP_newest_CP_7reg!Q456*1000000) -> 27.796844 | O8: =B27 -> West Asia | P8: =E30 -> 21.227544 | Q8: =M30 -> 26.807831 | S8: Wood | T8: =E94 -> 52.282094 | U8: =M94 -> 56.61975
C9: Residential Towers | D9: m2/cap | E9: =template_IRP_newest_CP_7reg!I389/(template_IRP_newest_CP_7reg!I457*1000000) -> 15.802835 | F9: =template_IRP_newest_CP_7reg!J389/(template_IRP_newest_CP_7reg!J457*1000000) -> 15.900494 | G9: =template_IRP_newest_CP_7reg!K389/(template_IRP_newest_CP_7reg!K457*1000000) -> 17.05738 | H9: =template_IRP_newest_CP_7reg!L389/(template_IRP_newest_CP_7reg!L457*1000000) -> 18.217695 | I9: =template_IRP_newest_CP_7reg!M389/(template_IRP_newest_CP_7reg!M457*1000000) -> 19.392095 | J9: =template_IRP_newest_CP_7reg!N389/(template_IRP_newest_CP_7reg!N457*1000000) -> 20.634385 | K9: =template_IRP_newest_CP_7reg!O389/(template_IRP_newest_CP_7reg!O457*1000000) -> 21.915154 | L9: =template_IRP_newest_CP_7reg!P389/(template_IRP_newest_CP_7reg!P457*1000000) -> 23.020469 | M9: =template_IRP_newest_CP_7reg!Q389/(template_IRP_newest_CP_7reg!Q457*1000000) -> 24.024136 | O9: =B32 -> Asia + Pacific | P9: =E35 -> 16.874322 | Q9: =M35 -> 24.706867
C10: Residential Total | D10: m2/cap | E10: =SUM(template_IRP_newest_CP_7reg!I387:I389)/(SUM(template_IRP_newest_CP_7reg!I455:I457)*1000000) -> 19.131339 | F10: =SUM(template_IRP_newest_CP_7reg!J387:J389)/(SUM(template_IRP_newest_CP_7reg!J455:J457)*1000000) -> 19.172853 | G10: =SUM(template_IRP_newest_CP_7reg!K387:K389)/(SUM(template_IRP_newest_CP_7reg!K455:K457)*1000000) -> 20.471927 | H10: =SUM(template_IRP_newest_CP_7reg!L387:L389)/(SUM(template_IRP_newest_CP_7reg!L455:L457)*1000000) -> 21.744565 | I10: =SUM(template_IRP_newest_CP_7reg!M387:M389)/(SUM(template_IRP_newest_CP_7reg!M455:M457)*1000000) -> 23.003029 | J10: =SUM(template_IRP_newest_CP_7reg!N387:N389)/(SUM(template_IRP_newest_CP_7reg!N455:N457)*1000000) -> 24.313266 | K10: =SUM(template_IRP_newest_CP_7reg!O387:O389)/(SUM(template_IRP_newest_CP_7reg!O455:O457)*1000000) -> 25.618315 | L10: =SUM(template_IRP_newest_CP_7reg!P387:P389)/(SUM(template_IRP_newest_CP_7reg!P455:P457)*1000000) -> 26.668949 | M10: =SUM(template_IRP_newest_CP_7reg!Q387:Q389)/(SUM(template_IRP_newest_CP_7reg!Q455:Q457)*1000000) -> 27.581707 | O10: =B37 -> World | P10: =E40 -> 19.959525 | Q10: =M40 -> 23.669749
C11: Commercial | D11: m2/cap | E11: =SUM(template_IRP_newest_CP_7reg!I390:I393)/(SUM(template_IRP_newest_CP_7reg!I455:I457)*1000000) -> 4.3346512 | F11: =SUM(template_IRP_newest_CP_7reg!J390:J393)/(SUM(template_IRP_newest_CP_7reg!J455:J457)*1000000) -> 4.5129952 | G11: =SUM(template_IRP_newest_CP_7reg!K390:K393)/(SUM(template_IRP_newest_CP_7reg!K455:K457)*1000000) -> 4.9689251 | H11: =SUM(template_IRP_newest_CP_7reg!L390:L393)/(SUM(template_IRP_newest_CP_7reg!L455:L457)*1000000) -> 5.4322603 | I11: =SUM(template_IRP_newest_CP_7reg!M390:M393)/(SUM(template_IRP_newest_CP_7reg!M455:M457)*1000000) -> 5.8903777 | J11: =SUM(template_IRP_newest_CP_7reg!N390:N393)/(SUM(template_IRP_newest_CP_7reg!N455:N457)*1000000) -> 6.3784432 | K11: =SUM(template_IRP_newest_CP_7reg!O390:O393)/(SUM(template_IRP_newest_CP_7reg!O455:O457)*1000000) -> 6.90471 | L11: =SUM(template_IRP_newest_CP_7reg!P390:P393)/(SUM(template_IRP_newest_CP_7reg!P455:P457)*1000000) -> 7.5316014 | M11: =SUM(template_IRP_newest_CP_7reg!Q390:Q393)/(SUM(template_IRP_newest_CP_7reg!Q455:Q457)*1000000) -> 8.078901
B12: Europe | C12: Single-Family Houses | D12: m2/cap | E12: =template_IRP_newest_CP_7reg!I627/(template_IRP_newest_CP_7reg!I695*1000000) -> 43.468807 | F12: =template_IRP_newest_CP_7reg!J627/(template_IRP_newest_CP_7reg!J695*1000000) -> 41.486034 | G12: =template_IRP_newest_CP_7reg!K627/(template_IRP_newest_CP_7reg!K695*1000000) -> 39.464286 | H12: =template_IRP_newest_CP_7reg!L627/(template_IRP_newest_CP_7reg!L695*1000000) -> 37.524333 | I12: =template_IRP_newest_CP_7reg!M627/(template_IRP_newest_CP_7reg!M695*1000000) -> 35.653202 | J12: =template_IRP_newest_CP_7reg!N627/(template_IRP_newest_CP_7reg!N695*1000000) -> 33.844602 | K12: =template_IRP_newest_CP_7reg!O627/(template_IRP_newest_CP_7reg!O695*1000000) -> 32.286483 | L12: =template_IRP_newest_CP_7reg!P627/(template_IRP_newest_CP_7reg!P695*1000000) -> 32.014069 | M12: =template_IRP_newest_CP_7reg!Q627/(template_IRP_newest_CP_7reg!Q695*1000000) -> 31.953472
C13: Multi-Family Houses | D13: m2/cap | E13: =template_IRP_newest_CP_7reg!I628/(template_IRP_newest_CP_7reg!I696*1000000) -> 40.207307 | F13: =template_IRP_newest_CP_7reg!J628/(template_IRP_newest_CP_7reg!J696*1000000) -> 38.579669 | G13: =template_IRP_newest_CP_7reg!K628/(template_IRP_newest_CP_7reg!K696*1000000) -> 36.773801 | H13: =template_IRP_newest_CP_7reg!L628/(template_IRP_newest_CP_7reg!L696*1000000) -> 34.979538 | I13: =template_IRP_newest_CP_7reg!M628/(template_IRP_newest_CP_7reg!M696*1000000) -> 33.199485 | J13: =template_IRP_newest_CP_7reg!N628/(template_IRP_newest_CP_7reg!N696*1000000) -> 31.435795 | K13: =template_IRP_newest_CP_7reg!O628/(template_IRP_newest_CP_7reg!O696*1000000) -> 29.896569 | L13: =template_IRP_newest_CP_7reg!P628/(template_IRP_newest_CP_7reg!P696*1000000) -> 29.665657 | M13: =template_IRP_newest_CP_7reg!Q628/(template_IRP_newest_CP_7reg!Q696*1000000) -> 29.644171 | O13: Commercial | Q13: =Q1 -> ResEff | U13: ResEff
C14: Residential Towers | D14: m2/cap | E14: =template_IRP_newest_CP_7reg!I629/(template_IRP_newest_CP_7reg!I697*1000000) -> 39.327957 | F14: =template_IRP_newest_CP_7reg!J629/(template_IRP_newest_CP_7reg!J697*1000000) -> 38.051496 | G14: =template_IRP_newest_CP_7reg!K629/(template_IRP_newest_CP_7reg!K697*1000000) -> 36.658518 | H14: =template_IRP_newest_CP_7reg!L629/(template_IRP_newest_CP_7reg!L697*1000000) -> 35.2681 | I14: =template_IRP_newest_CP_7reg!M629/(template_IRP_newest_CP_7reg!M697*1000000) -> 33.870038 | J14: =template_IRP_newest_CP_7reg!N629/(template_IRP_newest_CP_7reg!N697*1000000) -> 32.456755 | K14: =template_IRP_newest_CP_7reg!O629/(template_IRP_newest_CP_7reg!O697*1000000) -> 31.199062 | L14: =template_IRP_newest_CP_7reg!P629/(template_IRP_newest_CP_7reg!P697*1000000) -> 31.042077 | M14: =template_IRP_newest_CP_7reg!Q629/(template_IRP_newest_CP_7reg!Q697*1000000) -> 31.054997 | P14: =P2 -> 2020 | Q14: =Q2 -> 2050 | T14: 2020 | U14: 2060
C15: Residential Total | D15: m2/cap | E15: =SUM(template_IRP_newest_CP_7reg!I627:I629)/(SUM(template_IRP_newest_CP_7reg!I695:I697)*1000000) -> 41.139594 | F15: =SUM(template_IRP_newest_CP_7reg!J627:J629)/(SUM(template_IRP_newest_CP_7reg!J695:J697)*1000000) -> 39.451074 | G15: =SUM(template_IRP_newest_CP_7reg!K627:K629)/(SUM(template_IRP_newest_CP_7reg!K695:K697)*1000000) -> 37.654259 | H15: =SUM(template_IRP_newest_CP_7reg!L627:L629)/(SUM(template_IRP_newest_CP_7reg!L695:L697)*1000000) -> 35.894293 | I15: =SUM(template_IRP_newest_CP_7reg!M627:M629)/(SUM(template_IRP_newest_CP_7reg!M695:M697)*1000000) -> 34.163909 | J15: =SUM(template_IRP_newest_CP_7reg!N627:N629)/(SUM(template_IRP_newest_CP_7reg!N695:N697)*1000000) -> 32.458986 | K15: =SUM(template_IRP_newest_CP_7reg!O627:O629)/(SUM(template_IRP_newest_CP_7reg!O695:O697)*1000000) -> 30.96978 | L15: =SUM(template_IRP_newest_CP_7reg!P627:P629)/(SUM(template_IRP_newest_CP_7reg!P695:P697)*1000000) -> 30.725522 | M15: =SUM(template_IRP_newest_CP_7reg!Q627:Q629)/(SUM(template_IRP_newest_CP_7reg!Q695:Q697)*1000000) -> 30.684671 | O15: =O3 -> North America | P15: =E6 -> 21.621853 | Q15: =M6 -> 17.133002 | S15: Steel | T15: =E50 -> 85.994533 | U15: =M50 -> 80.725475
C16: Commercial | D16: m2/cap | E16: =SUM(template_IRP_newest_CP_7reg!I630:I633)/(SUM(template_IRP_newest_CP_7reg!I695:I697)*1000000) -> 14.353589 | F16: =SUM(template_IRP_newest_CP_7reg!J630:J633)/(SUM(template_IRP_newest_CP_7reg!J695:J697)*1000000) -> 14.65711 | G16: =SUM(template_IRP_newest_CP_7reg!K630:K633)/(SUM(template_IRP_newest_CP_7reg!K695:K697)*1000000) -> 15.056734 | H16: =SUM(template_IRP_newest_CP_7reg!L630:L633)/(SUM(template_IRP_newest_CP_7reg!L695:L697)*1000000) -> 15.383739 | I16: =SUM(template_IRP_newest_CP_7reg!M630:M633)/(SUM(template_IRP_newest_CP_7reg!M695:M697)*1000000) -> 15.603456 | J16: =SUM(template_IRP_newest_CP_7reg!N630:N633)/(SUM(template_IRP_newest_CP_7reg!N695:N697)*1000000) -> 15.692312 | K16: =SUM(template_IRP_newest_CP_7reg!O630:O633)/(SUM(template_IRP_newest_CP_7reg!O695:O697)*1000000) -> 15.651049 | L16: =SUM(template_IRP_newest_CP_7reg!P630:P633)/(SUM(template_IRP_newest_CP_7reg!P695:P697)*1000000) -> 15.524514 | M16: =SUM(template_IRP_newest_CP_7reg!Q630:Q633)/(SUM(template_IRP_newest_CP_7reg!Q695:Q697)*1000000) -> 15.338822 | O16: =O4 -> Latin America + Caribbean | P16: =E11 -> 4.3346512 | Q16: =M11 -> 8.078901 | S16: Al | T16: =E59 -> 4.9991666 | U16: =M59 -> 4.7408256
B17: EECCA | C17: Single-Family Houses | D17: m2/cap | E17: =template_IRP_newest_CP_7reg!I867/(template_IRP_newest_CP_7reg!I935*1000000) -> 20.943003 | F17: =template_IRP_newest_CP_7reg!J867/(template_IRP_newest_CP_7reg!J935*1000000) -> 21.204199 | G17: =template_IRP_newest_CP_7reg!K867/(template_IRP_newest_CP_7reg!K935*1000000) -> 22.211854 | H17: =template_IRP_newest_CP_7reg!L867/(template_IRP_newest_CP_7reg!L935*1000000) -> 23.106422 | I17: =template_IRP_newest_CP_7reg!M867/(template_IRP_newest_CP_7reg!M935*1000000) -> 23.84128 | J17: =template_IRP_newest_CP_7reg!N867/(template_IRP_newest_CP_7reg!N935*1000000) -> 24.464195 | K17: =template_IRP_newest_CP_7reg!O867/(template_IRP_newest_CP_7reg!O935*1000000) -> 24.899915 | L17: =template_IRP_newest_CP_7reg!P867/(template_IRP_newest_CP_7reg!P935*1000000) -> 25.314282 | M17: =template_IRP_newest_CP_7reg!Q867/(template_IRP_newest_CP_7reg!Q935*1000000) -> 25.539202 | O17: =O5 -> Europe | P17: =E16 -> 14.353589 | Q17: =M16 -> 15.338822 | S17: Copper | T17: =E68 -> 3.2862838 | U17: =M68 -> 3.2612676
C18: Multi-Family Houses | D18: m2/cap | E18: =template_IRP_newest_CP_7reg!I868/(template_IRP_newest_CP_7reg!I936*1000000) -> 20.218658 | F18: =template_IRP_newest_CP_7reg!J868/(template_IRP_newest_CP_7reg!J936*1000000) -> 20.559178 | G18: =template_IRP_newest_CP_7reg!K868/(template_IRP_newest_CP_7reg!K936*1000000) -> 21.679167 | H18: =template_IRP_newest_CP_7reg!L868/(template_IRP_newest_CP_7reg!L936*1000000) -> 22.575509 | I18: =template_IRP_newest_CP_7reg!M868/(template_IRP_newest_CP_7reg!M936*1000000) -> 23.20835 | J18: =template_IRP_newest_CP_7reg!N868/(template_IRP_newest_CP_7reg!N936*1000000) -> 23.723915 | K18: =template_IRP_newest_CP_7reg!O868/(template_IRP_newest_CP_7reg!O936*1000000) -> 24.137003 | L18: =template_IRP_newest_CP_7reg!P868/(template_IRP_newest_CP_7reg!P936*1000000) -> 24.527274 | M18: =template_IRP_newest_CP_7reg!Q868/(template_IRP_newest_CP_7reg!Q936*1000000) -> 24.65668 | O18: =O6 -> EECCA | P18: =E21 -> 4.4970505 | Q18: =M21 -> 8.7940294 | S18: Concrete | T18: =E77 -> 880.92819 | U18: =M77 -> 827.24715
C19: Residential Towers | D19: m2/cap | E19: =template_IRP_newest_CP_7reg!I869/(template_IRP_newest_CP_7reg!I937*1000000) -> 18.631626 | F19: =template_IRP_newest_CP_7reg!J869/(template_IRP_newest_CP_7reg!J937*1000000) -> 18.939431 | G19: =template_IRP_newest_CP_7reg!K869/(template_IRP_newest_CP_7reg!K937*1000000) -> 20.040805 | H19: =template_IRP_newest_CP_7reg!L869/(template_IRP_newest_CP_7reg!L937*1000000) -> 20.956962 | I19: =template_IRP_newest_CP_7reg!M869/(template_IRP_newest_CP_7reg!M937*1000000) -> 21.649924 | J19: =template_IRP_newest_CP_7reg!N869/(template_IRP_newest_CP_7reg!N937*1000000) -> 22.270484 | K19: =template_IRP_newest_CP_7reg!O869/(template_IRP_newest_CP_7reg!O937*1000000) -> 22.836665 | L19: =template_IRP_newest_CP_7reg!P869/(template_IRP_newest_CP_7reg!P937*1000000) -> 23.386777 | M19: =template_IRP_newest_CP_7reg!Q869/(template_IRP_newest_CP_7reg!Q937*1000000) -> 23.630835 | O19: =O7 -> Africa | P19: =E26 -> 1.6870683 | Q19: =M26 -> 4.1804172 | S19: Glass | T19: =E86 -> 7.7190328 | U19: =M86 -> 7.3907984
C20: Residential Total | D20: m2/cap | E20: =SUM(template_IRP_newest_CP_7reg!I867:I869)/(SUM(template_IRP_newest_CP_7reg!I935:I937)*1000000) -> 20.343442 | F20: =SUM(template_IRP_newest_CP_7reg!J867:J869)/(SUM(template_IRP_newest_CP_7reg!J935:J937)*1000000) -> 20.62254 | G20: =SUM(template_IRP_newest_CP_7reg!K867:K869)/(SUM(template_IRP_newest_CP_7reg!K935:K937)*1000000) -> 21.665604 | H20: =SUM(template_IRP_newest_CP_7reg!L867:L869)/(SUM(template_IRP_newest_CP_7reg!L935:L937)*1000000) -> 22.54726 | I20: =SUM(template_IRP_newest_CP_7reg!M867:M869)/(SUM(template_IRP_newest_CP_7reg!M935:M937)*1000000) -> 23.221772 | J20: =SUM(template_IRP_newest_CP_7reg!N867:N869)/(SUM(template_IRP_newest_CP_7reg!N935:N937)*1000000) -> 23.786819 | K20: =SUM(template_IRP_newest_CP_7reg!O867:O869)/(SUM(template_IRP_newest_CP_7reg!O935:O937)*1000000) -> 24.21804 | L20: =SUM(template_IRP_newest_CP_7reg!P867:P869)/(SUM(template_IRP_newest_CP_7reg!P935:P937)*1000000) -> 24.630702 | M20: =SUM(template_IRP_newest_CP_7reg!Q867:Q869)/(SUM(template_IRP_newest_CP_7reg!Q935:Q937)*1000000) -> 24.808878 | O20: =O8 -> West Asia | P20: =E31 -> 3.6611502 | Q20: =M31 -> 6.5363523 | S20: Wood | T20: =E95 -> 16.826321 | U20: =M95 -> 21.496855
C21: Commercial | D21: m2/cap | E21: =SUM(template_IRP_newest_CP_7reg!I870:I873)/(SUM(template_IRP_newest_CP_7reg!I935:I937)*1000000) -> 4.4970505 | F21: =SUM(template_IRP_newest_CP_7reg!J870:J873)/(SUM(template_IRP_newest_CP_7reg!J935:J937)*1000000) -> 4.9635107 | G21: =SUM(template_IRP_newest_CP_7reg!K870:K873)/(SUM(template_IRP_newest_CP_7reg!K935:K937)*1000000) -> 5.8070005 | H21: =SUM(template_IRP_newest_CP_7reg!L870:L873)/(SUM(template_IRP_newest_CP_7reg!L935:L937)*1000000) -> 6.6038705 | I21: =SUM(template_IRP_newest_CP_7reg!M870:M873)/(SUM(template_IRP_newest_CP_7reg!M935:M937)*1000000) -> 7.2584192 | J21: =SUM(template_IRP_newest_CP_7reg!N870:N873)/(SUM(template_IRP_newest_CP_7reg!N935:N937)*1000000) -> 7.7574389 | K21: =SUM(template_IRP_newest_CP_7reg!O870:O873)/(SUM(template_IRP_newest_CP_7reg!O935:O937)*1000000) -> 8.1178383 | L21: =SUM(template_IRP_newest_CP_7reg!P870:P873)/(SUM(template_IRP_newest_CP_7reg!P935:P937)*1000000) -> 8.4555263 | M21: =SUM(template_IRP_newest_CP_7reg!Q870:Q873)/(SUM(template_IRP_newest_CP_7reg!Q935:Q937)*1000000) -> 8.7940294 | O21: =O9 -> Asia + Pacific | P21: =E36 -> 3.609521 | Q21: =M36 -> 8.2757714
B22: Africa | C22: Single-Family Houses | D22: m2/cap | E22: =template_IRP_newest_CP_7reg!I1107/(template_IRP_newest_CP_7reg!I1175*1000000) -> 10.604086 | F22: =template_IRP_newest_CP_7reg!J1107/(template_IRP_newest_CP_7reg!J1175*1000000) -> 10.534764 | G22: =template_IRP_newest_CP_7reg!K1107/(template_IRP_newest_CP_7reg!K1175*1000000) -> 10.987246 | H22: =template_IRP_newest_CP_7reg!L1107/(template_IRP_newest_CP_7reg!L1175*1000000) -> 11.602495 | I22: =template_IRP_newest_CP_7reg!M1107/(template_IRP_newest_CP_7reg!M1175*1000000) -> 12.282449 | J22: =template_IRP_newest_CP_7reg!N1107/(template_IRP_newest_CP_7reg!N1175*1000000) -> 13.092782 | K22: =template_IRP_newest_CP_7reg!O1107/(template_IRP_newest_CP_7reg!O1175*1000000) -> 14.087812 | L22: =template_IRP_newest_CP_7reg!P1107/(template_IRP_newest_CP_7reg!P1175*1000000) -> 15.440822 | M22: =template_IRP_newest_CP_7reg!Q1107/(template_IRP_newest_CP_7reg!Q1175*1000000) -> 16.950235 | O22: =O10 -> World | P22: =E41 -> 5.0014535 | Q22: =M41 -> 8.0725424
C23: Multi-Family Houses | D23: m2/cap | E23: =template_IRP_newest_CP_7reg!I1108/(template_IRP_newest_CP_7reg!I1176*1000000) -> 10.032692 | F23: =template_IRP_newest_CP_7reg!J1108/(template_IRP_newest_CP_7reg!J1176*1000000) -> 10.000749 | G23: =template_IRP_newest_CP_7reg!K1108/(template_IRP_newest_CP_7reg!K1176*1000000) -> 10.46063 | H23: =template_IRP_newest_CP_7reg!L1108/(template_IRP_newest_CP_7reg!L1176*1000000) -> 11.04504 | I23: =template_IRP_newest_CP_7reg!M1108/(template_IRP_newest_CP_7reg!M1176*1000000) -> 11.648399 | J23: =template_IRP_newest_CP_7reg!N1108/(template_IRP_newest_CP_7reg!N1176*1000000) -> 12.326664 | K23: =template_IRP_newest_CP_7reg!O1108/(template_IRP_newest_CP_7reg!O1176*1000000) -> 13.130999 | L23: =template_IRP_newest_CP_7reg!P1108/(template_IRP_newest_CP_7reg!P1176*1000000) -> 14.242687 | M23: =template_IRP_newest_CP_7reg!Q1108/(template_IRP_newest_CP_7reg!Q1176*1000000) -> 15.511929
C24: Residential Towers | D24: m2/cap | E24: =template_IRP_newest_CP_7reg!I1109/(template_IRP_newest_CP_7reg!I1177*1000000) -> 9.6252613 | F24: =template_IRP_newest_CP_7reg!J1109/(template_IRP_newest_CP_7reg!J1177*1000000) -> 9.5672575 | G24: =template_IRP_newest_CP_7reg!K1109/(template_IRP_newest_CP_7reg!K1177*1000000) -> 10.036239 | H24: =template_IRP_newest_CP_7reg!L1109/(template_IRP_newest_CP_7reg!L1177*1000000) -> 10.655092 | I24: =template_IRP_newest_CP_7reg!M1109/(template_IRP_newest_CP_7reg!M1177*1000000) -> 11.313668 | J24: =template_IRP_newest_CP_7reg!N1109/(template_IRP_newest_CP_7reg!N1177*1000000) -> 12.065433 | K24: =template_IRP_newest_CP_7reg!O1109/(template_IRP_newest_CP_7reg!O1177*1000000) -> 12.961257 | L24: =template_IRP_newest_CP_7reg!P1109/(template_IRP_newest_CP_7reg!P1177*1000000) -> 14.167327 | M24: =template_IRP_newest_CP_7reg!Q1109/(template_IRP_newest_CP_7reg!Q1177*1000000) -> 15.513389
C25: Residential Total | D25: m2/cap | E25: =SUM(template_IRP_newest_CP_7reg!I1107:I1109)/(SUM(template_IRP_newest_CP_7reg!I1175:I1177)*1000000) -> 10.34158 | F25: =SUM(template_IRP_newest_CP_7reg!J1107:J1109)/(SUM(template_IRP_newest_CP_7reg!J1175:J1177)*1000000) -> 10.274235 | G25: =SUM(template_IRP_newest_CP_7reg!K1107:K1109)/(SUM(template_IRP_newest_CP_7reg!K1175:K1177)*1000000) -> 10.720666 | H25: =SUM(template_IRP_newest_CP_7reg!L1107:L1109)/(SUM(template_IRP_newest_CP_7reg!L1175:L1177)*1000000) -> 11.316703 | I25: =SUM(template_IRP_newest_CP_7reg!M1107:M1109)/(SUM(template_IRP_newest_CP_7reg!M1175:M1177)*1000000) -> 11.959402 | J25: =SUM(template_IRP_newest_CP_7reg!N1107:N1109)/(SUM(template_IRP_newest_CP_7reg!N1175:N1177)*1000000) -> 12.707902 | K25: =SUM(template_IRP_newest_CP_7reg!O1107:O1109)/(SUM(template_IRP_newest_CP_7reg!O1175:O1177)*1000000) -> 13.612462 | L25: =SUM(template_IRP_newest_CP_7reg!P1107:P1109)/(SUM(template_IRP_newest_CP_7reg!P1175:P1177)*1000000) -> 14.846111 | M25: =SUM(template_IRP_newest_CP_7reg!Q1107:Q1109)/(SUM(template_IRP_newest_CP_7reg!Q1175:Q1177)*1000000) -> 16.231561
C26: Commercial | D26: m2/cap | E26: =SUM(template_IRP_newest_CP_7reg!I1110:I1113)/(SUM(template_IRP_newest_CP_7reg!I1175:I1178)*1000000) -> 1.6870683 | F26: =SUM(template_IRP_newest_CP_7reg!J1110:J1113)/(SUM(template_IRP_newest_CP_7reg!J1175:J1178)*1000000) -> 1.7187419 | G26: =SUM(template_IRP_newest_CP_7reg!K1110:K1113)/(SUM(template_IRP_newest_CP_7reg!K1175:K1178)*1000000) -> 1.8665657 | H26: =SUM(template_IRP_newest_CP_7reg!L1110:L1113)/(SUM(template_IRP_newest_CP_7reg!L1175:L1178)*1000000) -> 2.0757228 | I26: =SUM(template_IRP_newest_CP_7reg!M1110:M1113)/(SUM(template_IRP_newest_CP_7reg!M1175:M1178)*1000000) -> 2.3469 | J26: =SUM(template_IRP_newest_CP_7reg!N1110:N1113)/(SUM(template_IRP_newest_CP_7reg!N1175:N1178)*1000000) -> 2.6781836 | K26: =SUM(template_IRP_newest_CP_7reg!O1110:O1113)/(SUM(template_IRP_newest_CP_7reg!O1175:O1178)*1000000) -> 3.1069058 | L26: =SUM(template_IRP_newest_CP_7reg!P1110:P1113)/(SUM(template_IRP_newest_CP_7reg!P1175:P1178)*1000000) -> 3.6317636 | M26: =SUM(template_IRP_newest_CP_7reg!Q1110:Q1113)/(SUM(template_IRP_newest_CP_7reg!Q1175:Q1178)*1000000) -> 4.1804172
B27: West Asia | C27: Single-Family Houses | D27: m2/cap | E27: =template_IRP_newest_CP_7reg!I1347/(template_IRP_newest_CP_7reg!I1415*1000000) -> 24.552249 | F27: =template_IRP_newest_CP_7reg!J1347/(template_IRP_newest_CP_7reg!J1415*1000000) -> 24.190982 | G27: =template_IRP_newest_CP_7reg!K1347/(template_IRP_newest_CP_7reg!K1415*1000000) -> 25.137293 | H27: =template_IRP_newest_CP_7reg!L1347/(template_IRP_newest_CP_7reg!L1415*1000000) -> 26.554127 | I27: =template_IRP_newest_CP_7reg!M1347/(template_IRP_newest_CP_7reg!M1415*1000000) -> 27.842275 | J27: =template_IRP_newest_CP_7reg!N1347/(template_IRP_newest_CP_7reg!N1415*1000000) -> 29.070087 | K27: =template_IRP_newest_CP_7reg!O1347/(template_IRP_newest_CP_7reg!O1415*1000000) -> 30.313281 | L27: =template_IRP_newest_CP_7reg!P1347/(template_IRP_newest_CP_7reg!P1415*1000000) -> 31.654183 | M27: =template_IRP_newest_CP_7reg!Q1347/(template_IRP_newest_CP_7reg!Q1415*1000000) -> 32.911
C28: Multi-Family Houses | D28: m2/cap | E28: =template_IRP_newest_CP_7reg!I1348/(template_IRP_newest_CP_7reg!I1416*1000000) -> 18.324145 | F28: =template_IRP_newest_CP_7reg!J1348/(template_IRP_newest_CP_7reg!J1416*1000000) -> 18.039366 | G28: =template_IRP_newest_CP_7reg!K1348/(template_IRP_newest_CP_7reg!K1416*1000000) -> 18.670871 | H28: =template_IRP_newest_CP_7reg!L1348/(template_IRP_newest_CP_7reg!L1416*1000000) -> 19.59762 | I28: =template_IRP_newest_CP_7reg!M1348/(template_IRP_newest_CP_7reg!M1416*1000000) -> 20.401302 | J28: =template_IRP_newest_CP_7reg!N1348/(template_IRP_newest_CP_7reg!N1416*1000000) -> 21.140843 | K28: =template_IRP_newest_CP_7reg!O1348/(template_IRP_newest_CP_7reg!O1416*1000000) -> 21.879433 | L28: =template_IRP_newest_CP_7reg!P1348/(template_IRP_newest_CP_7reg!P1416*1000000) -> 22.695278 | M28: =template_IRP_newest_CP_7reg!Q1348/(template_IRP_newest_CP_7reg!Q1416*1000000) -> 23.480542
C29: Residential Towers | D29: m2/cap | E29: =template_IRP_newest_CP_7reg!I1349/(template_IRP_newest_CP_7reg!I1417*1000000) -> 16.52038 | F29: =template_IRP_newest_CP_7reg!J1349/(template_IRP_newest_CP_7reg!J1417*1000000) -> 16.294065 | G29: =template_IRP_newest_CP_7reg!K1349/(template_IRP_newest_CP_7reg!K1417*1000000) -> 16.962269 | H29: =template_IRP_newest_CP_7reg!L1349/(template_IRP_newest_CP_7reg!L1417*1000000) -> 17.95319 | I29: =template_IRP_newest_CP_7reg!M1349/(template_IRP_newest_CP_7reg!M1417*1000000) -> 18.867738 | J29: =template_IRP_newest_CP_7reg!N1349/(template_IRP_newest_CP_7reg!N1417*1000000) -> 19.751276 | K29: =template_IRP_newest_CP_7reg!O1349/(template_IRP_newest_CP_7reg!O1417*1000000) -> 20.656325 | L29: =template_IRP_newest_CP_7reg!P1349/(template_IRP_newest_CP_7reg!P1417*1000000) -> 21.631663 | M29: =template_IRP_newest_CP_7reg!Q1349/(template_IRP_newest_CP_7reg!Q1417*1000000) -> 22.538043
C30: Residential Total | D30: m2/cap | E30: =SUM(template_IRP_newest_CP_7reg!I1347:I1349)/(SUM(template_IRP_newest_CP_7reg!I1415:I1417)*1000000) -> 21.227544 | F30: =SUM(template_IRP_newest_CP_7reg!J1347:J1349)/(SUM(template_IRP_newest_CP_7reg!J1415:J1417)*1000000) -> 20.843752 | G30: =SUM(template_IRP_newest_CP_7reg!K1347:K1349)/(SUM(template_IRP_newest_CP_7reg!K1415:K1417)*1000000) -> 21.535747 | H30: =SUM(template_IRP_newest_CP_7reg!L1347:L1349)/(SUM(template_IRP_newest_CP_7reg!L1415:L1417)*1000000) -> 22.576491 | I30: =SUM(template_IRP_newest_CP_7reg!M1347:M1349)/(SUM(template_IRP_newest_CP_7reg!M1415:M1417)*1000000) -> 23.471212 | J30: =SUM(template_IRP_newest_CP_7reg!N1347:N1349)/(SUM(template_IRP_newest_CP_7reg!N1415:N1417)*1000000) -> 24.284746 | K30: =SUM(template_IRP_newest_CP_7reg!O1347:O1349)/(SUM(template_IRP_newest_CP_7reg!O1415:O1417)*1000000) -> 25.08608 | L30: =SUM(template_IRP_newest_CP_7reg!P1347:P1349)/(SUM(template_IRP_newest_CP_7reg!P1415:P1417)*1000000) -> 25.964372 | M30: =SUM(template_IRP_newest_CP_7reg!Q1347:Q1349)/(SUM(template_IRP_newest_CP_7reg!Q1415:Q1417)*1000000) -> 26.807831
C31: Commercial | D31: m2/cap | E31: =SUM(template_IRP_newest_CP_7reg!I1350:I1353)/(SUM(template_IRP_newest_CP_7reg!I1415:I1418)*1000000) -> 3.6611502 | F31: =SUM(template_IRP_newest_CP_7reg!J1350:J1353)/(SUM(template_IRP_newest_CP_7reg!J1415:J1418)*1000000) -> 3.822678 | G31: =SUM(template_IRP_newest_CP_7reg!K1350:K1353)/(SUM(template_IRP_newest_CP_7reg!K1415:K1418)*1000000) -> 4.2149322 | H31: =SUM(template_IRP_newest_CP_7reg!L1350:L1353)/(SUM(template_IRP_newest_CP_7reg!L1415:L1418)*1000000) -> 4.695199 | I31: =SUM(template_IRP_newest_CP_7reg!M1350:M1353)/(SUM(template_IRP_newest_CP_7reg!M1415:M1418)*1000000) -> 5.1153845 | J31: =SUM(template_IRP_newest_CP_7reg!N1350:N1353)/(SUM(template_IRP_newest_CP_7reg!N1415:N1418)*1000000) -> 5.4969503 | K31: =SUM(template_IRP_newest_CP_7reg!O1350:O1353)/(SUM(template_IRP_newest_CP_7reg!O1415:O1418)*1000000) -> 5.8194972 | L31: =SUM(template_IRP_newest_CP_7reg!P1350:P1353)/(SUM(template_IRP_newest_CP_7reg!P1415:P1418)*1000000) -> 6.2037671 | M31: =SUM(template_IRP_newest_CP_7reg!Q1350:Q1353)/(SUM(template_IRP_newest_CP_7reg!Q1415:Q1418)*1000000) -> 6.5363523
B32: Asia + Pacific | C32: Single-Family Houses | D32: m2/cap | E32: =template_IRP_newest_CP_7reg!I1587/(template_IRP_newest_CP_7reg!I1655*1000000) -> 16.876056 | F32: =template_IRP_newest_CP_7reg!J1587/(template_IRP_newest_CP_7reg!J1655*1000000) -> 17.307698 | G32: =template_IRP_newest_CP_7reg!K1587/(template_IRP_newest_CP_7reg!K1655*1000000) -> 18.197003 | H32: =template_IRP_newest_CP_7reg!L1587/(template_IRP_newest_CP_7reg!L1655*1000000) -> 19.21724 | I32: =template_IRP_newest_CP_7reg!M1587/(template_IRP_newest_CP_7reg!M1655*1000000) -> 20.301024 | J32: =template_IRP_newest_CP_7reg!N1587/(template_IRP_newest_CP_7reg!N1655*1000000) -> 21.450176 | K32: =template_IRP_newest_CP_7reg!O1587/(template_IRP_newest_CP_7reg!O1655*1000000) -> 22.662291 | L32: =template_IRP_newest_CP_7reg!P1587/(template_IRP_newest_CP_7reg!P1655*1000000) -> 23.867211 | M32: =template_IRP_newest_CP_7reg!Q1587/(template_IRP_newest_CP_7reg!Q1655*1000000) -> 24.961721
C33: Multi-Family Houses | D33: m2/cap | E33: =template_IRP_newest_CP_7reg!I1588/(template_IRP_newest_CP_7reg!I1656*1000000) -> 17.690214 | F33: =template_IRP_newest_CP_7reg!J1588/(template_IRP_newest_CP_7reg!J1656*1000000) -> 18.257509 | G33: =template_IRP_newest_CP_7reg!K1588/(template_IRP_newest_CP_7reg!K1656*1000000) -> 19.160423 | H33: =template_IRP_newest_CP_7reg!L1588/(template_IRP_newest_CP_7reg!L1656*1000000) -> 20.148018 | I33: =template_IRP_newest_CP_7reg!M1588/(template_IRP_newest_CP_7reg!M1656*1000000) -> 21.132987 | J33: =template_IRP_newest_CP_7reg!N1588/(template_IRP_newest_CP_7reg!N1656*1000000) -> 22.100422 | K33: =template_IRP_newest_CP_7reg!O1588/(template_IRP_newest_CP_7reg!O1656*1000000) -> 23.056532 | L33: =template_IRP_newest_CP_7reg!P1588/(template_IRP_newest_CP_7reg!P1656*1000000) -> 23.975547 | M33: =template_IRP_newest_CP_7reg!Q1588/(template_IRP_newest_CP_7reg!Q1656*1000000) -> 24.7975
C34: Residential Towers | D34: m2/cap | E34: =template_IRP_newest_CP_7reg!I1589/(template_IRP_newest_CP_7reg!I1657*1000000) -> 15.186364 | F34: =template_IRP_newest_CP_7reg!J1589/(template_IRP_newest_CP_7reg!J1657*1000000) -> 15.709207 | G34: =template_IRP_newest_CP_7reg!K1589/(template_IRP_newest_CP_7reg!K1657*1000000) -> 16.651031 | H34: =template_IRP_newest_CP_7reg!L1589/(template_IRP_newest_CP_7reg!L1657*1000000) -> 17.762081 | I34: =template_IRP_newest_CP_7reg!M1589/(template_IRP_newest_CP_7reg!M1657*1000000) -> 18.964903 | J34: =template_IRP_newest_CP_7reg!N1589/(template_IRP_newest_CP_7reg!N1657*1000000) -> 20.239377 | K34: =template_IRP_newest_CP_7reg!O1589/(template_IRP_newest_CP_7reg!O1657*1000000) -> 21.568931 | L34: =template_IRP_newest_CP_7reg!P1589/(template_IRP_newest_CP_7reg!P1657*1000000) -> 22.813557 | M34: =template_IRP_newest_CP_7reg!Q1589/(template_IRP_newest_CP_7reg!Q1657*1000000) -> 23.893011
C35: Residential Total | D35: m2/cap | E35: =SUM(template_IRP_newest_CP_7reg!I1587:I1589)/(SUM(template_IRP_newest_CP_7reg!I1655:I1657)*1000000) -> 16.874322 | F35: =SUM(template_IRP_newest_CP_7reg!J1587:J1589)/(SUM(template_IRP_newest_CP_7reg!J1655:J1657)*1000000) -> 17.347909 | G35: =SUM(template_IRP_newest_CP_7reg!K1587:K1589)/(SUM(template_IRP_newest_CP_7reg!K1655:K1657)*1000000) -> 18.243613 | H35: =SUM(template_IRP_newest_CP_7reg!L1587:L1589)/(SUM(template_IRP_newest_CP_7reg!L1655:L1657)*1000000) -> 19.263305 | I35: =SUM(template_IRP_newest_CP_7reg!M1587:M1589)/(SUM(template_IRP_newest_CP_7reg!M1655:M1657)*1000000) -> 20.332595 | J35: =SUM(template_IRP_newest_CP_7reg!N1587:N1589)/(SUM(template_IRP_newest_CP_7reg!N1655:N1657)*1000000) -> 21.444014 | K35: =SUM(template_IRP_newest_CP_7reg!O1587:O1589)/(SUM(template_IRP_newest_CP_7reg!O1655:O1657)*1000000) -> 22.593279 | L35: =SUM(template_IRP_newest_CP_7reg!P1587:P1589)/(SUM(template_IRP_newest_CP_7reg!P1655:P1657)*1000000) -> 23.709542 | M35: =SUM(template_IRP_newest_CP_7reg!Q1587:Q1589)/(SUM(template_IRP_newest_CP_7reg!Q1655:Q1657)*1000000) -> 24.706867
C36: Commercial | D36: m2/cap | E36: =SUM(template_IRP_newest_CP_7reg!I1590:I1593)/(SUM(template_IRP_newest_CP_7reg!I1655:I1658)*1000000) -> 3.609521 | F36: =SUM(template_IRP_newest_CP_7reg!J1590:J1593)/(SUM(template_IRP_newest_CP_7reg!J1655:J1658)*1000000) -> 4.3493962 | G36: =SUM(template_IRP_newest_CP_7reg!K1590:K1593)/(SUM(template_IRP_newest_CP_7reg!K1655:K1658)*1000000) -> 5.1448666 | H36: =SUM(template_IRP_newest_CP_7reg!L1590:L1593)/(SUM(template_IRP_newest_CP_7reg!L1655:L1658)*1000000) -> 5.839024 | I36: =SUM(template_IRP_newest_CP_7reg!M1590:M1593)/(SUM(template_IRP_newest_CP_7reg!M1655:M1658)*1000000) -> 6.4560373 | J36: =SUM(template_IRP_newest_CP_7reg!N1590:N1593)/(SUM(template_IRP_newest_CP_7reg!N1655:N1658)*1000000) -> 6.9919066 | K36: =SUM(template_IRP_newest_CP_7reg!O1590:O1593)/(SUM(template_IRP_newest_CP_7reg!O1655:O1658)*1000000) -> 7.4558886 | L36: =SUM(template_IRP_newest_CP_7reg!P1590:P1593)/(SUM(template_IRP_newest_CP_7reg!P1655:P1658)*1000000) -> 7.8962602 | M36: =SUM(template_IRP_newest_CP_7reg!Q1590:Q1593)/(SUM(template_IRP_newest_CP_7reg!Q1655:Q1658)*1000000) -> 8.2757714
B37: World | C37: Single-Family Houses | D37: m2/cap | E37: =template_IRP_newest_CP_7reg!I1827/(template_IRP_newest_CP_7reg!I1895*1000000) -> 20.000948 | F37: =template_IRP_newest_CP_7reg!J1827/(template_IRP_newest_CP_7reg!J1895*1000000) -> 19.836683 | G37: =template_IRP_newest_CP_7reg!K1827/(template_IRP_newest_CP_7reg!K1895*1000000) -> 20.175831 | H37: =template_IRP_newest_CP_7reg!L1827/(template_IRP_newest_CP_7reg!L1895*1000000) -> 20.639823 | I37: =template_IRP_newest_CP_7reg!M1827/(template_IRP_newest_CP_7reg!M1895*1000000) -> 21.144682 | J37: =template_IRP_newest_CP_7reg!N1827/(template_IRP_newest_CP_7reg!N1895*1000000) -> 21.709355 | K37: =template_IRP_newest_CP_7reg!O1827/(template_IRP_newest_CP_7reg!O1895*1000000) -> 22.376995 | L37: =template_IRP_newest_CP_7reg!P1827/(template_IRP_newest_CP_7reg!P1895*1000000) -> 23.365447 | M37: =template_IRP_newest_CP_7reg!Q1827/(template_IRP_newest_CP_7reg!Q1895*1000000) -> 24.371135
C38: Multi-Family Houses | D38: m2/cap | E38: =template_IRP_newest_CP_7reg!I1828/(template_IRP_newest_CP_7reg!I1896*1000000) -> 20.318005 | F38: =template_IRP_newest_CP_7reg!J1828/(template_IRP_newest_CP_7reg!J1896*1000000) -> 20.142036 | G38: =template_IRP_newest_CP_7reg!K1828/(template_IRP_newest_CP_7reg!K1896*1000000) -> 20.404169 | H38: =template_IRP_newest_CP_7reg!L1828/(template_IRP_newest_CP_7reg!L1896*1000000) -> 20.752969 | I38: =template_IRP_newest_CP_7reg!M1828/(template_IRP_newest_CP_7reg!M1896*1000000) -> 21.109454 | J38: =template_IRP_newest_CP_7reg!N1828/(template_IRP_newest_CP_7reg!N1896*1000000) -> 21.489648 | K38: =template_IRP_newest_CP_7reg!O1828/(template_IRP_newest_CP_7reg!O1896*1000000) -> 21.936694 | L38: =template_IRP_newest_CP_7reg!P1828/(template_IRP_newest_CP_7reg!P1896*1000000) -> 22.623694 | M38: =template_IRP_newest_CP_7reg!Q1828/(template_IRP_newest_CP_7reg!Q1896*1000000) -> 23.338487
C39: Residential Towers | D39: m2/cap | E39: =template_IRP_newest_CP_7reg!I1829/(template_IRP_newest_CP_7reg!I1897*1000000) -> 19.111898 | F39: =template_IRP_newest_CP_7reg!J1829/(template_IRP_newest_CP_7reg!J1897*1000000) -> 18.825021 | G39: =template_IRP_newest_CP_7reg!K1829/(template_IRP_newest_CP_7reg!K1897*1000000) -> 19.000417 | H39: =template_IRP_newest_CP_7reg!L1829/(template_IRP_newest_CP_7reg!L1897*1000000) -> 19.32471 | I39: =template_IRP_newest_CP_7reg!M1829/(template_IRP_newest_CP_7reg!M1897*1000000) -> 19.73102 | J39: =template_IRP_newest_CP_7reg!N1829/(template_IRP_newest_CP_7reg!N1897*1000000) -> 20.230133 | K39: =template_IRP_newest_CP_7reg!O1829/(template_IRP_newest_CP_7reg!O1897*1000000) -> 20.853619 | L39: =template_IRP_newest_CP_7reg!P1829/(template_IRP_newest_CP_7reg!P1897*1000000) -> 21.722662 | M39: =template_IRP_newest_CP_7reg!Q1829/(template_IRP_newest_CP_7reg!Q1897*1000000) -> 22.582979
C40: Residential Total | D40: m2/cap | E40: =SUM(template_IRP_newest_CP_7reg!I1827:I1829)/(SUM(template_IRP_newest_CP_7reg!I1895:I1897)*1000000) -> 19.959525 | F40: =SUM(template_IRP_newest_CP_7reg!J1827:J1829)/(SUM(template_IRP_newest_CP_7reg!J1895:J1897)*1000000) -> 19.770981 | G40: =SUM(template_IRP_newest_CP_7reg!K1827:K1829)/(SUM(template_IRP_newest_CP_7reg!K1895:K1897)*1000000) -> 20.058662 | H40: =SUM(template_IRP_newest_CP_7reg!L1827:L1829)/(SUM(template_IRP_newest_CP_7reg!L1895:L1897)*1000000) -> 20.459902 | I40: =SUM(template_IRP_newest_CP_7reg!M1827:M1829)/(SUM(template_IRP_newest_CP_7reg!M1895:M1897)*1000000) -> 20.894531 | J40: =SUM(template_IRP_newest_CP_7reg!N1827:N1829)/(SUM(template_IRP_newest_CP_7reg!N1895:N1897)*1000000) -> 21.379247 | K40: =SUM(template_IRP_newest_CP_7reg!O1827:O1829)/(SUM(template_IRP_newest_CP_7reg!O1895:O1897)*1000000) -> 21.954877 | L40: =SUM(template_IRP_newest_CP_7reg!P1827:P1829)/(SUM(template_IRP_newest_CP_7reg!P1895:P1897)*1000000) -> 22.805998 | M40: =SUM(template_IRP_newest_CP_7reg!Q1827:Q1829)/(SUM(template_IRP_newest_CP_7reg!Q1895:Q1897)*1000000) -> 23.669749
...
