Workbook

Sheet Sheet2
A1: Cntry_ISO | B1: Cntry_name | C1: eFUA_name | D1: IMAGE-region | E1: GRIP-region | F1: R10 | G1: FUA_area | H1: FUA_urban | I1: FUA_total_area | J1: FUA_p_2015 | K1: 1870 | L1: 1880 | M1: 1890 | N1: 1900 | O1: 1910 | P1: 1920 | Q1: 1930 | R1: 1940 | S1: 1950 | T1: 1960 | U1: 1970 | V1: 1980 | W1: 1990 | X1: 1992 | Y1: 1993 | Z1: 1994 | AA1: 1995 | AB1: 1996 | AC1: 1997 | AD1: 1998 | AE1: 1999 | AF1: 2000 | AG1: 2001 | AH1: 2002 | AI1: 2003 | AJ1: 2004 | AK1: 2005 | AL1: 2006 | AM1: 2007 | AN1: 2008 | AO1: 2009 | AP1: 2010 | AQ1: 2011 | AR1: 2012 | AS1: 2013 | AT1: 2020 | AU1: 2024 | AV1: 2030 | AW1: 2040 | AX1: 2050 | AY1: 2060
A2: AFG | B2: Afghanistan | C2: 161_Afghanistan_country | D2: Rest of South Asia | E2: South and East Asia | F2: Southern Asia | G2: 643838.73 | H2: 1917.352 | I2: 645756.08 | K2: 131.84812 | L2: 142.60477 | M2: 153.64254 | N2: 170.19085 | O2: 188.72652 | P2: 196.10551 | Q2: 206.15466 | R2: 217.69632 | S2: 254.86721 | T2: 291.83836 | U2: 357.18789 | V2: 466.79345 | W2: 578.13683 | X2: 609.68643 | Y2: 705.36716 | Z2: 849.2652 | AA2: 893.55539 | AB2: 920.79412 | AC2: 935.11603 | AD2: 962.27858 | AE2: 980.45841 | AF2: 997.88307 | AG2: 1016.8153 | AH2: 1037.3453 | AI2: 1059.3365 | AJ2: 1090.3345 | AK2: 1112.2849 | AL2: 1134.9743 | AM2: 1181.275 | AN2: 1224.1342 | AO2: 1263.823 | AP2: 1359.6194 | AQ2: 1474.6454 | AR2: 1607.5437 | AS2: 1719.2458 | AT2: 1829.6659 | AU2: 1836.4786 | AV2: 1844.784 | AW2: 1850.0082 | AX2: 1838.642 | AY2: 1763.1448
A3: AGO | B3: Angola | C3: 69_Angola_country | D3: Rest of Southern Africa | E3: Africa | F3: Africa | G3: 1246918.1 | H3: 4318.8619 | I3: 1251237 | K3: 223.89716 | L3: 227.92512 | M3: 232.71952 | N3: 240.68294 | O3: 250.87418 | P3: 256.34157 | Q3: 264.92889 | R3: 276.55397 | S3: 319.15491 | T3: 384.12412 | U3: 530.99074 | V3: 719.44761 | W3: 961.08695 | X3: 1041.5217 | Y3: 1202.941 | Z3: 1377.615 | AA3: 1506.2453 | AB3: 1539.6032 | AC3: 1609.1059 | AD3: 1679.2419 | AE3: 1730.1105 | AF3: 1795.786 | AG3: 1852.4407 | AH3: 1896.1395 | AI3: 1944.0698 | AJ3: 2013.8577 | AK3: 2091.5766 | AL3: 2192.3047 | AM3: 2365.6697 | AN3: 2501.9219 | AO3: 2650.6899 | AP3: 2892.5219 | AQ3: 3250.2917 | AR3: 3649.9015 | AS3: 3979.0356 | AT3: 4342.7228 | AU3: 4366.6678 | AV3: 4396.7451 | AW3: 4417.1823 | AX3: 4344.2633 | AY3: 4054.3708
A4: ALB | B4: Albania | C4: 114_Albania_country | D4: Central Europe | E4: Europe | F4: Europe | G4: 28727.645 | H4: 806.29565 | I4: 29533.941 | K4: 84.742947 | L4: 94.047032 | M4: 104.25818 | N4: 117.80812 | O4: 138.17356 | P4: 146.13257 | Q4: 157.69914 | R4: 167.63982 | S4: 183.88669 | T4: 205.54909 | U4: 241.24807 | V4: 273.01877 | W4: 295.90385 | X4: 307.26851 | Y4: 344.02769 | Z4: 383.31811 | AA4: 405.78601 | AB4: 415.85854 | AC4: 428.46531 | AD4: 446.39113 | AE4: 457.75633 | AF4: 467.24033 | AG4: 477.51048 | AH4: 488.38357 | AI4: 495.45142 | AJ4: 504.11159 | AK4: 512.5596 | AL4: 526.40242 | AM4: 545.27543 | AN4: 561.77977 | AO4: 591.50392 | AP4: 626.56054 | AQ4: 680.02281 | AR4: 736.50365 | AS4: 782.49125 | AT4: 798.78865 | AU4: 796.86467 | AV4: 794.06547 | AW4: 786.90087 | AX4: 776.78775 | AY4: 763.98581
A5: ARE | B5: United Arab Emirates | C5: 194_United Arab Emirates_country | D5: Middle East | E5: Middle East and Central Asia | F5: Middle East | G5: 71093.261 | H5: 3889.0822 | I5: 74982.343 | K5: 59.161203 | L5: 65.118563 | M5: 71.164999 | N5: 78.469826 | O5: 89.124312 | P5: 97.960277 | Q5: 109.00476 | R5: 129.67434 | S5: 149.8278 | T5: 241.44334 | U5: 394.65557 | V5: 610.01621 | W5: 941.33471 | X5: 1179.3985 | Y5: 1292.8781 | Z5: 1428.2745 | AA5: 1606.3905 | AB5: 1667.4416 | AC5: 1731.5042 | AD5: 1798.7089 | AE5: 1853.8346 | AF5: 1895.0468 | AG5: 1932.0405 | AH5: 1974.1097 | AI5: 2021.4624 | AJ5: 2081.7225 | AK5: 2134.3282 | AL5: 2196.6106 | AM5: 2314.7907 | AN5: 2390.4311 | AO5: 2521.4308 | AP5: 2715.415 | AQ5: 2951.6334 | AR5: 3188.0742 | AS5: 3410.4026 | AT5: 3607.7675 | AU5: 3596.1779 | AV5: 3583.3762 | AW5: 3496.4193 | AX5: 3382.0555 | AY5: 3296.5251
A6: ARG | B6: Argentina | C6: 45_Argentina_country | D6: Rest of South America | E6: Central and South America | F6: Latin America and Caribbean | G6: 2779049.5 | H6: 18828.018 | I6: 2797877.5 | J6: 44908441 | K6: 374.52099 | L6: 586.38506 | M6: 811.91777 | N6: 1161.8352 | O6: 1707.2143 | P6: 2243.0254 | Q6: 2829.4104 | R6: 3388.4582 | S6: 3977.577 | T6: 4614.536 | U6: 4794.9622 | V6: 4915.2463 | W6: 4982.2227 | X6: 5072.4358 | Y6: 7293.5913 | Z6: 8449.959 | AA6: 9010.3737 | AB6: 9312.4508 | AC6: 9546.1847 | AD6: 9938.4749 | AE6: 10438.748 | AF6: 10709.387 | AG6: 10896.647 | AH6: 11022.399 | AI6: 11134.482 | AJ6: 11287.571 | AK6: 11491.234 | AL6: 11847.985 | AM6: 12243.009 | AN6: 12695.442 | AO6: 13340.602 | AP6: 14341.147 | AQ6: 15524.852 | AR6: 16630.646 | AS6: 17811.617 | AT6: 18351.102 | AU6: 18249.595 | AV6: 18105.192 | AW6: 17756.357 | AX6: 17289.666 | AY6: 16733.315
A7: ARM | B7: Armenia | C7: 158_Armenia_country | D7: Russia region | E7: Europe | F7: Eurasia | G7: 29690.165 | H7: 779.13352 | I7: 30469.298 | J7: 2812494 | K7: 7.3089448 | L7: 7.3089448 | M7: 7.3089448 | N7: 7.3089448 | O7: 7.3089448 | P7: 7.3089448 | Q7: 7.3089448 | R7: 9.136181 | S7: 9.136181 | T7: 12.790653 | U7: 20.099598 | V7: 27.408543 | W7: 32.890252 | X7: 32.890252 | Y7: 32.890252 | Z7: 56.644322 | AA7: 89.534574 | AB7: 124.25206 | AC7: 186.37809 | AD7: 199.16875 | AE7: 208.30493 | AF7: 219.26834 | AG7: 222.92282 | AH7: 226.57729 | AI7: 239.36794 | AJ7: 253.98583 | AK7: 303.32121 | AL7: 339.86593 | AM7: 385.54684 | AN7: 403.8192 | AO7: 416.60986 | AP7: 427.57327 | AQ7: 462.29076 | AR7: 575.57941 | AS7: 676.0774 | AT7: 730.89448 | AU7: 723.20086 | AV7: 717.01674 | AW7: 699.28823 | AX7: 681.46201 | AY7: 662.37312
A8: AUS | B8: Australia | C8: 55_Australia_country | D8: Oceania | E8: Oceania | F8: Asia-Pacific Developed | G8: 7688058.2 | H8: 33097.674 | I8: 7721155.9 | J8: 25544183 | K8: 788.12958 | L8: 1073.8658 | M8: 1598.2389 | N8: 2125.7519 | O8: 2901.3216 | P8: 3535.5933 | Q8: 4232.664 | R8: 4832.3961 | S8: 5711.5845 | T8: 7520.2006 | U8: 9972.5081 | V8: 11862.763 | W8: 14095.274 | X8: 14663.606 | Y8: 16833.317 | Z8: 18283.978 | AA8: 18805.211 | AB8: 19106.647 | AC8: 19467.743 | AD8: 19850.818 | AE8: 20243.312 | AF8: 20720.586 | AG8: 21084.821 | AH8: 21433.357 | AI8: 21932.61 | AJ8: 22315.685 | AK8: 22648.521 | AL8: 22927.977 | AM8: 23829.145 | AN8: 24381.778 | AO8: 24755.433 | AP8: 25515.303 | AQ8: 26969.103 | AR8: 28579.902 | AS8: 29628.648 | AT8: 31650.091 | AU8: 31508.541 | AV8: 31328.589 | AW8: 30963.347 | AX8: 30495.55 | AY8: 29969.634
A9: AUT | B9: Austria | C9: 115_Austria_country | D9: Western Europe | E9: Europe | F9: Europe | G9: 83946.896 | H9: 6142.9455 | I9: 90089.841 | J9: 8901100 | K9: 631.31838 | L9: 901.26141 | M9: 1055.8256 | N9: 1197.328 | O9: 1334.4764 | P9: 1334.4764 | Q9: 1399.7852 | R9: 1452.0323 | S9: 1543.4646 | T9: 1602.2425 | U9: 1728.5062 | V9: 1795.9919 | W9: 1872.1855 | X9: 1898.309 | Y9: 2192.1986 | Z9: 2499.15 | AA9: 2660.245 | AB9: 2747.3234 | AC9: 2808.2783 | AD9: 2934.542 | AE9: 3012.9125 | AF9: 3045.5669 | AG9: 3078.2213 | AH9: 3121.7605 | AI9: 3154.4149 | AJ9: 3226.2546 | AK9: 3261.086 | AL9: 3348.1644 | AM9: 3476.605 | AN9: 3591.9839 | AO9: 3853.2191 | AP9: 4277.7262 | AQ9: 4832.851 | AR9: 5488.116 | AS9: 5897.3844 | AT9: 6041.6417 | AU9: 6038.0046 | AV9: 6030.9895 | AW9: 6017.9073 | AX9: 5996.4008 | AY9: 5974.2223
A10: AZE | B10: Azerbaijan | C10: 159_Azerbaijan_country | D10: Russia region | E10: Middle East and Central Asia | F10: Eurasia | G10: 86235.488 | H10: 2080.6983 | I10: 88316.186 | J10: 10273527 | K10: 50.086696 | L10: 58.165196 | M10: 69.475095 | N10: 88.863493 | O10: 114.71469 | P10: 124.40889 | Q10: 135.71879 | R10: 150.26009 | S10: 166.41709 | T10: 240.73928 | U10: 340.91267 | V10: 434.62327 | W10: 533.18096 | X10: 534.79666 | Y10: 559.03216 | Z10: 602.65606 | AA10: 618.81305 | AB10: 625.27585 | AC10: 641.43285 | AD10: 657.58985 | AE10: 668.89975 | AF10: 672.13115 | AG10: 691.51955 | AH10: 735.14345 | AI10: 877.32503 | AJ10: 885.40353 | AK10: 945.18443 | AL10: 969.41993 | AM10: 1064.7462 | AN10: 1111.6015 | AO10: 1156.8411 | AP10: 1197.2336 | AQ10: 1297.407 | AR10: 1436.3572 | AS10: 1736.8774 | AT10: 1927.5622 | AU10: 1910.6261 | AV10: 1889.8786 | AW10: 1833.1789 | AX10: 1764.9331 | AY10: 1692.2045
A11: BDI | B11: Burundi | C11: 73_Burundi_country | D11: Eastern Africa | E11: Africa | F11: Africa | G11: 26935.291 | H11: 377.46844 | I11: 27312.76 | J11: 12053895 | K11: 22.46836 | L11: 22.46836 | M11: 22.46836 | N11: 22.46836 | O11: 22.46836 | P11: 22.46836 | Q11: 22.46836 | R11: 22.46836 | S11: 22.46836 | T11: 22.46836 | U11: 22.46836 | V11: 29.957813 | W11: 37.447266 | X11: 37.447266 | Y11: 67.405079 | Z11: 67.405079 | AA11: 67.405079 | AB11: 67.405079 | AC11: 67.405079 | AD11: 67.405079 | AE11: 67.405079 | AF11: 67.405079 | AG11: 67.405079 | AH11: 67.405079 | AI11: 67.405079 | AJ11: 82.383985 | AK11: 97.362891 | AL11: 97.362891 | AM11: 97.362891 | AN11: 112.3418 | AO11: 112.3418 | AP11: 134.81016 | AQ11: 254.64141 | AR11: 366.98321 | AS11: 374.47266 | AT11: 374.47266 | AU11: 374.47266 | AV11: 374.47266 | AW11: 357.82943 | AX11: 345.10225 | AY11: 293.81701
A12: BEL | B12: Belgium | C12: 116_Belgium_country | D12: Western Europe | E12: Europe | F12: Europe | G12: 30707.466 | H12: 14803.846 | I12: 45511.312 | J12: 11541270 | K12: 2697.6111 | L12: 3181.5444 | M12: 3713.4478 | N12: 4335.6479 | O12: 5083.4166 | P12: 5138.4411 | Q12: 5598.3895 | R12: 5800.1459 | S12: 6034.3528 | T12: 6473.1378 | U12: 6940.1406 | V12: 7237.8372 | W12: 7431.1284 | X12: 7538.3556 | Y12: 8695.2808 | Z12: 9392.2577 | AA12: 9606.7122 | AB12: 9715.3503 | AC12: 9788.7163 | AD12: 9949.5571 | AE12: 10267.006 | AF12: 10319.209 | AG12: 10346.016 | AH12: 10358.714 | AI12: 10381.288 | AJ12: 10434.901 | AK12: 10480.05 | AL12: 10539.307 | AM12: 10746.707 | AN12: 10908.959 | AO12: 11178.437 | AP12: 11699.054 | AQ12: 12393.209 | AR12: 13574.119 | AS12: 14247.111 | AT12: 14508.563 | AU12: 14431.56 | AV12: 14322.461 | AW12: 14088.835 | AX12: 13784.456 | AY12: 13402.579
A13: BEN | B13: Benin | C13: 70_Benin_country | D13: Western Africa | E13: Africa | F13: Africa | G13: 115286.16 | H13: 1192.2221 | I13: 116478.38 | J13: 12466822 | K13: 63.755194 | L13: 63.755194 | M13: 63.755194 | N13: 63.755194 | O13: 63.755194 | P13: 63.755194 | Q13: 63.755194 | R13: 63.755194 | S13: 63.755194 | T13: 71.724593 | U13: 111.57159 | V13: 191.26558 | W13: 278.92897 | X13: 278.92897 | Y13: 286.89837 | Z13: 398.46996 | AA13: 430.34756 | AB13: 438.31696 | AC13: 438.31696 | AD13: 462.22516 | AE13: 462.22516 | AF13: 533.94975 | AG13: 541.91915 | AH13: 557.85795 | AI13: 557.85795 | AJ13: 573.79675 | AK13: 597.70495 | AL13: 613.64374 | AM13: 661.46014 | AN13: 725.21533 | AO13: 820.84813 | AP13: 868.66452 | AQ13: 924.45032 | AR13: 1028.0525 | AS13: 1036.0219 | AT13: 1140.4957 | AU13: 1139.915 | AV13: 1154.4397 | AW13: 1164.5516 | AX13: 1171.8658 | AY13: 1171.8913
A14: BFA | B14: Burkina Faso | C14: 72_Burkina Faso_country | D14: Western Africa | E14: Africa | F14: Africa | G14: 272946.96 | H14: 1446.1177 | I14: 274393.08 | J14: 21231890 | K14: 55.40681 | L14: 55.40681 | M14: 55.40681 | N14: 55.40681 | O14: 55.40681 | P14: 55.40681 | Q14: 55.40681 | R14: 55.40681 | S14: 60.947491 | T14: 66.488172 | U14: 72.028853 | V14: 99.732257 | W14: 155.13907 | X14: 160.67975 | Y14: 199.46451 | Z14: 249.33064 | AA14: 332.44086 | AB14: 382.30699 | AC14: 398.92903 | AD14: 432.17312 | AE14: 448.79516 | AF14: 465.4172 | AG14: 465.4172 | AH14: 465.4172 | AI14: 509.74265 | AJ14: 542.98674 | AK14: 603.93423 | AL14: 687.04444 | AM14: 714.74785 | AN14: 764.61397 | AO14: 792.31738 | AP14: 941.91577 | AQ14: 1069.3514 | AR14: 1141.3803 | AS14: 1279.8973 | AT14: 1379.6296 | AU14: 1385.5507 | AV14: 1385.0826 | AW14: 1389.0791 | AX14: 1391.9111 | AY14: 1376.1101
A15: BGD | B15: Bangladesh | C15: 162_Bangladesh_country | D15: Rest of South Asia | E15: South and East Asia | F15: Southern Asia | G15: 139384.37 | H15: 24194.401 | I15: 163578.77 | J15: 166426991 | K15: 887.65911 | L15: 978.70107 | M15: 1115.264 | N15: 1274.5874 | O15: 1456.6714 | P15: 1547.7133 | Q15: 1707.0368 | R15: 1843.5997 | S15: 1911.8812 | T15: 2276.049 | U15: 3300.2711 | V15: 6099.8113 | W15: 8057.2135 | X15: 8603.4653 | Y15: 9217.9985 | Z15: 10128.418 | AA15: 10538.107 | AB15: 10697.43 | AC15: 10742.951 | AD15: 10788.472 | AE15: 10833.993 | AF15: 11107.119 | AG15: 11585.089 | AH15: 12176.862 | AI15: 12541.03 | AJ15: 12768.635 | AK15: 12814.156 | AL15: 12973.479 | AM15: 13292.126 | AN15: 13610.773 | AO15: 14248.067 | AP15: 14771.558 | AQ15: 16706.2 | AR15: 19642.303 | AS15: 22646.688 | AT15: 23379.368 | AU15: 23299.047 | AV15: 23149.669 | AW15: 22697.068 | AX15: 21695.393 | AY15: 19057.568
A16: BGR | B16: Bulgaria | C16: 118_Bulgaria_country | D16: Central Europe | E16: Europe | F16: Europe | G16: 111587.67 | H16: 2710.5348 | I16: 114298.21 | J16: 7020239 | K16: 52.300002 | L16: 64.503336 | M16: 81.93667 | N16: 92.396671 | O16: 129.00667 | P16: 148.18334 | Q16: 184.79334 | R16: 240.58001 | S16: 277.19001 | T16: 364.35668 | U16: 571.81336 | V16: 725.2267 | W16: 791.47337 | X16: 796.70337 | Y16: 911.76338 | Z16: 1037.2834 | AA16: 1065.1767 | AB16: 1084.3534 | AC16: 1103.5301 | AD16: 1155.8301 | AE16: 1194.1834 | AF16: 1262.1734 | AG16: 1317.9601 | AH16: 1354.5701 | AI16: 1389.4367 | AJ16: 1413.8434 | AK16: 1473.1167 | AL16: 1591.6634 | AM16: 1704.9801 | AN16: 1779.9434 | AO16: 1868.8534 | AP16: 1936.8434 | AQ16: 2111.1768 | AR16: 2391.8534 | AS16: 2604.5401 | AT16: 2655.0168 | AU16: 2649.9349 | AV16: 2640.1919 | AW16: 2610.4011 | AX16: 2570.5267 | AY16: 2520.4212
A17: BHR | B17: Bahrain | C17: 314_Bahrain_country | D17: Middle East | E17: Middle East and Central Asia | F17: Middle East | G17: 910.06629 | H17: 667.24695 | I17: 1577.3132 | J17: 1494035 | K17: 0 | L17: 0 | M17: 0 | N17: 0 | O17: 0 | P17: 0 | Q17: 0 | R17: 0 | S17: 0 | T17: 0 | U17: 0 | V17: 0 | W17: 0 | X17: 280.68691 | Y17: 292.99774 | Z17: 297.92207 | AA17: 300.38423 | AB17: 301.61532 | AC17: 301.61532 | AD17: 302.8464 | AE17: 304.07748 | AF17: 304.07748 | AG17: 307.77073 | AH17: 315.15723 | AI17: 320.08156 | AJ17: 321.31264 | AK17: 323.77481 | AL17: 325.00589 | AM17: 350.85863 | AN17: 361.93838 | AO17: 386.56004 | AP17: 438.26552 | AQ17: 513.36158 | AR17: 557.68057 | AS17: 578.60898 | AT17: 664.36467 | AU17: 659.54794 | AV17: 654.0123 | AW17: 641.13337 | AX17: 624.86983 | AY17: 607.091
... A19: BIH | B19: bosnia-herzegovina | C19: 117_Bosnia and Herzegovina_country | D19: Central Europe | E19: Europe | F19: Europe | G19: 51068.854 | H19: 790.81654 | I19: 51859.671 | J19: 3340977 | K19: 3.9527651 | L19: 3.9527651 | M19: 3.9527651 | N19: 5.2703535 | O19: 6.5879418 | P19: 7.9055302 | Q19: 9.2231186 | R19: 9.2231186 | S19: 9.2231186 | T19: 9.2231186 | U19: 10.540707 | V19: 13.175884 | W19: 15.81106 | X19: 17.128649 | Y19: 23.716591 | Z19: 36.892474 | AA19: 83.008067 | AB19: 126.48848 | AC19: 172.60408 | AD19: 204.2262 | AE19: 264.83526 | AF19: 281.96391 | AG19: 300.41015 | AH19: 318.85638 | AI19: 332.03227 | AJ19: 351.79609 | AK19: 367.60715 | AL19: 386.05339 | AM19: 407.13481 | AN19: 450.61522 | AO19: 505.95393 | AP19: 566.563 | AQ19: 610.04341 | AR19: 640.34795 | AS19: 736.5319 | AT19: 768.15402 | AU19: 764.24484 | AV19: 760.71427 | AW19: 747.57846 | AX19: 731.2698 | AY19: 711.87343
A20: BLR | B20: Belarus | C20: 146_Belarus_country | D20: Ukraine region | E20: Middle East and Central Asia | F20: Eurasia | G20: 207069.81 | H20: 3844.6981 | I20: 210914.51 | K20: 102.80584 | L20: 117.16622 | M20: 138.72749 | N20: 183.98634 | O20: 263.70183 | P20: 289.65913 | Q20: 306.67482 | R20: 339.31735 | S20: 362.53675 | T20: 485.5194 | U20: 670.85243 | V20: 857.85246 | W20: 1033.6264 | X20: 1044.7891 | Y20: 1127.0334 | Z20: 1197.111 | AA20: 1237.1839 | AB20: 1274.5114 | AC20: 1313.0808 | AD20: 1339.0463 | AE20: 1356.2237 | AF20: 1374.4645 | AG20: 1388.541 | AH20: 1413.4092 | AI20: 1459.9013 | AJ20: 1526.7754 | AK20: 1596.5759 | AL20: 1661.0305 | AM20: 1772.1807 | AN20: 1849.1222 | AO20: 1932.5027 | AP20: 2038.6038 | AQ20: 2302.2597 | AR20: 2642.961 | AS20: 2930.0919 | AT20: 3078.6181 | AU20: 3067.1507 | AV20: 3054.6267 | AW20: 3004.058 | AX20: 2939.5025 | AY20: 2858.6961
A21: BOL | B21: Bolivia | C21: 46_Bolivia_country | D21: Rest of South America | E21: Central and South America | F21: Latin America and Caribbean | G21: 1084380.2 | H21: 2854.2508 | I21: 1087234.5 | J21: 11862352 | K21: 22.652784 | L21: 22.652784 | M21: 56.63196 | N21: 56.63196 | O21: 79.284744 | P21: 124.59031 | Q21: 129.12087 | R21: 158.56949 | S21: 158.56949 | T21: 206.14033 | U21: 283.1598 | V21: 421.34178 | W21: 652.40018 | X21: 699.97102 | Y21: 847.21412 | Z21: 967.27387 | AA21: 1057.885 | AB21: 1085.0683 | AC21: 1130.3739 | AD21: 1177.9448 | AE21: 1189.2712 | AF21: 1257.2295 | AG21: 1288.9434 | AH21: 1354.6365 | AI21: 1395.4115 | AJ21: 1474.6962 | AK21: 1524.5324 | AL21: 1592.4907 | AM21: 1678.5713 | AN21: 1748.7949 | AO21: 1828.0797 | AP21: 2004.7714 | AQ21: 2285.6659 | AR21: 2487.2757 | AS21: 2639.0493 | AT21: 2784.2486 | AU21: 2801.7394 | AV21: 2824.5135 | AW21: 2855.2336 | AX21: 2868.9776 | AY21: 2854.6192
A22: BRA | B22: Brazil | C22: 53_brazil_country | D22: Brazil | E22: Central and South America | F22: Latin America and Caribbean | G22: 8509083.3 | H22: 73053.988 | I22: 8582137.3 | J22: 213317639 | K22: 1729.6824 | L22: 2124.0142 | M22: 2908.1966 | N22: 3873.8613 | O22: 5363.8079 | P22: 7572.9619 | Q22: 10277.271 | R22: 10694.008 | S22: 13747.838 | T22: 18726.277 | U22: 21275.99 | V22: 21376.813 | W22: 22573.252 | X22: 24636.772 | Y22: 29503.184 | Z22: 33027.524 | AA22: 35707.187 | AB22: 37008.93 | AC22: 38256.9 | AD22: 39560.884 | AE22: 40999.298 | AF22: 41917.912 | AG22: 42507.169 | AH22: 43251.022 | AI22: 44113.623 | AJ22: 45186.833 | AK22: 46251.08 | AL22: 47617.798 | AM22: 50167.511 | AN22: 51594.724 | AO22: 53635.838 | AP22: 56293.097 | AQ22: 61421.65 | AR22: 65976.629 | AS22: 69476.324 | AT22: 71254.21 | AU22: 70889.052 | AV22: 70379.664 | AW22: 69090.252 | AX22: 67246.411 | AY22: 64938.958
A23: BRN | B23: Brunei | C23: 302_Brunei_country | D23: Southeastern Asia | E23: South and East Asia | F23: South-East Asia and developing Pacific | G23: 5777.4914 | H23: 115.2332 | I23: 5892.7246 | J23: 439894 | K23: 2.9460643 | L23: 2.9460643 | M23: 2.9460643 | N23: 2.9460643 | O23: 2.9460643 | P23: 2.9460643 | Q23: 3.3669306 | R23: 3.7877969 | S23: 4.2086632 | T23: 8.4173264 | U23: 14.309455 | V23: 15.99292 | W23: 18.518118 | X23: 19.359851 | Y23: 35.352771 | Z23: 60.60475 | AA23: 73.23074 | AB23: 79.964601 | AC23: 82.910665 | AD23: 83.331532 | AE23: 85.014997 | AF23: 85.014997 | AG23: 86.277596 | AH23: 86.277596 | AI23: 86.277596 | AJ23: 86.698462 | AK23: 86.698462 | AL23: 86.698462 | AM23: 86.698462 | AN23: 87.119329 | AO23: 90.065393 | AP23: 90.065393 | AQ23: 92.590591 | AR23: 95.957521 | AS23: 100.58705 | AT23: 107.50896 | AU23: 105.87577 | AV23: 103.72086 | AW23: 98.861499 | AX23: 94.346352 | AY23: 89.269749
A24: BWA | B24: Botswana | C24: 71_Botswana_country | D24: Rest of Southern Africa | E24: Africa | F24: Africa | G24: 577870.82 | H24: 548.48246 | I24: 578419.31 | J24: 2523551 | K24: 10.194841 | L24: 10.194841 | M24: 10.194841 | N24: 10.194841 | O24: 10.194841 | P24: 10.194841 | Q24: 10.194841 | R24: 10.194841 | S24: 10.194841 | T24: 10.194841 | U24: 18.350714 | V24: 30.584524 | W24: 81.558729 | X24: 85.636666 | Y24: 108.06532 | Z24: 148.84468 | AA24: 175.35127 | AB24: 185.54611 | AC24: 193.70198 | AD24: 197.77992 | AE24: 212.0527 | AF24: 238.55928 | AG24: 256.91 | AH24: 275.26071 | AI24: 287.49452 | AJ24: 299.72833 | AK24: 303.80627 | AL24: 303.80627 | AM24: 309.92317 | AN24: 311.96214 | AO24: 330.31285 | AP24: 340.5077 | AQ24: 393.52087 | AR24: 481.1965 | AS24: 507.70309 | AT24: 529.5362 | AU24: 522.03412 | AV24: 517.72264 | AW24: 497.27427 | AX24: 475.22255 | AY24: 449.34944
A25: CAF | B25: Central African Republic | C25: 76_Central African Republic_country | D25: Western Africa | E25: Africa | F25: Africa | G25: 620199.67 | H25: 204.63717 | I25: 620404.31 | J25: 5352088 | K25: 59.192569 | L25: 59.192569 | M25: 59.192569 | N25: 59.192569 | O25: 59.192569 | P25: 59.192569 | Q25: 59.192569 | R25: 59.192569 | S25: 76.104732 | T25: 84.560813 | U25: 101.47298 | V25: 109.92906 | W25: 109.92906 | X25: 109.92906 | Y25: 118.38514 | Z25: 126.84122 | AA25: 126.84122 | AB25: 126.84122 | AC25: 135.2973 | AD25: 135.2973 | AE25: 135.2973 | AF25: 135.2973 | AG25: 135.2973 | AH25: 135.2973 | AI25: 135.2973 | AJ25: 135.2973 | AK25: 135.2973 | AL25: 135.2973 | AM25: 135.2973 | AN25: 152.20946 | AO25: 152.20946 | AP25: 160.66555 | AQ25: 160.66555 | AR25: 194.48987 | AS25: 194.48987 | AT25: 194.48987 | AU25: 203.75129 | AV25: 202.94595 | AW25: 201.97025 | AX25: 208.382 | AY25: 207.0376
A26: CAN | B26: Canada | C26: 182_Canada_country | D26: Canada | E26: North-America | F26: North America | G26: 9955196.2 | H26: 47487.542 | I26: 10002684 | J26: 37758236 | K26: 1826.9026 | L26: 2356.9197 | M26: 3034.3478 | N26: 3522.9572 | O26: 4796.6545 | P26: 6080.2896 | Q26: 7486.4912 | R26: 8539.9001 | S26: 10393.304 | T26: 14595.345 | U26: 19585.787 | V26: 22485.974 | W26: 26106.654 | X26: 27552.606 | Y26: 30235.818 | Z26: 32215.1 | AA26: 32769.962 | AB26: 32996.876 | AC26: 33250.29 | AD26: 33558.362 | AE26: 33685.898 | AF26: 33882.998 | AG26: 34050.284 | AH26: 34167.882 | AI26: 34277.198 | AJ26: 34472.642 | AK26: 34692.93 | AL26: 35085.474 | AM26: 35741.37 | AN26: 36236.605 | AO26: 36720.245 | AP26: 37145.915 | AQ26: 38626.651 | AR26: 41129.325 | AS26: 44463.464 | AT26: 46021.872 | AU26: 45791.381 | AV26: 45478.86 | AW26: 44832.028 | AX26: 43946.094 | AY26: 42917.539
A27: CHE | B27: Switzerland | C27: 145_Switzerland_country | D27: Western Europe | E27: Europe | F27: Europe | G27: 41235.436 | H27: 8253.9036 | I27: 49489.34 | J27: 8606426 | K27: 489.28749 | L27: 533.1979 | M27: 572.92638 | N27: 687.92985 | O27: 834.2979 | P27: 874.02637 | Q27: 934.66456 | R27: 1003.6666 | S27: 1141.6708 | T27: 1423.9521 | U27: 1875.602 | V27: 1942.5131 | W27: 2676.4444 | X27: 2707.809 | Y27: 2952.4527 | Z27: 3201.2784 | AA27: 3389.4659 | AB27: 3475.1958 | AC27: 3533.743 | AD27: 4058.577 | AE27: 4121.3062 | AF27: 4192.3992 | AG27: 4303.2207 | AH27: 4409.8603 | AI27: 4441.2249 | AJ27: 4520.6818 | AK27: 4696.3235 | AL27: 4792.5082 | AM27: 4984.8777 | AN27: 5099.8811 | AO27: 5712.536 | AP27: 6047.0915 | AQ27: 6377.4651 | AR27: 7071.6679 | AS27: 7872.5102 | AT27: 8113.0033 | AU27: 8099.5945 | AV27: 8077.1772 | AW27: 8032.2937 | AX27: 7971.0006 | AY27: 7895.8002
A28: CHL | B28: Chile | C28: 47_Chile_country | D28: Rest of South America | E28: Central and South America | F28: Latin America and Caribbean | G28: 752545.1 | H28: 8755.98 | I28: 761301.08 | J28: 19206692 | K28: 172.73357 | L28: 211.88652 | M28: 255.64569 | N28: 317.82977 | O28: 423.77303 | P28: 481.35089 | Q28: 555.05055 | R28: 677.11561 | S28: 852.15229 | T28: 1197.6194 | U28: 1706.6077 | V28: 2204.0804 | W28: 2719.978 | X28: 2878.8929 | Y28: 3615.8895 | Z28: 4078.8154 | AA28: 4246.9428 | AB28: 4302.2175 | AC28: 4396.6452 | AD28: 4525.6196 | AE28: 4739.8092 | AF28: 4901.0272 | AG28: 5006.9705 | AH28: 5103.7013 | AI28: 5156.6729 | AJ28: 5237.2819 | AK28: 5327.1034 | AL28: 5423.8342 | AM28: 5654.1456 | AN28: 5843.001 | AO28: 6047.9782 | AP28: 6483.2668 | AQ28: 7229.4758 | AR28: 7786.8295 | AS28: 8288.9084 | AT28: 8540.0437 | AU28: 8500.7891 | AV28: 8438.3234 | AW28: 8292.5733 | AX28: 8111.4224 | AY28: 7901.5796
A29: CHN | B29: China | C29: 184_China_country | D29: China region | E29: South and East Asia | F29: Eastern Asia | G29: 9349155.5 | H29: 382823.89 | I29: 9731979.4 | J29: 1423998017 | K29: 6225.7581 | L29: 6391.153 | M29: 7000.8922 | N29: 8659.7778 | O29: 15490.338 | P29: 17450.39 | Q29: 17820.677 | R29: 17971.261 | S29: 18144.061 | T29: 19595.586 | U29: 22140.692 | V29: 24569.774 | W29: 34663.797 | X29: 37364.423 | Y29: 44575.145 | Z29: 53049.779 | AA29: 61507.133 | AB29: 66049.32 | AC29: 70221.22 | AD29: 76686.43 | AE29: 81248.365 | AF29: 87123.585 | AG29: 94205.94 | AH29: 104628.28 | AI29: 116716.92 | AJ29: 127203.45 | AK29: 137939.3 | AL29: 150176.05 | AM29: 167826.39 | AN29: 178683.21 | AO29: 197005.01 | AP29: 224823.43 | AQ29: 252730.73 | AR29: 282225.32 | AS29: 323174.12 | AT29: 353050.44 | AU29: 349710.62 | AV29: 345680.42 | AW29: 336048.71 | AX29: 325484.83 | AY29: 314488.18
A30: CIV | B30: ivory coast | C30: 88_Côte d'Ivoire_country | D30: Western Africa | E30: Africa | F30: Africa | G30: 321543.25 | H30: 2466.7868 | I30: 324010.03 | J30: 26477572 | K30: 55.867993 | L30: 60.165531 | M30: 64.463069 | N30: 73.058145 | O30: 81.65322 | P30: 85.950758 | Q30: 90.248296 | R30: 98.843372 | S30: 116.03352 | T30: 189.09167 | U30: 352.39811 | V30: 541.48978 | W30: 666.11838 | X30: 734.87898 | Y30: 945.45834 | Z30: 1027.1116 | AA30: 1074.3845 | AB30: 1113.0623 | AC30: 1143.1451 | AD30: 1216.2032 | AE30: 1246.286 | AF30: 1272.0712 | AG30: 1272.0712 | AH30: 1293.5589 | AI30: 1336.5343 | AJ30: 1353.7244 | AK30: 1405.2949 | AL30: 1422.485 | AM30: 1491.2457 | AN30: 1525.626 | AO30: 1594.3866 | AP30: 1637.3619 | AQ30: 1792.0733 | AR30: 2024.1404 | AS30: 2393.7286 | AT30: 2421.7572 | AU30: 2445.7533 | AV30: 2481.5355 | AW30: 2536.4749 | AX30: 2545.1603 | AY30: 2396.3365
A31: CMR | B31: Cameroon | C31: 74_Cameroon_country | D31: Western Africa | E31: Africa | F31: Africa | G31: 466040.04 | H31: 2406.1205 | I31: 468446.16 | J31: 26137122 | K31: 109.61825 | L31: 109.61825 | M31: 109.61825 | N31: 118.7531 | O31: 118.7531 | P31: 118.7531 | Q31: 118.7531 | R31: 118.7531 | S31: 127.88796 | T31: 155.29252 | U31: 228.37135 | V31: 383.66387 | W31: 557.2261 | X31: 648.57464 | Y31: 730.78832 | Z31: 858.67628 | AA31: 950.02482 | AB31: 950.02482 | AC31: 968.29453 | AD31: 986.56423 | AE31: 1004.8339 | AF31: 1013.9688 | AG31: 1023.1037 | AH31: 1032.2385 | AI31: 1032.2385 | AJ31: 1050.5082 | AK31: 1068.7779 | AL31: 1087.0476 | AM31: 1388.4978 | AN31: 1415.9024 | AO31: 1507.2509 | AP31: 1963.9936 | AQ31: 2082.7467 | AR31: 2320.2529 | AS31: 2384.1969 | AT31: 2318.6036 | AU31: 2319.0349 | AV31: 2319.6414 | AW31: 2260.8764 | AX31: 2088.6608 | AY31: 1639.0149
A32: COD | B32: congo democratic republic | C32: 79_Democratic Republic of the Congo_country | D32: Western Africa | E32: Africa | F32: Africa | G32: 2328869.3 | H32: 4142.8262 | I32: 2333012.1 | K32: 214.77117 | L32: 218.63495 | M32: 223.23393 | N32: 230.87277 | O32: 240.64861 | P32: 245.89315 | Q32: 254.13045 | R32: 265.2817 | S32: 306.14623 | T32: 368.46732 | U32: 509.3477 | V32: 690.12311 | W32: 921.91329 | X32: 999.0695 | Y32: 1153.9094 | Z32: 1321.4637 | AA32: 1444.8511 | AB32: 1476.8494 | AC32: 1543.5192 | AD32: 1610.7965 | AE32: 1659.5916 | AF32: 1722.5902 | AG32: 1776.9357 | AH32: 1818.8534 | AI32: 1864.83 | AJ32: 1931.7734 | AK32: 2006.3245 | AL32: 2102.947 | AM32: 2269.2456 | AN32: 2399.9442 | AO32: 2542.6485 | AP32: 2774.6234 | AQ32: 3117.8107 | AR32: 3501.1324 | AS32: 3816.8511 | AT32: 4062.5124 | AU32: 4073.5789 | AV32: 4083.8584 | AW32: 4008.6858 | AX32: 3629.4588 | AY32: 2739.6141
A33: COG | B33: Congo Brazzaville | C33: 78_Republic of the Congo_country | D33: Western Africa | E33: Africa | F33: Africa | G33: 341732.67 | H33: 429.13948 | I33: 342161.81 | J33: 5272024 | K33: 16.117915 | L33: 16.117915 | M33: 16.117915 | N33: 16.117915 | O33: 16.117915 | P33: 16.117915 | Q33: 16.117915 | R33: 16.117915 | S33: 18.132654 | T33: 22.162133 | U33: 34.250569 | V33: 54.397963 | W33: 78.574835 | X33: 80.589574 | Y33: 84.619053 | Z33: 86.633793 | AA33: 88.648532 | AB33: 90.663271 | AC33: 90.663271 | AD33: 90.663271 | AE33: 90.663271 | AF33: 94.69275 | AG33: 110.81066 | AH33: 110.81066 | AI33: 114.84014 | AJ33: 114.84014 | AK33: 132.9728 | AL33: 137.00228 | AM33: 147.07597 | AN33: 153.12019 | AO33: 173.26759 | AP33: 211.54763 | AQ33: 284.07825 | AR33: 332.43199 | AS33: 413.02157 | AT33: 410.67486 | AU33: 404.09137 | AV33: 396.24912 | AW33: 369.63695 | AX33: 311.97654 | AY33: 220.27817
A34: COL | B34: Colombia | C34: 45_Colombia_country | D34: Rest of South America | E34: Central and South America | F34: Latin America and Caribbean | G34: 1137241.3 | H34: 7273.2353 | I34: 1144514.5 | J34: 50617026 | K34: 94.632248 | L34: 114.55483 | M34: 134.4774 | N34: 161.87095 | O34: 199.22578 | P34: 261.48384 | Q34: 343.66448 | R34: 415.88382 | S34: 565.30316 | T34: 916.43861 | U34: 1486.7224 | V34: 2154.1288 | W34: 2968.4642 | X34: 3152.748 | Y34: 3879.9221 | Z34: 4335.6511 | AA34: 4430.2834 | AB34: 4477.5995 | AC34: 4509.9737 | AD34: 4592.1543 | AE34: 4664.3737 | AF34: 4679.3156 | AG34: 4696.7479 | AH34: 4709.1995 | AI34: 4726.6317 | AJ34: 4751.535 | AK34: 4778.9285 | AL34: 4791.3801 | AM34: 4935.8188 | AN34: 5035.4317 | AO34: 5187.3414 | AP34: 5471.2381 | AQ34: 5971.7929 | AR34: 6390.167 | AS34: 6671.5735 | AT34: 7009.1365 | AU34: 6965.5606 | AV34: 6908.5909 | AW34: 6764.0187 | AX34: 6545.357 | AY34: 6200.0927
A35: CRI | B35: Costa Rica | C35: 32_Costa Rica_country | D35: Central America | E35: Central and South America | F35: Latin America and Caribbean | G35: 51177.91 | H35: 1998.3282 | I35: 53176.239 | J35: 5105361 | K35: 48.771433 | L35: 52.022861 | M35: 58.525719 | N35: 68.280006 | O35: 84.53715 | P35: 97.542865 | Q35: 104.04572 | R35: 130.05715 | S35: 185.33144 | T35: 260.11431 | U35: 409.68003 | V35: 601.51434 | W35: 952.66865 | X35: 1024.2001 | Y35: 1128.2458 | Z35: 1199.7772 | AA35: 1212.783 | AB35: 1219.2858 | AC35: 1225.7887 | AD35: 1248.5487 | AE35: 1268.0572 | AF35: 1303.823 | AG35: 1307.0744 | AH35: 1316.8287 | AI35: 1316.8287 | AJ35: 1316.8287 | AK35: 1323.3315 | AL35: 1326.583 | AM35: 1385.1087 | AN35: 1391.6115 | AO35: 1459.8916 | AP35: 1518.4173 | AQ35: 1680.9887 | AR35: 1723.2573 | AS35: 1798.0402 | AT35: 1924.3965 | AU35: 1910.3758 | AV35: 1894.7392 | AW35: 1857.3697 | AX35: 1810.1093 | AY35: 1746.9156
A36: CUB | B36: Cuba | C36: 33_Cuba_country | D36: Central America | E36: Central and South America | F36: Latin America and Caribbean | G36: 110730.65 | H36: 2365.6029 | I36: 113096.26 | K36: 90.481966 | L36: 98.914939 | M36: 112.6461 | N36: 129.59546 | O36: 152.26855 | P36: 174.27715 | Q36: 195.11341 | R36: 219.9606 | S36: 259.30493 | T36: 339.47062 | U36: 464.69831 | V36: 597.51862 | W36: 761.48584 | X36: 817.13696 | Y36: 979.59467 | Z36: 1091.9899 | AA36: 1167.973 | AB36: 1197.9814 | AC36: 1223.9421 | AD36: 1268.5659 | AE36: 1312.9922 | AF36: 1345.0307 | AG36: 1356.6278 | AH36: 1375.4885 | AI36: 1391.4001 | AJ36: 1414.246 | AK36: 1430.3888 | AL36: 1454.5174 | AM36: 1508.0469 | AN36: 1551.7184 | AO36: 1621.3448 | AP36: 1760.3146 | AQ36: 1953.9684 | AR36: 2110.635 | AS36: 2219.3845 | AT36: 2322.844 | AU36: 2317.892 | AV36: 2308.5207 | AW36: 2275.8368 | AX36: 2215.8485 | AY36: 2151.8901
A37: CYP | B37: Cyprus | C37: 120_Cyprus_country | D37: Central Europe | E37: Europe | F37: Europe | G37: 5719.8196 | H37: 492.87656 | I37: 6212.6962 | J37: 1233777 | K37: 13.798336 | L37: 16.558003 | M37: 20.237559 | N37: 24.837005 | O37: 34.035895 | P37: 38.635341 | Q37: 43.234786 | R37: 47.834231 | S37: 61.632567 | T37: 69.911569 | U37: 80.950238 | V37: 104.86735 | W37: 120.50547 | X37: 159.14081 | Y37: 183.97781 | Z37: 214.33415 | AA37: 222.61315 | AB37: 223.53304 | AC37: 225.37282 | AD37: 229.97227 | AE37: 229.97227 | AF37: 237.33138 | AG37: 243.7706 | AH37: 260.32861 | AI37: 267.68772 | AJ37: 275.04683 | AK37: 284.24572 | AL37: 295.28439 | AM37: 325.64073 | AN37: 349.55784 | AO37: 358.75674 | AP37: 421.30919 | AQ37: 463.62409 | AR37: 496.7401 | AS37: 514.21799 | AT37: 473.74287 | AU37: 472.54956 | AV37: 470.41446 | AW37: 464.24902 | AX37: 452.28136 | AY37: 439.85663
A38: CZE | B38: czech-republic | C38: 121_Czechia_country | D38: Central Europe | E38: Europe | F38: Europe | G38: 78837.644 | H38: 10683.085 | I38: 89520.73 | J38: 10537908 | K38: 885.88239 | L38: 1060.8715 | M38: 1240.2353 | N38: 1585.8389 | O38: 2325.1679 | P38: 2441.0981 | Q38: 2707.9565 | R38: 2707.9565 | S38: 2707.9565 | T38: 2952.9413 | U38: 3307.2943 | V38: 3967.8782 | W38: 4145.0547 | X38: 4155.9915 | Y38: 4556.2791 | Z38: 5319.6691 | AA38: 5676.2094 | AB38: 5868.6974 | AC38: 6061.1855 | AD38: 6233.9872 | AE38: 6332.4186 | AF38: 6441.7868 | AG38: 6538.0308 | AH38: 6592.7149 | AI38: 6632.0874 | AJ38: 6697.7084 | AK38: 6758.9546 | AL38: 6863.948 | AM38: 7078.3097 | AN38: 7231.4252 | AO38: 7649.2117 | AP38: 8108.5581 | AQ38: 8979.1289 | AR38: 9685.6475 | AS38: 10269.674 | AT38: 10493.248 | AU38: 10462.655 | AV38: 10422.338 | AW38: 10327.024 | AX38: 10193.683 | AY38: 10032.495
A39: DEU | B39: Germany | C39: 347_Germany_country | D39: Western Europe | E39: Europe | F39: Europe | G39: 357823.91 | H39: 65554.872 | I39: 423378.78 | J39: 83267652 | K39: 5237.4737 | L39: 6861.8271 | M39: 9013.4169 | N39: 12574.201 | O39: 18086.923 | P39: 18086.923 | Q39: 19565.899 | R39: 21283.294 | S39: 21327.877 | T39: 23754.715 | U39: 26261.026 | V39: 27197.259 | W39: 28443.63 | X39: 28860.379 | Y39: 31577.973 | Z39: 35266.69 | AA39: 37519.075 | AB39: 38610.377 | AC39: 39558.239 | AD39: 40548.746 | AE39: 41238.805 | AF39: 41645.863 | AG39: 41957.94 | AH39: 42271.956 | AI39: 42446.409 | AJ39: 42710.028 | AK39: 43049.242 | AL39: 43717.98 | AM39: 44640.643 | AN39: 45739.699 | AO39: 48079.31 | AP39: 50756.198 | AQ39: 55712.608 | AR39: 60260.023 | AS39: 64146.453 | AT39: 65058.149 | AU39: 64948.979 | AV39: 64790.951 | AW39: 64448.437 | AX39: 64001.487 | AY39: 63418.835
A40: DJI | B40: Djibouti | C40: 80_Djibouti_country | D40: Eastern Africa | E40: Africa | F40: Africa | G40: 22372.295 | H40: 52.672493 | I40: 22424.967 | J40: 1082341 | K40: 6.3005375 | L40: 6.3005375 | M40: 6.3005375 | N40: 6.3005375 | O40: 6.3005375 | P40: 6.3005375 | Q40: 6.3005375 | R40: 6.3005375 | S40: 6.3005375 | T40: 6.3005375 | U40: 7.560645 | V40: 10.08086 | W40: 11.340967 | X40: 12.601075 | Y40: 16.381397 | Z40: 16.381397 | AA40: 17.641505 | AB40: 17.641505 | AC40: 17.641505 | AD40: 17.641505 | AE40: 17.641505 | AF40: 18.901612 | AG40: 18.901612 | AH40: 18.901612 | AI40: 20.16172 | AJ40: 20.16172 | AK40: 21.421827 | AL40: 21.421827 | AM40: 22.681935 | AN40: 31.502687 | AO40: 42.843655 | AP40: 42.843655 | AQ40: 49.144192 | AR40: 55.44473 | AS40: 55.44473 | AT40: 51.664407 | AU40: 51.664407 | AV40: 51.664407 | AW40: 50.372797 | AX40: 49.316025 | AY40: 43.866006
A41: DNK | B41: Denmark | C41: 122_Denmark_country | D41: Western Europe | E41: Europe | F41: Europe | G41: 43144.849 | H41: 6975.4192 | I41: 50120.268 | J41: 5810771 | K41: 798.58661 | L41: 901.93311 | M41: 1031.1162 | N41: 1216.6702 | O41: 1465.6413 | P41: 1686.427 | Q41: 1864.9346 | R41: 2036.3959 | S41: 2160.8814 | T41: 2539.0357 | U41: 3060.4657 | V41: 3506.7347 | W41: 3666.452 | X41: 3833.2157 | Y41: 4091.582 | Z41: 4321.7628 | AA41: 4434.5045 | AB41: 4481.4801 | AC41: 4547.2461 | AD41: 4638.8487 | AE41: 4678.778 | AF41: 4702.2659 | AG41: 4714.0098 | AH41: 4732.8001 | AI41: 4739.8464 | AJ41: 4782.1245 | AK41: 4815.0075 | AL41: 4840.8441 | AM41: 4918.354 | AN41: 4977.0736 | AO41: 5092.164 | AP41: 5366.9718 | AQ41: 5806.1944 | AR41: 6391.0417 | AS41: 6856.1009 | AT41: 6841.8327 | AU41: 6832.3821 | AV41: 6814.2789 | AW41: 6802.7885 | AX41: 6801.2265 | AY41: 6838.9781
...

Sheet Input_final
A1: Cntry_ISO | B1: Cntry_name | C1: eFUA_name | D1: IMAGE-region | E1: GRIP-region | F1: R10 | G1: FUA_area | H1: FUA_urban | I1: FUA_total_area | J1: FUA_p_2015 | K1: 1870 | L1: 1880 | M1: 1890 | N1: 1900 | O1: 1910 | P1: 1920 | Q1: 1930 | R1: 1940 | S1: 1950 | T1: 1960 | U1: 1970 | V1: 1980 | W1: 1990 | X1: 1992 | Y1: 1993 | Z1: 1994 | AA1: 1995 | AB1: 1996 | AC1: 1997 | AD1: 1998 | AE1: 1999 | AF1: 2000 | AG1: 2001 | AH1: 2002 | AI1: 2003 | AJ1: 2004 | AK1: 2005 | AL1: 2006 | AM1: 2007 | AN1: 2008 | AO1: 2009 | AP1: 2010 | AQ1: 2011 | AR1: 2012 | AS1: 2013 | AT1: 2020 | AU1: 2024 | AV1: 2030 | AW1: 2040 | AX1: 2050 | AY1: 2060
A2: AFG | B2: Afghanistan | C2: 161_Afghanistan_country | D2: Rest of South Asia | E2: South and East Asia | F2: Southern Asia | G2: 643838.73 | H2: 1917.352 | I2: 645756.08 | K2: 131.84812 | L2: 142.60477 | M2: 153.64254 | N2: 170.19085 | O2: 188.72652 | P2: 196.10551 | Q2: 206.15466 | R2: 217.69632 | S2: 254.86721 | T2: 291.83836 | U2: 357.18789 | V2: 466.79345 | W2: 578.13683 | X2: 609.68643 | Y2: 705.36716 | Z2: 849.2652 | AA2: 893.55539 | AB2: 920.79412 | AC2: 935.11603 | AD2: 962.27858 | AE2: 980.45841 | AF2: 997.88307 | AG2: 1016.8153 | AH2: 1037.3453 | AI2: 1059.3365 | AJ2: 1090.3345 | AK2: 1112.2849 | AL2: 1134.9743 | AM2: 1181.275 | AN2: 1224.1342 | AO2: 1263.823 | AP2: 1359.6194 | AQ2: 1474.6454 | AR2: 1607.5437 | AS2: 1719.2458 | AT2: 1829.6659 | AU2: 1836.4786 | AV2: 1844.784 | AW2: 1850.0082 | AX2: 1838.642 | AY2: 1763.1448
A3: AGO | B3: Angola | C3: 69_Angola_country | D3: Rest of Southern Africa | E3: Africa | F3: Africa | G3: 1246918.1 | H3: 4318.8619 | I3: 1251237 | K3: 223.89716 | L3: 227.92512 | M3: 232.71952 | N3: 240.68294 | O3: 250.87418 | P3: 256.34157 | Q3: 264.92889 | R3: 276.55397 | S3: 319.15491 | T3: 384.12412 | U3: 530.99074 | V3: 719.44761 | W3: 961.08695 | X3: 1041.5217 | Y3: 1202.941 | Z3: 1377.615 | AA3: 1506.2453 | AB3: 1539.6032 | AC3: 1609.1059 | AD3: 1679.2419 | AE3: 1730.1105 | AF3: 1795.786 | AG3: 1852.4407 | AH3: 1896.1395 | AI3: 1944.0698 | AJ3: 2013.8577 | AK3: 2091.5766 | AL3: 2192.3047 | AM3: 2365.6697 | AN3: 2501.9219 | AO3: 2650.6899 | AP3: 2892.5219 | AQ3: 3250.2917 | AR3: 3649.9015 | AS3: 3979.0356 | AT3: 4342.7228 | AU3: 4366.6678 | AV3: 4396.7451 | AW3: 4417.1823 | AX3: 4344.2633 | AY3: 4054.3708
A4: ALB | B4: Albania | C4: 114_Albania_country | D4: Central Europe | E4: Europe | F4: Europe | G4: 28727.645 | H4: 806.29565 | I4: 29533.941 | K4: 84.742947 | L4: 94.047032 | M4: 104.25818 | N4: 117.80812 | O4: 138.17356 | P4: 146.13257 | Q4: 157.69914 | R4: 167.63982 | S4: 183.88669 | T4: 205.54909 | U4: 241.24807 | V4: 273.01877 | W4: 295.90385 | X4: 307.26851 | Y4: 344.02769 | Z4: 383.31811 | AA4: 405.78601 | AB4: 415.85854 | AC4: 428.46531 | AD4: 446.39113 | AE4: 457.75633 | AF4: 467.24033 | AG4: 477.51048 | AH4: 488.38357 | AI4: 495.45142 | AJ4: 504.11159 | AK4: 512.5596 | AL4: 526.40242 | AM4: 545.27543 | AN4: 561.77977 | AO4: 591.50392 | AP4: 626.56054 | AQ4: 680.02281 | AR4: 736.50365 | AS4: 782.49125 | AT4: 798.78865 | AU4: 796.86467 | AV4: 794.06547 | AW4: 786.90087 | AX4: 776.78775 | AY4: 763.98581
A5: ARE | B5: United Arab Emirates | C5: 194_United Arab Emirates_country | D5: Middle East | E5: Middle East and Central Asia | F5: Middle East | G5: 71093.261 | H5: 3889.0822 | I5: 74982.343 | K5: 59.161203 | L5: 65.118563 | M5: 71.164999 | N5: 78.469826 | O5: 89.124312 | P5: 97.960277 | Q5: 109.00476 | R5: 129.67434 | S5: 149.8278 | T5: 241.44334 | U5: 394.65557 | V5: 610.01621 | W5: 941.33471 | X5: 1179.3985 | Y5: 1292.8781 | Z5: 1428.2745 | AA5: 1606.3905 | AB5: 1667.4416 | AC5: 1731.5042 | AD5: 1798.7089 | AE5: 1853.8346 | AF5: 1895.0468 | AG5: 1932.0405 | AH5: 1974.1097 | AI5: 2021.4624 | AJ5: 2081.7225 | AK5: 2134.3282 | AL5: 2196.6106 | AM5: 2314.7907 | AN5: 2390.4311 | AO5: 2521.4308 | AP5: 2715.415 | AQ5: 2951.6334 | AR5: 3188.0742 | AS5: 3410.4026 | AT5: 3607.7675 | AU5: 3596.1779 | AV5: 3583.3762 | AW5: 3496.4193 | AX5: 3382.0555 | AY5: 3296.5251
A6: ARG | B6: Argentina | C6: 45_Argentina_country | D6: Rest of South America | E6: Central and South America | F6: Latin America and Caribbean | G6: 2779049.5 | H6: 18828.018 | I6: 2797877.5 | J6: 44908441 | K6: 374.52099 | L6: 586.38506 | M6: 811.91777 | N6: 1161.8352 | O6: 1707.2143 | P6: 2243.0254 | Q6: 2829.4104 | R6: 3388.4582 | S6: 3977.577 | T6: 4614.536 | U6: 4794.9622 | V6: 4915.2463 | W6: 4982.2227 | X6: 5072.4358 | Y6: 7293.5913 | Z6: 8449.959 | AA6: 9010.3737 | AB6: 9312.4508 | AC6: 9546.1847 | AD6: 9938.4749 | AE6: 10438.748 | AF6: 10709.387 | AG6: 10896.647 | AH6: 11022.399 | AI6: 11134.482 | AJ6: 11287.571 | AK6: 11491.234 | AL6: 11847.985 | AM6: 12243.009 | AN6: 12695.442 | AO6: 13340.602 | AP6: 14341.147 | AQ6: 15524.852 | AR6: 16630.646 | AS6: 17811.617 | AT6: =Sheet1!$AT6*_xlfn.XLOOKUP($A6,'[1]SSP4-change-rate'!$B$2:$B$147,'[1]SSP4-change-rate'!C$2:C$147) -> 18351.102 | AU6: =Sheet1!$AT6*_xlfn.XLOOKUP($A6,'[1]SSP4-change-rate'!$B$2:$B$147,'[1]SSP4-change-rate'!D$2:D$147) -> 18249.595 | AV6: =Sheet1!$AT6*_xlfn.XLOOKUP($A6,'[1]SSP4-change-rate'!$B$2:$B$147,'[1]SSP4-change-rate'!E$2:E$147) -> 18105.192 | AW6: =Sheet1!$AT6*_xlfn.XLOOKUP($A6,'[1]SSP4-change-rate'!$B$2:$B$147,'[1]SSP4-change-rate'!F$2:F$147) -> 17756.357 | AX6: =Sheet1!$AT6*_xlfn.XLOOKUP($A6,'[1]SSP4-change-rate'!$B$2:$B$147,'[1]SSP4-change-rate'!G$2:G$147) -> 17289.666 | AY6: =Sheet1!$AT6*_xlfn.XLOOKUP($A6,'[1]SSP4-change-rate'!$B$2:$B$147,'[1]SSP4-change-rate'!H$2:H$147) -> 16733.315
A7: ARM | B7: Armenia | C7: 158_Armenia_country | D7: Russia region | E7: Europe | F7: Eurasia | G7: 29690.165 | H7: 779.13352 | I7: 30469.298 | J7: 2812494 | K7: 7.3089448 | L7: 7.3089448 | M7: 7.3089448 | N7: 7.3089448 | O7: 7.3089448 | P7: 7.3089448 | Q7: 7.3089448 | R7: 9.136181 | S7: 9.136181 | T7: 12.790653 | U7: 20.099598 | V7: 27.408543 | W7: 32.890252 | X7: 32.890252 | Y7: 32.890252 | Z7: 56.644322 | AA7: 89.534574 | AB7: 124.25206 | AC7: 186.37809 | AD7: 199.16875 | AE7: 208.30493 | AF7: 219.26834 | AG7: 222.92282 | AH7: 226.57729 | AI7: 239.36794 | AJ7: 253.98583 | AK7: 303.32121 | AL7: 339.86593 | AM7: 385.54684 | AN7: 403.8192 | AO7: 416.60986 | AP7: 427.57327 | AQ7: 462.29076 | AR7: 575.57941 | AS7: 676.0774 | AT7: =Sheet1!$AT7*_xlfn.XLOOKUP($A7,'[1]SSP4-change-rate'!$B$2:$B$147,'[1]SSP4-change-rate'!C$2:C$147) -> 730.89448 | AU7: =Sheet1!$AT7*_xlfn.XLOOKUP($A7,'[1]SSP4-change-rate'!$B$2:$B$147,'[1]SSP4-change-rate'!D$2:D$147) -> 723.20086 | AV7: =Sheet1!$AT7*_xlfn.XLOOKUP($A7,'[1]SSP4-change-rate'!$B$2:$B$147,'[1]SSP4-change-rate'!E$2:E$147) -> 717.01674 | AW7: =Sheet1!$AT7*_xlfn.XLOOKUP($A7,'[1]SSP4-change-rate'!$B$2:$B$147,'[1]SSP4-change-rate'!F$2:F$147) -> 699.28823 | AX7: =Sheet1!$AT7*_xlfn.XLOOKUP($A7,'[1]SSP4-change-rate'!$B$2:$B$147,'[1]SSP4-change-rate'!G$2:G$147) -> 681.46201 | AY7: =Sheet1!$AT7*_xlfn.XLOOKUP($A7,'[1]SSP4-change-rate'!$B$2:$B$147,'[1]SSP4-change-rate'!H$2:H$147) -> 662.37312
A8: AUS | B8: Australia | C8: 55_Australia_country | D8: Oceania | E8: Oceania | F8: Asia-Pacific Developed | G8: 7688058.2 | H8: 33097.674 | I8: 7721155.9 | J8: 25544183 | K8: 788.12958 | L8: 1073.8658 | M8: 1598.2389 | N8: 2125.7519 | O8: 2901.3216 | P8: 3535.5933 | Q8: 4232.664 | R8: 4832.3961 | S8: 5711.5845 | T8: 7520.2006 | U8: 9972.5081 | V8: 11862.763 | W8: 14095.274 | X8: 14663.606 | Y8: 16833.317 | Z8: 18283.978 | AA8: 18805.211 | AB8: 19106.647 | AC8: 19467.743 | AD8: 19850.818 | AE8: 20243.312 | AF8: 20720.586 | AG8: 21084.821 | AH8: 21433.357 | AI8: 21932.61 | AJ8: 22315.685 | AK8: 22648.521 | AL8: 22927.977 | AM8: 23829.145 | AN8: 24381.778 | AO8: 24755.433 | AP8: 25515.303 | AQ8: 26969.103 | AR8: 28579.902 | AS8: 29628.648 | AT8: =Sheet1!$AT8*_xlfn.XLOOKUP($A8,'[1]SSP4-change-rate'!$B$2:$B$147,'[1]SSP4-change-rate'!C$2:C$147) -> 31650.091 | AU8: =Sheet1!$AT8*_xlfn.XLOOKUP($A8,'[1]SSP4-change-rate'!$B$2:$B$147,'[1]SSP4-change-rate'!D$2:D$147) -> 31508.541 | AV8: =Sheet1!$AT8*_xlfn.XLOOKUP($A8,'[1]SSP4-change-rate'!$B$2:$B$147,'[1]SSP4-change-rate'!E$2:E$147) -> 31328.589 | AW8: =Sheet1!$AT8*_xlfn.XLOOKUP($A8,'[1]SSP4-change-rate'!$B$2:$B$147,'[1]SSP4-change-rate'!F$2:F$147) -> 30963.347 | AX8: =Sheet1!$AT8*_xlfn.XLOOKUP($A8,'[1]SSP4-change-rate'!$B$2:$B$147,'[1]SSP4-change-rate'!G$2:G$147) -> 30495.55 | AY8: =Sheet1!$AT8*_xlfn.XLOOKUP($A8,'[1]SSP4-change-rate'!$B$2:$B$147,'[1]SSP4-change-rate'!H$2:H$147) -> 29969.634
A9: AUT | B9: Austria | C9: 115_Austria_country | D9: Western Europe | E9: Europe | F9: Europe | G9: 83946.896 | H9: 6142.9455 | I9: 90089.841 | J9: 8901100 | K9: 631.31838 | L9: 901.26141 | M9: 1055.8256 | N9: 1197.328 | O9: 1334.4764 | P9: 1334.4764 | Q9: 1399.7852 | R9: 1452.0323 | S9: 1543.4646 | T9: 1602.2425 | U9: 1728.5062 | V9: 1795.9919 | W9: 1872.1855 | X9: 1898.309 | Y9: 2192.1986 | Z9: 2499.15 | AA9: 2660.245 | AB9: 2747.3234 | AC9: 2808.2783 | AD9: 2934.542 | AE9: 3012.9125 | AF9: 3045.5669 | AG9: 3078.2213 | AH9: 3121.7605 | AI9: 3154.4149 | AJ9: 3226.2546 | AK9: 3261.086 | AL9: 3348.1644 | AM9: 3476.605 | AN9: 3591.9839 | AO9: 3853.2191 | AP9: 4277.7262 | AQ9: 4832.851 | AR9: 5488.116 | AS9: 5897.3844 | AT9: =Sheet1!$AT9*_xlfn.XLOOKUP($A9,'[1]SSP4-change-rate'!$B$2:$B$147,'[1]SSP4-change-rate'!C$2:C$147) -> 6041.6417 | AU9: =Sheet1!$AT9*_xlfn.XLOOKUP($A9,'[1]SSP4-change-rate'!$B$2:$B$147,'[1]SSP4-change-rate'!D$2:D$147) -> 6038.0046 | AV9: =Sheet1!$AT9*_xlfn.XLOOKUP($A9,'[1]SSP4-change-rate'!$B$2:$B$147,'[1]SSP4-change-rate'!E$2:E$147) -> 6030.9895 | AW9: =Sheet1!$AT9*_xlfn.XLOOKUP($A9,'[1]SSP4-change-rate'!$B$2:$B$147,'[1]SSP4-change-rate'!F$2:F$147) -> 6017.9073 | AX9: =Sheet1!$AT9*_xlfn.XLOOKUP($A9,'[1]SSP4-change-rate'!$B$2:$B$147,'[1]SSP4-change-rate'!G$2:G$147) -> 5996.4008 | AY9: =Sheet1!$AT9*_xlfn.XLOOKUP($A9,'[1]SSP4-change-rate'!$B$2:$B$147,'[1]SSP4-change-rate'!H$2:H$147) -> 5974.2223
A10: AZE | B10: Azerbaijan | C10: 159_Azerbaijan_country | D10: Russia region | E10: Middle East and Central Asia | F10: Eurasia | G10: 86235.488 | H10: 2080.6983 | I10: 88316.186 | J10: 10273527 | K10: 50.086696 | L10: 58.165196 | M10: 69.475095 | N10: 88.863493 | O10: 114.71469 | P10: 124.40889 | Q10: 135.71879 | R10: 150.26009 | S10: 166.41709 | T10: 240.73928 | U10: 340.91267 | V10: 434.62327 | W10: 533.18096 | X10: 534.79666 | Y10: 559.03216 | Z10: 602.65606 | AA10: 618.81305 | AB10: 625.27585 | AC10: 641.43285 | AD10: 657.58985 | AE10: 668.89975 | AF10: 672.13115 | AG10: 691.51955 | AH10: 735.14345 | AI10: 877.32503 | AJ10: 885.40353 | AK10: 945.18443 | AL10: 969.41993 | AM10: 1064.7462 | AN10: 1111.6015 | AO10: 1156.8411 | AP10: 1197.2336 | AQ10: 1297.407 | AR10: 1436.3572 | AS10: 1736.8774 | AT10: =Sheet1!$AT10*_xlfn.XLOOKUP($A10,'[1]SSP4-change-rate'!$B$2:$B$147,'[1]SSP4-change-rate'!C$2:C$147) -> 1927.5622 | AU10: =Sheet1!$AT10*_xlfn.XLOOKUP($A10,'[1]SSP4-change-rate'!$B$2:$B$147,'[1]SSP4-change-rate'!D$2:D$147) -> 1910.6261 | AV10: =Sheet1!$AT10*_xlfn.XLOOKUP($A10,'[1]SSP4-change-rate'!$B$2:$B$147,'[1]SSP4-change-rate'!E$2:E$147) -> 1889.8786 | AW10: =Sheet1!$AT10*_xlfn.XLOOKUP($A10,'[1]SSP4-change-rate'!$B$2:$B$147,'[1]SSP4-change-rate'!F$2:F$147) -> 1833.1789 | AX10: =Sheet1!$AT10*_xlfn.XLOOKUP($A10,'[1]SSP4-change-rate'!$B$2:$B$147,'[1]SSP4-change-rate'!G$2:G$147) -> 1764.9331 | AY10: =Sheet1!$AT10*_xlfn.XLOOKUP($A10,'[1]SSP4-change-rate'!$B$2:$B$147,'[1]SSP4-change-rate'!H$2:H$147) -> 1692.2045
A11: BDI | B11: Burundi | C11: 73_Burundi_country | D11: Eastern Africa | E11: Africa | F11: Africa | G11: 26935.291 | H11: 377.46844 | I11: 27312.76 | J11: 12053895 | K11: 22.46836 | L11: 22.46836 | M11: 22.46836 | N11: 22.46836 | O11: 22.46836 | P11: 22.46836 | Q11: 22.46836 | R11: 22.46836 | S11: 22.46836 | T11: 22.46836 | U11: 22.46836 | V11: 29.957813 | W11: 37.447266 | X11: 37.447266 | Y11: 67.405079 | Z11: 67.405079 | AA11: 67.405079 | AB11: 67.405079 | AC11: 67.405079 | AD11: 67.405079 | AE11: 67.405079 | AF11: 67.405079 | AG11: 67.405079 | AH11: 67.405079 | AI11: 67.405079 | AJ11: 82.383985 | AK11: 97.362891 | AL11: 97.362891 | AM11: 97.362891 | AN11: 112.3418 | AO11: 112.3418 | AP11: 134.81016 | AQ11: 254.64141 | AR11: 366.98321 | AS11: 374.47266 | AT11: =Sheet1!$AT11*_xlfn.XLOOKUP($A11,'[1]SSP4-change-rate'!$B$2:$B$147,'[1]SSP4-change-rate'!C$2:C$147) -> 374.47266 | AU11: =Sheet1!$AT11*_xlfn.XLOOKUP($A11,'[1]SSP4-change-rate'!$B$2:$B$147,'[1]SSP4-change-rate'!D$2:D$147) -> 374.47266 | AV11: =Sheet1!$AT11*_xlfn.XLOOKUP($A11,'[1]SSP4-change-rate'!$B$2:$B$147,'[1]SSP4-change-rate'!E$2:E$147) -> 374.47266 | AW11: =Sheet1!$AT11*_xlfn.XLOOKUP($A11,'[1]SSP4-change-rate'!$B$2:$B$147,'[1]SSP4-change-rate'!F$2:F$147) -> 357.82943 | AX11: =Sheet1!$AT11*_xlfn.XLOOKUP($A11,'[1]SSP4-change-rate'!$B$2:$B$147,'[1]SSP4-change-rate'!G$2:G$147) -> 345.10225 | AY11: =Sheet1!$AT11*_xlfn.XLOOKUP($A11,'[1]SSP4-change-rate'!$B$2:$B$147,'[1]SSP4-change-rate'!H$2:H$147) -> 293.81701
A12: BEL | B12: Belgium | C12: 116_Belgium_country | D12: Western Europe | E12: Europe | F12: Europe | G12: 30707.466 | H12: 14803.846 | I12: 45511.312 | J12: 11541270 | K12: 2697.6111 | L12: 3181.5444 | M12: 3713.4478 | N12: 4335.6479 | O12: 5083.4166 | P12: 5138.4411 | Q12: 5598.3895 | R12: 5800.1459 | S12: 6034.3528 | T12: 6473.1378 | U12: 6940.1406 | V12: 7237.8372 | W12: 7431.1284 | X12: 7538.3556 | Y12: 8695.2808 | Z12: 9392.2577 | AA12: 9606.7122 | AB12: 9715.3503 | AC12: 9788.7163 | AD12: 9949.5571 | AE12: 10267.006 | AF12: 10319.209 | AG12: 10346.016 | AH12: 10358.714 | AI12: 10381.288 | AJ12: 10434.901 | AK12: 10480.05 | AL12: 10539.307 | AM12: 10746.707 | AN12: 10908.959 | AO12: 11178.437 | AP12: 11699.054 | AQ12: 12393.209 | AR12: 13574.119 | AS12: 14247.111 | AT12: =Sheet1!$AT12*_xlfn.XLOOKUP($A12,'[1]SSP4-change-rate'!$B$2:$B$147,'[1]SSP4-change-rate'!C$2:C$147) -> 14508.563 | AU12: =Sheet1!$AT12*_xlfn.XLOOKUP($A12,'[1]SSP4-change-rate'!$B$2:$B$147,'[1]SSP4-change-rate'!D$2:D$147) -> 14431.56 | AV12: =Sheet1!$AT12*_xlfn.XLOOKUP($A12,'[1]SSP4-change-rate'!$B$2:$B$147,'[1]SSP4-change-rate'!E$2:E$147) -> 14322.461 | AW12: =Sheet1!$AT12*_xlfn.XLOOKUP($A12,'[1]SSP4-change-rate'!$B$2:$B$147,'[1]SSP4-change-rate'!F$2:F$147) -> 14088.835 | AX12: =Sheet1!$AT12*_xlfn.XLOOKUP($A12,'[1]SSP4-change-rate'!$B$2:$B$147,'[1]SSP4-change-rate'!G$2:G$147) -> 13784.456 | AY12: =Sheet1!$AT12*_xlfn.XLOOKUP($A12,'[1]SSP4-change-rate'!$B$2:$B$147,'[1]SSP4-change-rate'!H$2:H$147) -> 13402.579
A13: BEN | B13: Benin | C13: 70_Benin_country | D13: Western Africa | E13: Africa | F13: Africa | G13: 115286.16 | H13: 1192.2221 | I13: 116478.38 | J13: 12466822 | K13: 63.755194 | L13: 63.755194 | M13: 63.755194 | N13: 63.755194 | O13: 63.755194 | P13: 63.755194 | Q13: 63.755194 | R13: 63.755194 | S13: 63.755194 | T13: 71.724593 | U13: 111.57159 | V13: 191.26558 | W13: 278.92897 | X13: 278.92897 | Y13: 286.89837 | Z13: 398.46996 | AA13: 430.34756 | AB13: 438.31696 | AC13: 438.31696 | AD13: 462.22516 | AE13: 462.22516 | AF13: 533.94975 | AG13: 541.91915 | AH13: 557.85795 | AI13: 557.85795 | AJ13: 573.79675 | AK13: 597.70495 | AL13: 613.64374 | AM13: 661.46014 | AN13: 725.21533 | AO13: 820.84813 | AP13: 868.66452 | AQ13: 924.45032 | AR13: 1028.0525 | AS13: 1036.0219 | AT13: =Sheet1!$AT13*_xlfn.XLOOKUP($A13,'[1]SSP4-change-rate'!$B$2:$B$147,'[1]SSP4-change-rate'!C$2:C$147) -> 1140.4957 | AU13: =Sheet1!$AT13*_xlfn.XLOOKUP($A13,'[1]SSP4-change-rate'!$B$2:$B$147,'[1]SSP4-change-rate'!D$2:D$147) -> 1139.915 | AV13: =Sheet1!$AT13*_xlfn.XLOOKUP($A13,'[1]SSP4-change-rate'!$B$2:$B$147,'[1]SSP4-change-rate'!E$2:E$147) -> 1154.4397 | AW13: =Sheet1!$AT13*_xlfn.XLOOKUP($A13,'[1]SSP4-change-rate'!$B$2:$B$147,'[1]SSP4-change-rate'!F$2:F$147) -> 1164.5516 | AX13: =Sheet1!$AT13*_xlfn.XLOOKUP($A13,'[1]SSP4-change-rate'!$B$2:$B$147,'[1]SSP4-change-rate'!G$2:G$147) -> 1171.8658 | AY13: =Sheet1!$AT13*_xlfn.XLOOKUP($A13,'[1]SSP4-change-rate'!$B$2:$B$147,'[1]SSP4-change-rate'!H$2:H$147) -> 1171.8913
A14: BFA | B14: Burkina Faso | C14: 72_Burkina Faso_country | D14: Western Africa | E14: Africa | F14: Africa | G14: 272946.96 | H14: 1446.1177 | I14: 274393.08 | J14: 21231890 | K14: 55.40681 | L14: 55.40681 | M14: 55.40681 | N14: 55.40681 | O14: 55.40681 | P14: 55.40681 | Q14: 55.40681 | R14: 55.40681 | S14: 60.947491 | T14: 66.488172 | U14: 72.028853 | V14: 99.732257 | W14: 155.13907 | X14: 160.67975 | Y14: 199.46451 | Z14: 249.33064 | AA14: 332.44086 | AB14: 382.30699 | AC14: 398.92903 | AD14: 432.17312 | AE14: 448.79516 | AF14: 465.4172 | AG14: 465.4172 | AH14: 465.4172 | AI14: 509.74265 | AJ14: 542.98674 | AK14: 603.93423 | AL14: 687.04444 | AM14: 714.74785 | AN14: 764.61397 | AO14: 792.31738 | AP14: 941.91577 | AQ14: 1069.3514 | AR14: 1141.3803 | AS14: 1279.8973 | AT14: =Sheet1!$AT14*_xlfn.XLOOKUP($A14,'[1]SSP4-change-rate'!$B$2:$B$147,'[1]SSP4-change-rate'!C$2:C$147) -> 1379.6296 | AU14: =Sheet1!$AT14*_xlfn.XLOOKUP($A14,'[1]SSP4-change-rate'!$B$2:$B$147,'[1]SSP4-change-rate'!D$2:D$147) -> 1385.5507 | AV14: =Sheet1!$AT14*_xlfn.XLOOKUP($A14,'[1]SSP4-change-rate'!$B$2:$B$147,'[1]SSP4-change-rate'!E$2:E$147) -> 1385.0826 | AW14: =Sheet1!$AT14*_xlfn.XLOOKUP($A14,'[1]SSP4-change-rate'!$B$2:$B$147,'[1]SSP4-change-rate'!F$2:F$147) -> 1389.0791 | AX14: =Sheet1!$AT14*_xlfn.XLOOKUP($A14,'[1]SSP4-change-rate'!$B$2:$B$147,'[1]SSP4-change-rate'!G$2:G$147) -> 1391.9111 | AY14: =Sheet1!$AT14*_xlfn.XLOOKUP($A14,'[1]SSP4-change-rate'!$B$2:$B$147,'[1]SSP4-change-rate'!H$2:H$147) -> 1376.1101
A15: BGD | B15: Bangladesh | C15: 162_Bangladesh_country | D15: Rest of South Asia | E15: South and East Asia | F15: Southern Asia | G15: 139384.37 | H15: 24194.401 | I15: 163578.77 | J15: 166426991 | K15: 887.65911 | L15: 978.70107 | M15: 1115.264 | N15: 1274.5874 | O15: 1456.6714 | P15: 1547.7133 | Q15: 1707.0368 | R15: 1843.5997 | S15: 1911.8812 | T15: 2276.049 | U15: 3300.2711 | V15: 6099.8113 | W15: 8057.2135 | X15: 8603.4653 | Y15: 9217.9985 | Z15: 10128.418 | AA15: 10538.107 | AB15: 10697.43 | AC15: 10742.951 | AD15: 10788.472 | AE15: 10833.993 | AF15: 11107.119 | AG15: 11585.089 | AH15: 12176.862 | AI15: 12541.03 | AJ15: 12768.635 | AK15: 12814.156 | AL15: 12973.479 | AM15: 13292.126 | AN15: 13610.773 | AO15: 14248.067 | AP15: 14771.558 | AQ15: 16706.2 | AR15: 19642.303 | AS15: 22646.688 | AT15: =Sheet1!$AT15*_xlfn.XLOOKUP($A15,'[1]SSP4-change-rate'!$B$2:$B$147,'[1]SSP4-change-rate'!C$2:C$147) -> 23379.368 | AU15: =Sheet1!$AT15*_xlfn.XLOOKUP($A15,'[1]SSP4-change-rate'!$B$2:$B$147,'[1]SSP4-change-rate'!D$2:D$147) -> 23299.047 | AV15: =Sheet1!$AT15*_xlfn.XLOOKUP($A15,'[1]SSP4-change-rate'!$B$2:$B$147,'[1]SSP4-change-rate'!E$2:E$147) -> 23149.669 | AW15: =Sheet1!$AT15*_xlfn.XLOOKUP($A15,'[1]SSP4-change-rate'!$B$2:$B$147,'[1]SSP4-change-rate'!F$2:F$147) -> 22697.068 | AX15: =Sheet1!$AT15*_xlfn.XLOOKUP($A15,'[1]SSP4-change-rate'!$B$2:$B$147,'[1]SSP4-change-rate'!G$2:G$147) -> 21695.393 | AY15: =Sheet1!$AT15*_xlfn.XLOOKUP($A15,'[1]SSP4-change-rate'!$B$2:$B$147,'[1]SSP4-change-rate'!H$2:H$147) -> 19057.568
A16: BGR | B16: Bulgaria | C16: 118_Bulgaria_country | D16: Central Europe | E16: Europe | F16: Europe | G16: 111587.67 | H16: 2710.5348 | I16: 114298.21 | J16: 7020239 | K16: 52.300002 | L16: 64.503336 | M16: 81.93667 | N16: 92.396671 | O16: 129.00667 | P16: 148.18334 | Q16: 184.79334 | R16: 240.58001 | S16: 277.19001 | T16: 364.35668 | U16: 571.81336 | V16: 725.2267 | W16: 791.47337 | X16: 796.70337 | Y16: 911.76338 | Z16: 1037.2834 | AA16: 1065.1767 | AB16: 1084.3534 | AC16: 1103.5301 | AD16: 1155.8301 | AE16: 1194.1834 | AF16: 1262.1734 | AG16: 1317.9601 | AH16: 1354.5701 | AI16: 1389.4367 | AJ16: 1413.8434 | AK16: 1473.1167 | AL16: 1591.6634 | AM16: 1704.9801 | AN16: 1779.9434 | AO16: 1868.8534 | AP16: 1936.8434 | AQ16: 2111.1768 | AR16: 2391.8534 | AS16: 2604.5401 | AT16: =Sheet1!$AT16*_xlfn.XLOOKUP($A16,'[1]SSP4-change-rate'!$B$2:$B$147,'[1]SSP4-change-rate'!C$2:C$147) -> 2655.0168 | AU16: =Sheet1!$AT16*_xlfn.XLOOKUP($A16,'[1]SSP4-change-rate'!$B$2:$B$147,'[1]SSP4-change-rate'!D$2:D$147) -> 2649.9349 | AV16: =Sheet1!$AT16*_xlfn.XLOOKUP($A16,'[1]SSP4-change-rate'!$B$2:$B$147,'[1]SSP4-change-rate'!E$2:E$147) -> 2640.1919 | AW16: =Sheet1!$AT16*_xlfn.XLOOKUP($A16,'[1]SSP4-change-rate'!$B$2:$B$147,'[1]SSP4-change-rate'!F$2:F$147) -> 2610.4011 | AX16: =Sheet1!$AT16*_xlfn.XLOOKUP($A16,'[1]SSP4-change-rate'!$B$2:$B$147,'[1]SSP4-change-rate'!G$2:G$147) -> 2570.5267 | AY16: =Sheet1!$AT16*_xlfn.XLOOKUP($A16,'[1]SSP4-change-rate'!$B$2:$B$147,'[1]SSP4-change-rate'!H$2:H$147) -> 2520.4212
A17: BHR | B17: Bahrain | C17: 314_Bahrain_country | D17: Middle East | E17: Middle East and Central Asia | F17: Middle East | G17: 910.06629 | H17: 667.24695 | I17: 1577.3132 | J17: 1494035 | K17: 0 | L17: 0 | M17: 0 | N17: 0 | O17: 0 | P17: 0 | Q17: 0 | R17: 0 | S17: 0 | T17: 0 | U17: 0 | V17: 0 | W17: 0 | X17: 280.68691 | Y17: 292.99774 | Z17: 297.92207 | AA17: 300.38423 | AB17: 301.61532 | AC17: 301.61532 | AD17: 302.8464 | AE17: 304.07748 | AF17: 304.07748 | AG17: 307.77073 | AH17: 315.15723 | AI17: 320.08156 | AJ17: 321.31264 | AK17: 323.77481 | AL17: 325.00589 | AM17: 350.85863 | AN17: 361.93838 | AO17: 386.56004 | AP17: 438.26552 | AQ17: 513.36158 | AR17: 557.68057 | AS17: 578.60898 | AT17: =Sheet1!$AT17*_xlfn.XLOOKUP($A17,'[1]SSP4-change-rate'!$B$2:$B$147,'[1]SSP4-change-rate'!C$2:C$147) -> 664.36467 | AU17: =Sheet1!$AT17*_xlfn.XLOOKUP($A17,'[1]SSP4-change-rate'!$B$2:$B$147,'[1]SSP4-change-rate'!D$2:D$147) -> 659.54794 | AV17: =Sheet1!$AT17*_xlfn.XLOOKUP($A17,'[1]SSP4-change-rate'!$B$2:$B$147,'[1]SSP4-change-rate'!E$2:E$147) -> 654.0123 | AW17: =Sheet1!$AT17*_xlfn.XLOOKUP($A17,'[1]SSP4-change-rate'!$B$2:$B$147,'[1]SSP4-change-rate'!F$2:F$147) -> 641.13337 | AX17: =Sheet1!$AT17*_xlfn.XLOOKUP($A17,'[1]SSP4-change-rate'!$B$2:$B$147,'[1]SSP4-change-rate'!G$2:G$147) -> 624.86983 | AY17: =Sheet1!$AT17*_xlfn.XLOOKUP($A17,'[1]SSP4-change-rate'!$B$2:$B$147,'[1]SSP4-change-rate'!H$2:H$147) -> 607.091
... A19: BIH | B19: bosnia-herzegovina | C19: 117_Bosnia and Herzegovina_country | D19: Central Europe | E19: Europe | F19: Europe | G19: 51068.854 | H19: 790.81654 | I19: 51859.671 | J19: 3340977 | K19: 3.9527651 | L19: 3.9527651 | M19: 3.9527651 | N19: 5.2703535 | O19: 6.5879418 | P19: 7.9055302 | Q19: 9.2231186 | R19: 9.2231186 | S19: 9.2231186 | T19: 9.2231186 | U19: 10.540707 | V19: 13.175884 | W19: 15.81106 | X19: 17.128649 | Y19: 23.716591 | Z19: 36.892474 | AA19: 83.008067 | AB19: 126.48848 | AC19: 172.60408 | AD19: 204.2262 | AE19: 264.83526 | AF19: 281.96391 | AG19: 300.41015 | AH19: 318.85638 | AI19: 332.03227 | AJ19: 351.79609 | AK19: 367.60715 | AL19: 386.05339 | AM19: 407.13481 | AN19: 450.61522 | AO19: 505.95393 | AP19: 566.563 | AQ19: 610.04341 | AR19: 640.34795 | AS19: 736.5319 | AT19: =Sheet1!$AT19*_xlfn.XLOOKUP($A19,'[1]SSP4-change-rate'!$B$2:$B$147,'[1]SSP4-change-rate'!C$2:C$147) -> 768.15402 | AU19: =Sheet1!$AT19*_xlfn.XLOOKUP($A19,'[1]SSP4-change-rate'!$B$2:$B$147,'[1]SSP4-change-rate'!D$2:D$147) -> 764.24484 | AV19: =Sheet1!$AT19*_xlfn.XLOOKUP($A19,'[1]SSP4-change-rate'!$B$2:$B$147,'[1]SSP4-change-rate'!E$2:E$147) -> 760.71427 | AW19: =Sheet1!$AT19*_xlfn.XLOOKUP($A19,'[1]SSP4-change-rate'!$B$2:$B$147,'[1]SSP4-change-rate'!F$2:F$147) -> 747.57846 | AX19: =Sheet1!$AT19*_xlfn.XLOOKUP($A19,'[1]SSP4-change-rate'!$B$2:$B$147,'[1]SSP4-change-rate'!G$2:G$147) -> 731.2698 | AY19: =Sheet1!$AT19*_xlfn.XLOOKUP($A19,'[1]SSP4-change-rate'!$B$2:$B$147,'[1]SSP4-change-rate'!H$2:H$147) -> 711.87343
A20: BLR | B20: Belarus | C20: 146_Belarus_country | D20: Ukraine region | E20: Middle East and Central Asia | F20: Eurasia | G20: 207069.81 | H20: 3844.6981 | I20: 210914.51 | K20: 102.80584 | L20: 117.16622 | M20: 138.72749 | N20: 183.98634 | O20: 263.70183 | P20: 289.65913 | Q20: 306.67482 | R20: 339.31735 | S20: 362.53675 | T20: 485.5194 | U20: 670.85243 | V20: 857.85246 | W20: 1033.6264 | X20: 1044.7891 | Y20: 1127.0334 | Z20: 1197.111 | AA20: 1237.1839 | AB20: 1274.5114 | AC20: 1313.0808 | AD20: 1339.0463 | AE20: 1356.2237 | AF20: 1374.4645 | AG20: 1388.541 | AH20: 1413.4092 | AI20: 1459.9013 | AJ20: 1526.7754 | AK20: 1596.5759 | AL20: 1661.0305 | AM20: 1772.1807 | AN20: 1849.1222 | AO20: 1932.5027 | AP20: 2038.6038 | AQ20: 2302.2597 | AR20: 2642.961 | AS20: 2930.0919 | AT20: 3078.6181 | AU20: 3067.1507 | AV20: 3054.6267 | AW20: 3004.058 | AX20: 2939.5025 | AY20: 2858.6961
